[2024-09-10T16:53:27.147+0530] {local_task_job_runner.py:123} INFO - ::group::Pre task execution logs
[2024-09-10T16:53:27.159+0530] {taskinstance.py:2612} INFO - Dependencies all met for dep_context=non-requeueable deps ti=<TaskInstance: apache_beam_etl_pipeline.run_beam_pipeline2 manual__2024-09-10T11:23:22.649352+00:00 [queued]>
[2024-09-10T16:53:27.169+0530] {taskinstance.py:2612} INFO - Dependencies all met for dep_context=requeueable deps ti=<TaskInstance: apache_beam_etl_pipeline.run_beam_pipeline2 manual__2024-09-10T11:23:22.649352+00:00 [queued]>
[2024-09-10T16:53:27.169+0530] {taskinstance.py:2865} INFO - Starting attempt 1 of 2
[2024-09-10T16:53:27.205+0530] {taskinstance.py:2888} INFO - Executing <Task(BashOperator): run_beam_pipeline2> on 2024-09-10 11:23:22.649352+00:00
[2024-09-10T16:53:27.210+0530] {standard_task_runner.py:72} INFO - Started process 207201 to run task
[2024-09-10T16:53:27.216+0530] {standard_task_runner.py:104} INFO - Running: ['airflow', 'tasks', 'run', 'apache_beam_etl_pipeline', 'run_beam_pipeline2', 'manual__2024-09-10T11:23:22.649352+00:00', '--job-id', '90', '--raw', '--subdir', 'DAGS_FOLDER/aaz.py', '--cfg-path', '/tmp/tmpz7ivczsd']
[2024-09-10T16:53:27.218+0530] {standard_task_runner.py:105} INFO - Job 90: Subtask run_beam_pipeline2
[2024-09-10T16:53:27.314+0530] {task_command.py:467} INFO - Running <TaskInstance: apache_beam_etl_pipeline.run_beam_pipeline2 manual__2024-09-10T11:23:22.649352+00:00 [running]> on host PG0392KD.springernature.com
[2024-09-10T16:53:27.752+0530] {taskinstance.py:3131} INFO - Exporting env vars: AIRFLOW_CTX_DAG_OWNER='airflow_SS' AIRFLOW_CTX_DAG_ID='apache_beam_etl_pipeline' AIRFLOW_CTX_TASK_ID='run_beam_pipeline2' AIRFLOW_CTX_EXECUTION_DATE='2024-09-10T11:23:22.649352+00:00' AIRFLOW_CTX_TRY_NUMBER='1' AIRFLOW_CTX_DAG_RUN_ID='manual__2024-09-10T11:23:22.649352+00:00'
[2024-09-10T16:53:27.753+0530] {logging_mixin.py:190} INFO - Task instance is in running state
[2024-09-10T16:53:27.753+0530] {logging_mixin.py:190} INFO -  Previous state of the Task instance: queued
[2024-09-10T16:53:27.753+0530] {logging_mixin.py:190} INFO - Current task name:run_beam_pipeline2 state:running start_date:2024-09-10 11:23:27.160402+00:00
[2024-09-10T16:53:27.753+0530] {logging_mixin.py:190} INFO - Dag name:apache_beam_etl_pipeline and current dag run status:running
[2024-09-10T16:53:27.754+0530] {taskinstance.py:731} INFO - ::endgroup::
[2024-09-10T16:53:27.755+0530] {subprocess.py:63} INFO - Tmp dir root location: /tmp
[2024-09-10T16:53:27.757+0530] {subprocess.py:75} INFO - Running command: ['/usr/bin/bash', '-c', 'python3 ~/airflow_projects/project1/beam_scripts/etl_pipe_1.py']
[2024-09-10T16:53:27.779+0530] {subprocess.py:86} INFO - Output:
[2024-09-10T16:53:32.516+0530] {subprocess.py:93} INFO - WARNING:google.auth.compute_engine._metadata:Compute Engine Metadata server unavailable on attempt 1 of 3. Reason: timed out
[2024-09-10T16:53:36.489+0530] {subprocess.py:93} INFO - WARNING:google.auth.compute_engine._metadata:Compute Engine Metadata server unavailable on attempt 2 of 3. Reason: timed out
[2024-09-10T16:53:41.653+0530] {subprocess.py:93} INFO - WARNING:google.auth.compute_engine._metadata:Compute Engine Metadata server unavailable on attempt 3 of 3. Reason: timed out
[2024-09-10T16:53:41.654+0530] {subprocess.py:93} INFO - WARNING:google.auth._default:Authentication failed using Compute Engine authentication due to unavailable metadata server.
[2024-09-10T16:53:41.658+0530] {subprocess.py:93} INFO - WARNING:apache_beam.utils.retry:Retry with exponential backoff: waiting for 1.199970552720937 seconds before retrying _get_credentials_with_retrys because we caught exception: google.auth.exceptions.DefaultCredentialsError: Your default credentials were not found. To set up Application Default Credentials, see https://cloud.google.com/docs/authentication/external/set-up-adc for more information.
[2024-09-10T16:53:41.658+0530] {subprocess.py:93} INFO -  Traceback for above exception (most recent call last):
[2024-09-10T16:53:41.658+0530] {subprocess.py:93} INFO -   File "/home/sst7260/airflow_projects/project1/env/lib/python3.10/site-packages/apache_beam/utils/retry.py", line 298, in wrapper
[2024-09-10T16:53:41.658+0530] {subprocess.py:93} INFO -     return fun(*args, **kwargs)
[2024-09-10T16:53:41.658+0530] {subprocess.py:93} INFO -   File "/home/sst7260/airflow_projects/project1/env/lib/python3.10/site-packages/apache_beam/internal/gcp/auth.py", line 175, in _get_credentials_with_retrys
[2024-09-10T16:53:41.658+0530] {subprocess.py:93} INFO -     credentials, _ = google.auth.default(
[2024-09-10T16:53:41.658+0530] {subprocess.py:93} INFO -   File "/home/sst7260/airflow_projects/project1/env/lib/python3.10/site-packages/google/auth/_default.py", line 691, in default
[2024-09-10T16:53:41.658+0530] {subprocess.py:93} INFO -     raise exceptions.DefaultCredentialsError(_CLOUD_SDK_MISSING_CREDENTIALS)
[2024-09-10T16:53:41.658+0530] {subprocess.py:93} INFO - 
[2024-09-10T16:53:45.865+0530] {subprocess.py:93} INFO - WARNING:google.auth.compute_engine._metadata:Compute Engine Metadata server unavailable on attempt 1 of 3. Reason: timed out
[2024-09-10T16:53:49.772+0530] {subprocess.py:93} INFO - WARNING:google.auth.compute_engine._metadata:Compute Engine Metadata server unavailable on attempt 2 of 3. Reason: timed out
[2024-09-10T16:53:54.622+0530] {subprocess.py:93} INFO - WARNING:google.auth.compute_engine._metadata:Compute Engine Metadata server unavailable on attempt 3 of 3. Reason: timed out
[2024-09-10T16:53:54.623+0530] {subprocess.py:93} INFO - WARNING:google.auth._default:Authentication failed using Compute Engine authentication due to unavailable metadata server.
[2024-09-10T16:53:54.623+0530] {subprocess.py:93} INFO - WARNING:apache_beam.utils.retry:Retry with exponential backoff: waiting for 2.6221721259811694 seconds before retrying _get_credentials_with_retrys because we caught exception: google.auth.exceptions.DefaultCredentialsError: Your default credentials were not found. To set up Application Default Credentials, see https://cloud.google.com/docs/authentication/external/set-up-adc for more information.
[2024-09-10T16:53:54.623+0530] {subprocess.py:93} INFO -  Traceback for above exception (most recent call last):
[2024-09-10T16:53:54.623+0530] {subprocess.py:93} INFO -   File "/home/sst7260/airflow_projects/project1/env/lib/python3.10/site-packages/apache_beam/utils/retry.py", line 298, in wrapper
[2024-09-10T16:53:54.623+0530] {subprocess.py:93} INFO -     return fun(*args, **kwargs)
[2024-09-10T16:53:54.623+0530] {subprocess.py:93} INFO -   File "/home/sst7260/airflow_projects/project1/env/lib/python3.10/site-packages/apache_beam/internal/gcp/auth.py", line 175, in _get_credentials_with_retrys
[2024-09-10T16:53:54.623+0530] {subprocess.py:93} INFO -     credentials, _ = google.auth.default(
[2024-09-10T16:53:54.623+0530] {subprocess.py:93} INFO -   File "/home/sst7260/airflow_projects/project1/env/lib/python3.10/site-packages/google/auth/_default.py", line 691, in default
[2024-09-10T16:53:54.623+0530] {subprocess.py:93} INFO -     raise exceptions.DefaultCredentialsError(_CLOUD_SDK_MISSING_CREDENTIALS)
[2024-09-10T16:53:54.624+0530] {subprocess.py:93} INFO - 
[2024-09-10T16:54:00.253+0530] {subprocess.py:93} INFO - WARNING:google.auth.compute_engine._metadata:Compute Engine Metadata server unavailable on attempt 1 of 3. Reason: timed out
[2024-09-10T16:54:04.311+0530] {subprocess.py:93} INFO - WARNING:google.auth.compute_engine._metadata:Compute Engine Metadata server unavailable on attempt 2 of 3. Reason: timed out
[2024-09-10T16:54:09.416+0530] {subprocess.py:93} INFO - WARNING:google.auth.compute_engine._metadata:Compute Engine Metadata server unavailable on attempt 3 of 3. Reason: timed out
[2024-09-10T16:54:09.416+0530] {subprocess.py:93} INFO - WARNING:google.auth._default:Authentication failed using Compute Engine authentication due to unavailable metadata server.
[2024-09-10T16:54:09.416+0530] {subprocess.py:93} INFO - WARNING:apache_beam.utils.retry:Retry with exponential backoff: waiting for 7.786283418086088 seconds before retrying _get_credentials_with_retrys because we caught exception: google.auth.exceptions.DefaultCredentialsError: Your default credentials were not found. To set up Application Default Credentials, see https://cloud.google.com/docs/authentication/external/set-up-adc for more information.
[2024-09-10T16:54:09.416+0530] {subprocess.py:93} INFO -  Traceback for above exception (most recent call last):
[2024-09-10T16:54:09.416+0530] {subprocess.py:93} INFO -   File "/home/sst7260/airflow_projects/project1/env/lib/python3.10/site-packages/apache_beam/utils/retry.py", line 298, in wrapper
[2024-09-10T16:54:09.416+0530] {subprocess.py:93} INFO -     return fun(*args, **kwargs)
[2024-09-10T16:54:09.416+0530] {subprocess.py:93} INFO -   File "/home/sst7260/airflow_projects/project1/env/lib/python3.10/site-packages/apache_beam/internal/gcp/auth.py", line 175, in _get_credentials_with_retrys
[2024-09-10T16:54:09.416+0530] {subprocess.py:93} INFO -     credentials, _ = google.auth.default(
[2024-09-10T16:54:09.416+0530] {subprocess.py:93} INFO -   File "/home/sst7260/airflow_projects/project1/env/lib/python3.10/site-packages/google/auth/_default.py", line 691, in default
[2024-09-10T16:54:09.417+0530] {subprocess.py:93} INFO -     raise exceptions.DefaultCredentialsError(_CLOUD_SDK_MISSING_CREDENTIALS)
[2024-09-10T16:54:09.417+0530] {subprocess.py:93} INFO - 
[2024-09-10T16:54:20.218+0530] {subprocess.py:93} INFO - WARNING:google.auth.compute_engine._metadata:Compute Engine Metadata server unavailable on attempt 1 of 3. Reason: timed out
[2024-09-10T16:54:24.210+0530] {subprocess.py:93} INFO - WARNING:google.auth.compute_engine._metadata:Compute Engine Metadata server unavailable on attempt 2 of 3. Reason: timed out
[2024-09-10T16:54:29.238+0530] {subprocess.py:93} INFO - WARNING:google.auth.compute_engine._metadata:Compute Engine Metadata server unavailable on attempt 3 of 3. Reason: timed out
[2024-09-10T16:54:29.252+0530] {subprocess.py:93} INFO - WARNING:google.auth._default:Authentication failed using Compute Engine authentication due to unavailable metadata server.
[2024-09-10T16:54:29.253+0530] {subprocess.py:93} INFO - WARNING:apache_beam.utils.retry:Retry with exponential backoff: waiting for 13.18985528600815 seconds before retrying _get_credentials_with_retrys because we caught exception: google.auth.exceptions.DefaultCredentialsError: Your default credentials were not found. To set up Application Default Credentials, see https://cloud.google.com/docs/authentication/external/set-up-adc for more information.
[2024-09-10T16:54:29.267+0530] {subprocess.py:93} INFO -  Traceback for above exception (most recent call last):
[2024-09-10T16:54:29.268+0530] {subprocess.py:93} INFO -   File "/home/sst7260/airflow_projects/project1/env/lib/python3.10/site-packages/apache_beam/utils/retry.py", line 298, in wrapper
[2024-09-10T16:54:29.268+0530] {subprocess.py:93} INFO -     return fun(*args, **kwargs)
[2024-09-10T16:54:29.268+0530] {subprocess.py:93} INFO -   File "/home/sst7260/airflow_projects/project1/env/lib/python3.10/site-packages/apache_beam/internal/gcp/auth.py", line 175, in _get_credentials_with_retrys
[2024-09-10T16:54:29.268+0530] {subprocess.py:93} INFO -     credentials, _ = google.auth.default(
[2024-09-10T16:54:29.268+0530] {subprocess.py:93} INFO -   File "/home/sst7260/airflow_projects/project1/env/lib/python3.10/site-packages/google/auth/_default.py", line 691, in default
[2024-09-10T16:54:29.269+0530] {subprocess.py:93} INFO -     raise exceptions.DefaultCredentialsError(_CLOUD_SDK_MISSING_CREDENTIALS)
[2024-09-10T16:54:29.269+0530] {subprocess.py:93} INFO - 
[2024-09-10T16:54:33.138+0530] {local_task_job_runner.py:318} WARNING - Recorded pid 207600 does not match the current pid 207201
[2024-09-10T16:54:33.140+0530] {local_task_job_runner.py:218} WARNING - Heartbeat failed with Exception: PID of job runner does not match
[2024-09-10T16:54:38.173+0530] {local_task_job_runner.py:318} WARNING - Recorded pid 207600 does not match the current pid 207201
[2024-09-10T16:54:38.173+0530] {local_task_job_runner.py:218} WARNING - Heartbeat failed with Exception: PID of job runner does not match
[2024-09-10T16:54:43.207+0530] {local_task_job_runner.py:318} WARNING - Recorded pid 207600 does not match the current pid 207201
[2024-09-10T16:54:43.208+0530] {local_task_job_runner.py:218} WARNING - Heartbeat failed with Exception: PID of job runner does not match
[2024-09-10T16:54:45.457+0530] {subprocess.py:93} INFO - WARNING:google.auth.compute_engine._metadata:Compute Engine Metadata server unavailable on attempt 1 of 3. Reason: timed out
[2024-09-10T16:54:48.236+0530] {local_task_job_runner.py:318} WARNING - Recorded pid 207600 does not match the current pid 207201
[2024-09-10T16:54:48.237+0530] {local_task_job_runner.py:218} WARNING - Heartbeat failed with Exception: PID of job runner does not match
[2024-09-10T16:54:49.437+0530] {subprocess.py:93} INFO - WARNING:google.auth.compute_engine._metadata:Compute Engine Metadata server unavailable on attempt 2 of 3. Reason: timed out
[2024-09-10T16:54:53.264+0530] {local_task_job_runner.py:318} WARNING - Recorded pid 207600 does not match the current pid 207201
[2024-09-10T16:54:53.265+0530] {local_task_job_runner.py:218} WARNING - Heartbeat failed with Exception: PID of job runner does not match
[2024-09-10T16:54:54.380+0530] {subprocess.py:93} INFO - WARNING:google.auth.compute_engine._metadata:Compute Engine Metadata server unavailable on attempt 3 of 3. Reason: timed out
[2024-09-10T16:54:54.380+0530] {subprocess.py:93} INFO - WARNING:google.auth._default:Authentication failed using Compute Engine authentication due to unavailable metadata server.
[2024-09-10T16:54:54.381+0530] {subprocess.py:93} INFO - WARNING:apache_beam.internal.gcp.auth:Unable to find default credentials to use: Your default credentials were not found. To set up Application Default Credentials, see https://cloud.google.com/docs/authentication/external/set-up-adc for more information.
[2024-09-10T16:54:54.382+0530] {subprocess.py:93} INFO - Connecting anonymously. This is expected if no credentials are needed to access GCP resources.
[2024-09-10T16:54:54.968+0530] {subprocess.py:93} INFO - WARNING:apache_beam.utils.retry:Retry with exponential backoff: waiting for 3.065211317729827 seconds before retrying _gcs_object because we caught exception: google.auth.exceptions.InvalidOperation: Anonymous credentials cannot be refreshed.
[2024-09-10T16:54:54.968+0530] {subprocess.py:93} INFO -  Traceback for above exception (most recent call last):
[2024-09-10T16:54:54.968+0530] {subprocess.py:93} INFO -   File "/home/sst7260/airflow_projects/project1/env/lib/python3.10/site-packages/apache_beam/utils/retry.py", line 298, in wrapper
[2024-09-10T16:54:54.968+0530] {subprocess.py:93} INFO -     return fun(*args, **kwargs)
[2024-09-10T16:54:54.968+0530] {subprocess.py:93} INFO -   File "/home/sst7260/airflow_projects/project1/env/lib/python3.10/site-packages/apache_beam/io/gcp/gcsio.py", line 462, in _gcs_object
[2024-09-10T16:54:54.968+0530] {subprocess.py:93} INFO -     blob = bucket.get_blob(blob_name)
[2024-09-10T16:54:54.969+0530] {subprocess.py:93} INFO -   File "/usr/lib/python3.10/contextlib.py", line 79, in inner
[2024-09-10T16:54:54.969+0530] {subprocess.py:93} INFO -     return func(*args, **kwds)
[2024-09-10T16:54:54.969+0530] {subprocess.py:93} INFO -   File "/home/sst7260/airflow_projects/project1/env/lib/python3.10/site-packages/google/cloud/storage/bucket.py", line 1283, in get_blob
[2024-09-10T16:54:54.969+0530] {subprocess.py:93} INFO -     blob.reload(
[2024-09-10T16:54:54.969+0530] {subprocess.py:93} INFO -   File "/home/sst7260/airflow_projects/project1/env/lib/python3.10/site-packages/google/cloud/storage/_helpers.py", line 300, in reload
[2024-09-10T16:54:54.969+0530] {subprocess.py:93} INFO -     api_response = client._get_resource(
[2024-09-10T16:54:54.969+0530] {subprocess.py:93} INFO -   File "/home/sst7260/airflow_projects/project1/env/lib/python3.10/site-packages/google/cloud/storage/client.py", line 464, in _get_resource
[2024-09-10T16:54:54.969+0530] {subprocess.py:93} INFO -     return self._connection.api_request(
[2024-09-10T16:54:54.969+0530] {subprocess.py:93} INFO -   File "/home/sst7260/airflow_projects/project1/env/lib/python3.10/site-packages/google/cloud/storage/_http.py", line 90, in api_request
[2024-09-10T16:54:54.969+0530] {subprocess.py:93} INFO -     return call()
[2024-09-10T16:54:54.969+0530] {subprocess.py:93} INFO -   File "/home/sst7260/airflow_projects/project1/env/lib/python3.10/site-packages/google/api_core/retry/retry_unary.py", line 293, in retry_wrapped_func
[2024-09-10T16:54:54.969+0530] {subprocess.py:93} INFO -     return retry_target(
[2024-09-10T16:54:54.969+0530] {subprocess.py:93} INFO -   File "/home/sst7260/airflow_projects/project1/env/lib/python3.10/site-packages/google/api_core/retry/retry_unary.py", line 153, in retry_target
[2024-09-10T16:54:54.969+0530] {subprocess.py:93} INFO -     _retry_error_helper(
[2024-09-10T16:54:54.969+0530] {subprocess.py:93} INFO -   File "/home/sst7260/airflow_projects/project1/env/lib/python3.10/site-packages/google/api_core/retry/retry_base.py", line 212, in _retry_error_helper
[2024-09-10T16:54:54.969+0530] {subprocess.py:93} INFO -     raise final_exc from source_exc
[2024-09-10T16:54:54.970+0530] {subprocess.py:93} INFO -   File "/home/sst7260/airflow_projects/project1/env/lib/python3.10/site-packages/google/api_core/retry/retry_unary.py", line 144, in retry_target
[2024-09-10T16:54:54.970+0530] {subprocess.py:93} INFO -     result = target()
[2024-09-10T16:54:54.970+0530] {subprocess.py:93} INFO -   File "/home/sst7260/airflow_projects/project1/env/lib/python3.10/site-packages/google/cloud/_http/__init__.py", line 482, in api_request
[2024-09-10T16:54:54.970+0530] {subprocess.py:93} INFO -     response = self._make_request(
[2024-09-10T16:54:54.970+0530] {subprocess.py:93} INFO -   File "/home/sst7260/airflow_projects/project1/env/lib/python3.10/site-packages/google/cloud/_http/__init__.py", line 341, in _make_request
[2024-09-10T16:54:54.970+0530] {subprocess.py:93} INFO -     return self._do_request(
[2024-09-10T16:54:54.970+0530] {subprocess.py:93} INFO -   File "/home/sst7260/airflow_projects/project1/env/lib/python3.10/site-packages/google/cloud/_http/__init__.py", line 379, in _do_request
[2024-09-10T16:54:54.970+0530] {subprocess.py:93} INFO -     return self.http.request(
[2024-09-10T16:54:54.970+0530] {subprocess.py:93} INFO -   File "/home/sst7260/airflow_projects/project1/env/lib/python3.10/site-packages/google/auth/transport/requests.py", line 574, in request
[2024-09-10T16:54:54.970+0530] {subprocess.py:93} INFO -     self.credentials.refresh(auth_request)
[2024-09-10T16:54:54.970+0530] {subprocess.py:93} INFO -   File "/home/sst7260/airflow_projects/project1/env/lib/python3.10/site-packages/google/auth/credentials.py", line 311, in refresh
[2024-09-10T16:54:54.970+0530] {subprocess.py:93} INFO -     raise exceptions.InvalidOperation("Anonymous credentials cannot be refreshed.")
[2024-09-10T16:54:54.970+0530] {subprocess.py:93} INFO - 
[2024-09-10T16:54:58.293+0530] {local_task_job_runner.py:318} WARNING - Recorded pid 207600 does not match the current pid 207201
[2024-09-10T16:54:58.293+0530] {local_task_job_runner.py:218} WARNING - Heartbeat failed with Exception: PID of job runner does not match
[2024-09-10T16:54:58.419+0530] {subprocess.py:93} INFO - WARNING:apache_beam.utils.retry:Retry with exponential backoff: waiting for 8.798829144683001 seconds before retrying _gcs_object because we caught exception: google.auth.exceptions.InvalidOperation: Anonymous credentials cannot be refreshed.
[2024-09-10T16:54:58.420+0530] {subprocess.py:93} INFO -  Traceback for above exception (most recent call last):
[2024-09-10T16:54:58.420+0530] {subprocess.py:93} INFO -   File "/home/sst7260/airflow_projects/project1/env/lib/python3.10/site-packages/apache_beam/utils/retry.py", line 298, in wrapper
[2024-09-10T16:54:58.420+0530] {subprocess.py:93} INFO -     return fun(*args, **kwargs)
[2024-09-10T16:54:58.420+0530] {subprocess.py:93} INFO -   File "/home/sst7260/airflow_projects/project1/env/lib/python3.10/site-packages/apache_beam/io/gcp/gcsio.py", line 462, in _gcs_object
[2024-09-10T16:54:58.420+0530] {subprocess.py:93} INFO -     blob = bucket.get_blob(blob_name)
[2024-09-10T16:54:58.421+0530] {subprocess.py:93} INFO -   File "/usr/lib/python3.10/contextlib.py", line 79, in inner
[2024-09-10T16:54:58.421+0530] {subprocess.py:93} INFO -     return func(*args, **kwds)
[2024-09-10T16:54:58.421+0530] {subprocess.py:93} INFO -   File "/home/sst7260/airflow_projects/project1/env/lib/python3.10/site-packages/google/cloud/storage/bucket.py", line 1283, in get_blob
[2024-09-10T16:54:58.421+0530] {subprocess.py:93} INFO -     blob.reload(
[2024-09-10T16:54:58.421+0530] {subprocess.py:93} INFO -   File "/home/sst7260/airflow_projects/project1/env/lib/python3.10/site-packages/google/cloud/storage/_helpers.py", line 300, in reload
[2024-09-10T16:54:58.421+0530] {subprocess.py:93} INFO -     api_response = client._get_resource(
[2024-09-10T16:54:58.422+0530] {subprocess.py:93} INFO -   File "/home/sst7260/airflow_projects/project1/env/lib/python3.10/site-packages/google/cloud/storage/client.py", line 464, in _get_resource
[2024-09-10T16:54:58.422+0530] {subprocess.py:93} INFO -     return self._connection.api_request(
[2024-09-10T16:54:58.422+0530] {subprocess.py:93} INFO -   File "/home/sst7260/airflow_projects/project1/env/lib/python3.10/site-packages/google/cloud/storage/_http.py", line 90, in api_request
[2024-09-10T16:54:58.422+0530] {subprocess.py:93} INFO -     return call()
[2024-09-10T16:54:58.422+0530] {subprocess.py:93} INFO -   File "/home/sst7260/airflow_projects/project1/env/lib/python3.10/site-packages/google/api_core/retry/retry_unary.py", line 293, in retry_wrapped_func
[2024-09-10T16:54:58.422+0530] {subprocess.py:93} INFO -     return retry_target(
[2024-09-10T16:54:58.423+0530] {subprocess.py:93} INFO -   File "/home/sst7260/airflow_projects/project1/env/lib/python3.10/site-packages/google/api_core/retry/retry_unary.py", line 153, in retry_target
[2024-09-10T16:54:58.423+0530] {subprocess.py:93} INFO -     _retry_error_helper(
[2024-09-10T16:54:58.423+0530] {subprocess.py:93} INFO -   File "/home/sst7260/airflow_projects/project1/env/lib/python3.10/site-packages/google/api_core/retry/retry_base.py", line 212, in _retry_error_helper
[2024-09-10T16:54:58.423+0530] {subprocess.py:93} INFO -     raise final_exc from source_exc
[2024-09-10T16:54:58.423+0530] {subprocess.py:93} INFO -   File "/home/sst7260/airflow_projects/project1/env/lib/python3.10/site-packages/google/api_core/retry/retry_unary.py", line 144, in retry_target
[2024-09-10T16:54:58.423+0530] {subprocess.py:93} INFO -     result = target()
[2024-09-10T16:54:58.423+0530] {subprocess.py:93} INFO -   File "/home/sst7260/airflow_projects/project1/env/lib/python3.10/site-packages/google/cloud/_http/__init__.py", line 482, in api_request
[2024-09-10T16:54:58.423+0530] {subprocess.py:93} INFO -     response = self._make_request(
[2024-09-10T16:54:58.423+0530] {subprocess.py:93} INFO -   File "/home/sst7260/airflow_projects/project1/env/lib/python3.10/site-packages/google/cloud/_http/__init__.py", line 341, in _make_request
[2024-09-10T16:54:58.423+0530] {subprocess.py:93} INFO -     return self._do_request(
[2024-09-10T16:54:58.423+0530] {subprocess.py:93} INFO -   File "/home/sst7260/airflow_projects/project1/env/lib/python3.10/site-packages/google/cloud/_http/__init__.py", line 379, in _do_request
[2024-09-10T16:54:58.424+0530] {subprocess.py:93} INFO -     return self.http.request(
[2024-09-10T16:54:58.424+0530] {subprocess.py:93} INFO -   File "/home/sst7260/airflow_projects/project1/env/lib/python3.10/site-packages/google/auth/transport/requests.py", line 574, in request
[2024-09-10T16:54:58.424+0530] {subprocess.py:93} INFO -     self.credentials.refresh(auth_request)
[2024-09-10T16:54:58.424+0530] {subprocess.py:93} INFO -   File "/home/sst7260/airflow_projects/project1/env/lib/python3.10/site-packages/google/auth/credentials.py", line 311, in refresh
[2024-09-10T16:54:58.424+0530] {subprocess.py:93} INFO -     raise exceptions.InvalidOperation("Anonymous credentials cannot be refreshed.")
[2024-09-10T16:54:58.424+0530] {subprocess.py:93} INFO - 
[2024-09-10T16:55:03.316+0530] {local_task_job_runner.py:318} WARNING - Recorded pid 207600 does not match the current pid 207201
[2024-09-10T16:55:03.316+0530] {local_task_job_runner.py:218} WARNING - Heartbeat failed with Exception: PID of job runner does not match
[2024-09-10T16:55:07.608+0530] {subprocess.py:93} INFO - WARNING:apache_beam.utils.retry:Retry with exponential backoff: waiting for 18.329815368030463 seconds before retrying _gcs_object because we caught exception: google.auth.exceptions.InvalidOperation: Anonymous credentials cannot be refreshed.
[2024-09-10T16:55:07.609+0530] {subprocess.py:93} INFO -  Traceback for above exception (most recent call last):
[2024-09-10T16:55:07.609+0530] {subprocess.py:93} INFO -   File "/home/sst7260/airflow_projects/project1/env/lib/python3.10/site-packages/apache_beam/utils/retry.py", line 298, in wrapper
[2024-09-10T16:55:07.610+0530] {subprocess.py:93} INFO -     return fun(*args, **kwargs)
[2024-09-10T16:55:07.610+0530] {subprocess.py:93} INFO -   File "/home/sst7260/airflow_projects/project1/env/lib/python3.10/site-packages/apache_beam/io/gcp/gcsio.py", line 462, in _gcs_object
[2024-09-10T16:55:07.610+0530] {subprocess.py:93} INFO -     blob = bucket.get_blob(blob_name)
[2024-09-10T16:55:07.610+0530] {subprocess.py:93} INFO -   File "/usr/lib/python3.10/contextlib.py", line 79, in inner
[2024-09-10T16:55:07.611+0530] {subprocess.py:93} INFO -     return func(*args, **kwds)
[2024-09-10T16:55:07.611+0530] {subprocess.py:93} INFO -   File "/home/sst7260/airflow_projects/project1/env/lib/python3.10/site-packages/google/cloud/storage/bucket.py", line 1283, in get_blob
[2024-09-10T16:55:07.612+0530] {subprocess.py:93} INFO -     blob.reload(
[2024-09-10T16:55:07.612+0530] {subprocess.py:93} INFO -   File "/home/sst7260/airflow_projects/project1/env/lib/python3.10/site-packages/google/cloud/storage/_helpers.py", line 300, in reload
[2024-09-10T16:55:07.612+0530] {subprocess.py:93} INFO -     api_response = client._get_resource(
[2024-09-10T16:55:07.613+0530] {subprocess.py:93} INFO -   File "/home/sst7260/airflow_projects/project1/env/lib/python3.10/site-packages/google/cloud/storage/client.py", line 464, in _get_resource
[2024-09-10T16:55:07.613+0530] {subprocess.py:93} INFO -     return self._connection.api_request(
[2024-09-10T16:55:07.614+0530] {subprocess.py:93} INFO -   File "/home/sst7260/airflow_projects/project1/env/lib/python3.10/site-packages/google/cloud/storage/_http.py", line 90, in api_request
[2024-09-10T16:55:07.614+0530] {subprocess.py:93} INFO -     return call()
[2024-09-10T16:55:07.614+0530] {subprocess.py:93} INFO -   File "/home/sst7260/airflow_projects/project1/env/lib/python3.10/site-packages/google/api_core/retry/retry_unary.py", line 293, in retry_wrapped_func
[2024-09-10T16:55:07.614+0530] {subprocess.py:93} INFO -     return retry_target(
[2024-09-10T16:55:07.614+0530] {subprocess.py:93} INFO -   File "/home/sst7260/airflow_projects/project1/env/lib/python3.10/site-packages/google/api_core/retry/retry_unary.py", line 153, in retry_target
[2024-09-10T16:55:07.615+0530] {subprocess.py:93} INFO -     _retry_error_helper(
[2024-09-10T16:55:07.615+0530] {subprocess.py:93} INFO -   File "/home/sst7260/airflow_projects/project1/env/lib/python3.10/site-packages/google/api_core/retry/retry_base.py", line 212, in _retry_error_helper
[2024-09-10T16:55:07.615+0530] {subprocess.py:93} INFO -     raise final_exc from source_exc
[2024-09-10T16:55:07.615+0530] {subprocess.py:93} INFO -   File "/home/sst7260/airflow_projects/project1/env/lib/python3.10/site-packages/google/api_core/retry/retry_unary.py", line 144, in retry_target
[2024-09-10T16:55:07.615+0530] {subprocess.py:93} INFO -     result = target()
[2024-09-10T16:55:07.615+0530] {subprocess.py:93} INFO -   File "/home/sst7260/airflow_projects/project1/env/lib/python3.10/site-packages/google/cloud/_http/__init__.py", line 482, in api_request
[2024-09-10T16:55:07.615+0530] {subprocess.py:93} INFO -     response = self._make_request(
[2024-09-10T16:55:07.616+0530] {subprocess.py:93} INFO -   File "/home/sst7260/airflow_projects/project1/env/lib/python3.10/site-packages/google/cloud/_http/__init__.py", line 341, in _make_request
[2024-09-10T16:55:07.616+0530] {subprocess.py:93} INFO -     return self._do_request(
[2024-09-10T16:55:07.616+0530] {subprocess.py:93} INFO -   File "/home/sst7260/airflow_projects/project1/env/lib/python3.10/site-packages/google/cloud/_http/__init__.py", line 379, in _do_request
[2024-09-10T16:55:07.616+0530] {subprocess.py:93} INFO -     return self.http.request(
[2024-09-10T16:55:07.616+0530] {subprocess.py:93} INFO -   File "/home/sst7260/airflow_projects/project1/env/lib/python3.10/site-packages/google/auth/transport/requests.py", line 574, in request
[2024-09-10T16:55:07.616+0530] {subprocess.py:93} INFO -     self.credentials.refresh(auth_request)
[2024-09-10T16:55:07.616+0530] {subprocess.py:93} INFO -   File "/home/sst7260/airflow_projects/project1/env/lib/python3.10/site-packages/google/auth/credentials.py", line 311, in refresh
[2024-09-10T16:55:07.616+0530] {subprocess.py:93} INFO -     raise exceptions.InvalidOperation("Anonymous credentials cannot be refreshed.")
[2024-09-10T16:55:07.616+0530] {subprocess.py:93} INFO - 
[2024-09-10T16:55:08.393+0530] {local_task_job_runner.py:318} WARNING - Recorded pid 207600 does not match the current pid 207201
[2024-09-10T16:55:08.394+0530] {local_task_job_runner.py:218} WARNING - Heartbeat failed with Exception: PID of job runner does not match
[2024-09-10T16:55:13.419+0530] {local_task_job_runner.py:318} WARNING - Recorded pid 207600 does not match the current pid 207201
[2024-09-10T16:55:13.419+0530] {local_task_job_runner.py:218} WARNING - Heartbeat failed with Exception: PID of job runner does not match
[2024-09-10T16:55:18.450+0530] {local_task_job_runner.py:318} WARNING - Recorded pid 207600 does not match the current pid 207201
[2024-09-10T16:55:18.450+0530] {local_task_job_runner.py:218} WARNING - Heartbeat failed with Exception: PID of job runner does not match
[2024-09-10T16:55:23.479+0530] {local_task_job_runner.py:318} WARNING - Recorded pid 207600 does not match the current pid 207201
[2024-09-10T16:55:23.479+0530] {local_task_job_runner.py:218} WARNING - Heartbeat failed with Exception: PID of job runner does not match
[2024-09-10T16:55:26.342+0530] {subprocess.py:93} INFO - WARNING:apache_beam.utils.retry:Retry with exponential backoff: waiting for 33.13713252349496 seconds before retrying _gcs_object because we caught exception: google.auth.exceptions.InvalidOperation: Anonymous credentials cannot be refreshed.
[2024-09-10T16:55:26.343+0530] {subprocess.py:93} INFO -  Traceback for above exception (most recent call last):
[2024-09-10T16:55:26.343+0530] {subprocess.py:93} INFO -   File "/home/sst7260/airflow_projects/project1/env/lib/python3.10/site-packages/apache_beam/utils/retry.py", line 298, in wrapper
[2024-09-10T16:55:26.343+0530] {subprocess.py:93} INFO -     return fun(*args, **kwargs)
[2024-09-10T16:55:26.343+0530] {subprocess.py:93} INFO -   File "/home/sst7260/airflow_projects/project1/env/lib/python3.10/site-packages/apache_beam/io/gcp/gcsio.py", line 462, in _gcs_object
[2024-09-10T16:55:26.343+0530] {subprocess.py:93} INFO -     blob = bucket.get_blob(blob_name)
[2024-09-10T16:55:26.343+0530] {subprocess.py:93} INFO -   File "/usr/lib/python3.10/contextlib.py", line 79, in inner
[2024-09-10T16:55:26.343+0530] {subprocess.py:93} INFO -     return func(*args, **kwds)
[2024-09-10T16:55:26.343+0530] {subprocess.py:93} INFO -   File "/home/sst7260/airflow_projects/project1/env/lib/python3.10/site-packages/google/cloud/storage/bucket.py", line 1283, in get_blob
[2024-09-10T16:55:26.343+0530] {subprocess.py:93} INFO -     blob.reload(
[2024-09-10T16:55:26.343+0530] {subprocess.py:93} INFO -   File "/home/sst7260/airflow_projects/project1/env/lib/python3.10/site-packages/google/cloud/storage/_helpers.py", line 300, in reload
[2024-09-10T16:55:26.343+0530] {subprocess.py:93} INFO -     api_response = client._get_resource(
[2024-09-10T16:55:26.343+0530] {subprocess.py:93} INFO -   File "/home/sst7260/airflow_projects/project1/env/lib/python3.10/site-packages/google/cloud/storage/client.py", line 464, in _get_resource
[2024-09-10T16:55:26.343+0530] {subprocess.py:93} INFO -     return self._connection.api_request(
[2024-09-10T16:55:26.343+0530] {subprocess.py:93} INFO -   File "/home/sst7260/airflow_projects/project1/env/lib/python3.10/site-packages/google/cloud/storage/_http.py", line 90, in api_request
[2024-09-10T16:55:26.344+0530] {subprocess.py:93} INFO -     return call()
[2024-09-10T16:55:26.344+0530] {subprocess.py:93} INFO -   File "/home/sst7260/airflow_projects/project1/env/lib/python3.10/site-packages/google/api_core/retry/retry_unary.py", line 293, in retry_wrapped_func
[2024-09-10T16:55:26.344+0530] {subprocess.py:93} INFO -     return retry_target(
[2024-09-10T16:55:26.344+0530] {subprocess.py:93} INFO -   File "/home/sst7260/airflow_projects/project1/env/lib/python3.10/site-packages/google/api_core/retry/retry_unary.py", line 153, in retry_target
[2024-09-10T16:55:26.344+0530] {subprocess.py:93} INFO -     _retry_error_helper(
[2024-09-10T16:55:26.344+0530] {subprocess.py:93} INFO -   File "/home/sst7260/airflow_projects/project1/env/lib/python3.10/site-packages/google/api_core/retry/retry_base.py", line 212, in _retry_error_helper
[2024-09-10T16:55:26.344+0530] {subprocess.py:93} INFO -     raise final_exc from source_exc
[2024-09-10T16:55:26.344+0530] {subprocess.py:93} INFO -   File "/home/sst7260/airflow_projects/project1/env/lib/python3.10/site-packages/google/api_core/retry/retry_unary.py", line 144, in retry_target
[2024-09-10T16:55:26.344+0530] {subprocess.py:93} INFO -     result = target()
[2024-09-10T16:55:26.344+0530] {subprocess.py:93} INFO -   File "/home/sst7260/airflow_projects/project1/env/lib/python3.10/site-packages/google/cloud/_http/__init__.py", line 482, in api_request
[2024-09-10T16:55:26.344+0530] {subprocess.py:93} INFO -     response = self._make_request(
[2024-09-10T16:55:26.344+0530] {subprocess.py:93} INFO -   File "/home/sst7260/airflow_projects/project1/env/lib/python3.10/site-packages/google/cloud/_http/__init__.py", line 341, in _make_request
[2024-09-10T16:55:26.344+0530] {subprocess.py:93} INFO -     return self._do_request(
[2024-09-10T16:55:26.344+0530] {subprocess.py:93} INFO -   File "/home/sst7260/airflow_projects/project1/env/lib/python3.10/site-packages/google/cloud/_http/__init__.py", line 379, in _do_request
[2024-09-10T16:55:26.344+0530] {subprocess.py:93} INFO -     return self.http.request(
[2024-09-10T16:55:26.344+0530] {subprocess.py:93} INFO -   File "/home/sst7260/airflow_projects/project1/env/lib/python3.10/site-packages/google/auth/transport/requests.py", line 574, in request
[2024-09-10T16:55:26.344+0530] {subprocess.py:93} INFO -     self.credentials.refresh(auth_request)
[2024-09-10T16:55:26.345+0530] {subprocess.py:93} INFO -   File "/home/sst7260/airflow_projects/project1/env/lib/python3.10/site-packages/google/auth/credentials.py", line 311, in refresh
[2024-09-10T16:55:26.345+0530] {subprocess.py:93} INFO -     raise exceptions.InvalidOperation("Anonymous credentials cannot be refreshed.")
[2024-09-10T16:55:26.345+0530] {subprocess.py:93} INFO - 
[2024-09-10T16:55:28.503+0530] {local_task_job_runner.py:318} WARNING - Recorded pid 207600 does not match the current pid 207201
[2024-09-10T16:55:28.504+0530] {local_task_job_runner.py:218} WARNING - Heartbeat failed with Exception: PID of job runner does not match
[2024-09-10T16:55:33.534+0530] {local_task_job_runner.py:318} WARNING - Recorded pid 207600 does not match the current pid 207201
[2024-09-10T16:55:33.534+0530] {local_task_job_runner.py:218} WARNING - Heartbeat failed with Exception: PID of job runner does not match
[2024-09-10T16:55:38.557+0530] {local_task_job_runner.py:318} WARNING - Recorded pid 207600 does not match the current pid 207201
[2024-09-10T16:55:38.557+0530] {local_task_job_runner.py:218} WARNING - Heartbeat failed with Exception: PID of job runner does not match
[2024-09-10T16:55:43.597+0530] {local_task_job_runner.py:318} WARNING - Recorded pid 207600 does not match the current pid 207201
[2024-09-10T16:55:43.597+0530] {local_task_job_runner.py:218} WARNING - Heartbeat failed with Exception: PID of job runner does not match
[2024-09-10T16:55:48.636+0530] {local_task_job_runner.py:318} WARNING - Recorded pid 207600 does not match the current pid 207201
[2024-09-10T16:55:48.636+0530] {local_task_job_runner.py:218} WARNING - Heartbeat failed with Exception: PID of job runner does not match
[2024-09-10T16:55:53.667+0530] {local_task_job_runner.py:318} WARNING - Recorded pid 207600 does not match the current pid 207201
[2024-09-10T16:55:53.668+0530] {local_task_job_runner.py:218} WARNING - Heartbeat failed with Exception: PID of job runner does not match
[2024-09-10T16:55:58.730+0530] {local_task_job_runner.py:318} WARNING - Recorded pid 207600 does not match the current pid 207201
[2024-09-10T16:55:58.730+0530] {local_task_job_runner.py:218} WARNING - Heartbeat failed with Exception: PID of job runner does not match
[2024-09-10T16:56:00.203+0530] {subprocess.py:93} INFO - WARNING:apache_beam.utils.retry:Retry with exponential backoff: waiting for 75.142694064616 seconds before retrying _gcs_object because we caught exception: google.auth.exceptions.InvalidOperation: Anonymous credentials cannot be refreshed.
[2024-09-10T16:56:00.204+0530] {subprocess.py:93} INFO -  Traceback for above exception (most recent call last):
[2024-09-10T16:56:00.205+0530] {subprocess.py:93} INFO -   File "/home/sst7260/airflow_projects/project1/env/lib/python3.10/site-packages/apache_beam/utils/retry.py", line 298, in wrapper
[2024-09-10T16:56:00.205+0530] {subprocess.py:93} INFO -     return fun(*args, **kwargs)
[2024-09-10T16:56:00.205+0530] {subprocess.py:93} INFO -   File "/home/sst7260/airflow_projects/project1/env/lib/python3.10/site-packages/apache_beam/io/gcp/gcsio.py", line 462, in _gcs_object
[2024-09-10T16:56:00.205+0530] {subprocess.py:93} INFO -     blob = bucket.get_blob(blob_name)
[2024-09-10T16:56:00.205+0530] {subprocess.py:93} INFO -   File "/usr/lib/python3.10/contextlib.py", line 79, in inner
[2024-09-10T16:56:00.205+0530] {subprocess.py:93} INFO -     return func(*args, **kwds)
[2024-09-10T16:56:00.205+0530] {subprocess.py:93} INFO -   File "/home/sst7260/airflow_projects/project1/env/lib/python3.10/site-packages/google/cloud/storage/bucket.py", line 1283, in get_blob
[2024-09-10T16:56:00.205+0530] {subprocess.py:93} INFO -     blob.reload(
[2024-09-10T16:56:00.205+0530] {subprocess.py:93} INFO -   File "/home/sst7260/airflow_projects/project1/env/lib/python3.10/site-packages/google/cloud/storage/_helpers.py", line 300, in reload
[2024-09-10T16:56:00.205+0530] {subprocess.py:93} INFO -     api_response = client._get_resource(
[2024-09-10T16:56:00.206+0530] {subprocess.py:93} INFO -   File "/home/sst7260/airflow_projects/project1/env/lib/python3.10/site-packages/google/cloud/storage/client.py", line 464, in _get_resource
[2024-09-10T16:56:00.206+0530] {subprocess.py:93} INFO -     return self._connection.api_request(
[2024-09-10T16:56:00.206+0530] {subprocess.py:93} INFO -   File "/home/sst7260/airflow_projects/project1/env/lib/python3.10/site-packages/google/cloud/storage/_http.py", line 90, in api_request
[2024-09-10T16:56:00.206+0530] {subprocess.py:93} INFO -     return call()
[2024-09-10T16:56:00.206+0530] {subprocess.py:93} INFO -   File "/home/sst7260/airflow_projects/project1/env/lib/python3.10/site-packages/google/api_core/retry/retry_unary.py", line 293, in retry_wrapped_func
[2024-09-10T16:56:00.206+0530] {subprocess.py:93} INFO -     return retry_target(
[2024-09-10T16:56:00.206+0530] {subprocess.py:93} INFO -   File "/home/sst7260/airflow_projects/project1/env/lib/python3.10/site-packages/google/api_core/retry/retry_unary.py", line 153, in retry_target
[2024-09-10T16:56:00.206+0530] {subprocess.py:93} INFO -     _retry_error_helper(
[2024-09-10T16:56:00.206+0530] {subprocess.py:93} INFO -   File "/home/sst7260/airflow_projects/project1/env/lib/python3.10/site-packages/google/api_core/retry/retry_base.py", line 212, in _retry_error_helper
[2024-09-10T16:56:00.207+0530] {subprocess.py:93} INFO -     raise final_exc from source_exc
[2024-09-10T16:56:00.207+0530] {subprocess.py:93} INFO -   File "/home/sst7260/airflow_projects/project1/env/lib/python3.10/site-packages/google/api_core/retry/retry_unary.py", line 144, in retry_target
[2024-09-10T16:56:00.207+0530] {subprocess.py:93} INFO -     result = target()
[2024-09-10T16:56:00.207+0530] {subprocess.py:93} INFO -   File "/home/sst7260/airflow_projects/project1/env/lib/python3.10/site-packages/google/cloud/_http/__init__.py", line 482, in api_request
[2024-09-10T16:56:00.207+0530] {subprocess.py:93} INFO -     response = self._make_request(
[2024-09-10T16:56:00.207+0530] {subprocess.py:93} INFO -   File "/home/sst7260/airflow_projects/project1/env/lib/python3.10/site-packages/google/cloud/_http/__init__.py", line 341, in _make_request
[2024-09-10T16:56:00.207+0530] {subprocess.py:93} INFO -     return self._do_request(
[2024-09-10T16:56:00.207+0530] {subprocess.py:93} INFO -   File "/home/sst7260/airflow_projects/project1/env/lib/python3.10/site-packages/google/cloud/_http/__init__.py", line 379, in _do_request
[2024-09-10T16:56:00.208+0530] {subprocess.py:93} INFO -     return self.http.request(
[2024-09-10T16:56:00.208+0530] {subprocess.py:93} INFO -   File "/home/sst7260/airflow_projects/project1/env/lib/python3.10/site-packages/google/auth/transport/requests.py", line 574, in request
[2024-09-10T16:56:00.208+0530] {subprocess.py:93} INFO -     self.credentials.refresh(auth_request)
[2024-09-10T16:56:00.208+0530] {subprocess.py:93} INFO -   File "/home/sst7260/airflow_projects/project1/env/lib/python3.10/site-packages/google/auth/credentials.py", line 311, in refresh
[2024-09-10T16:56:00.208+0530] {subprocess.py:93} INFO -     raise exceptions.InvalidOperation("Anonymous credentials cannot be refreshed.")
[2024-09-10T16:56:00.208+0530] {subprocess.py:93} INFO - 
[2024-09-10T16:56:03.795+0530] {local_task_job_runner.py:318} WARNING - Recorded pid 207600 does not match the current pid 207201
[2024-09-10T16:56:03.795+0530] {local_task_job_runner.py:218} WARNING - Heartbeat failed with Exception: PID of job runner does not match
[2024-09-10T16:56:08.822+0530] {local_task_job_runner.py:318} WARNING - Recorded pid 207600 does not match the current pid 207201
[2024-09-10T16:56:08.822+0530] {local_task_job_runner.py:218} WARNING - Heartbeat failed with Exception: PID of job runner does not match
[2024-09-10T16:56:13.848+0530] {local_task_job_runner.py:318} WARNING - Recorded pid 207600 does not match the current pid 207201
[2024-09-10T16:56:13.849+0530] {local_task_job_runner.py:218} WARNING - Heartbeat failed with Exception: PID of job runner does not match
[2024-09-10T16:56:18.972+0530] {local_task_job_runner.py:318} WARNING - Recorded pid 207600 does not match the current pid 207201
[2024-09-10T16:56:18.972+0530] {local_task_job_runner.py:218} WARNING - Heartbeat failed with Exception: PID of job runner does not match
[2024-09-10T16:56:24.000+0530] {local_task_job_runner.py:318} WARNING - Recorded pid 207600 does not match the current pid 207201
[2024-09-10T16:56:24.000+0530] {local_task_job_runner.py:218} WARNING - Heartbeat failed with Exception: PID of job runner does not match
[2024-09-10T16:56:29.031+0530] {local_task_job_runner.py:318} WARNING - Recorded pid 207600 does not match the current pid 207201
[2024-09-10T16:56:29.031+0530] {local_task_job_runner.py:218} WARNING - Heartbeat failed with Exception: PID of job runner does not match
[2024-09-10T16:56:34.056+0530] {local_task_job_runner.py:318} WARNING - Recorded pid 207600 does not match the current pid 207201
[2024-09-10T16:56:34.057+0530] {local_task_job_runner.py:218} WARNING - Heartbeat failed with Exception: PID of job runner does not match
[2024-09-10T16:56:39.085+0530] {local_task_job_runner.py:318} WARNING - Recorded pid 207600 does not match the current pid 207201
[2024-09-10T16:56:39.086+0530] {local_task_job_runner.py:218} WARNING - Heartbeat failed with Exception: PID of job runner does not match
[2024-09-10T16:56:44.110+0530] {local_task_job_runner.py:318} WARNING - Recorded pid 207600 does not match the current pid 207201
[2024-09-10T16:56:44.111+0530] {local_task_job_runner.py:218} WARNING - Heartbeat failed with Exception: PID of job runner does not match
[2024-09-10T16:56:49.138+0530] {local_task_job_runner.py:318} WARNING - Recorded pid 207600 does not match the current pid 207201
[2024-09-10T16:56:49.139+0530] {local_task_job_runner.py:218} WARNING - Heartbeat failed with Exception: PID of job runner does not match
[2024-09-10T16:56:54.211+0530] {local_task_job_runner.py:318} WARNING - Recorded pid 207600 does not match the current pid 207201
[2024-09-10T16:56:54.212+0530] {local_task_job_runner.py:218} WARNING - Heartbeat failed with Exception: PID of job runner does not match
[2024-09-10T16:56:59.248+0530] {local_task_job_runner.py:318} WARNING - Recorded pid 207600 does not match the current pid 207201
[2024-09-10T16:56:59.249+0530] {local_task_job_runner.py:218} WARNING - Heartbeat failed with Exception: PID of job runner does not match
[2024-09-10T16:57:04.281+0530] {local_task_job_runner.py:318} WARNING - Recorded pid 207600 does not match the current pid 207201
[2024-09-10T16:57:04.281+0530] {local_task_job_runner.py:218} WARNING - Heartbeat failed with Exception: PID of job runner does not match
[2024-09-10T16:57:09.309+0530] {local_task_job_runner.py:318} WARNING - Recorded pid 207600 does not match the current pid 207201
[2024-09-10T16:57:09.309+0530] {local_task_job_runner.py:218} WARNING - Heartbeat failed with Exception: PID of job runner does not match
[2024-09-10T16:57:14.337+0530] {local_task_job_runner.py:318} WARNING - Recorded pid 207600 does not match the current pid 207201
[2024-09-10T16:57:14.338+0530] {local_task_job_runner.py:218} WARNING - Heartbeat failed with Exception: PID of job runner does not match
[2024-09-10T16:57:15.808+0530] {subprocess.py:93} INFO - WARNING:apache_beam.utils.retry:Retry with exponential backoff: waiting for 84.21767692635794 seconds before retrying _gcs_object because we caught exception: google.auth.exceptions.InvalidOperation: Anonymous credentials cannot be refreshed.
[2024-09-10T16:57:15.808+0530] {subprocess.py:93} INFO -  Traceback for above exception (most recent call last):
[2024-09-10T16:57:15.808+0530] {subprocess.py:93} INFO -   File "/home/sst7260/airflow_projects/project1/env/lib/python3.10/site-packages/apache_beam/utils/retry.py", line 298, in wrapper
[2024-09-10T16:57:15.808+0530] {subprocess.py:93} INFO -     return fun(*args, **kwargs)
[2024-09-10T16:57:15.808+0530] {subprocess.py:93} INFO -   File "/home/sst7260/airflow_projects/project1/env/lib/python3.10/site-packages/apache_beam/io/gcp/gcsio.py", line 462, in _gcs_object
[2024-09-10T16:57:15.809+0530] {subprocess.py:93} INFO -     blob = bucket.get_blob(blob_name)
[2024-09-10T16:57:15.809+0530] {subprocess.py:93} INFO -   File "/usr/lib/python3.10/contextlib.py", line 79, in inner
[2024-09-10T16:57:15.809+0530] {subprocess.py:93} INFO -     return func(*args, **kwds)
[2024-09-10T16:57:15.809+0530] {subprocess.py:93} INFO -   File "/home/sst7260/airflow_projects/project1/env/lib/python3.10/site-packages/google/cloud/storage/bucket.py", line 1283, in get_blob
[2024-09-10T16:57:15.809+0530] {subprocess.py:93} INFO -     blob.reload(
[2024-09-10T16:57:15.809+0530] {subprocess.py:93} INFO -   File "/home/sst7260/airflow_projects/project1/env/lib/python3.10/site-packages/google/cloud/storage/_helpers.py", line 300, in reload
[2024-09-10T16:57:15.809+0530] {subprocess.py:93} INFO -     api_response = client._get_resource(
[2024-09-10T16:57:15.809+0530] {subprocess.py:93} INFO -   File "/home/sst7260/airflow_projects/project1/env/lib/python3.10/site-packages/google/cloud/storage/client.py", line 464, in _get_resource
[2024-09-10T16:57:15.809+0530] {subprocess.py:93} INFO -     return self._connection.api_request(
[2024-09-10T16:57:15.809+0530] {subprocess.py:93} INFO -   File "/home/sst7260/airflow_projects/project1/env/lib/python3.10/site-packages/google/cloud/storage/_http.py", line 90, in api_request
[2024-09-10T16:57:15.809+0530] {subprocess.py:93} INFO -     return call()
[2024-09-10T16:57:15.809+0530] {subprocess.py:93} INFO -   File "/home/sst7260/airflow_projects/project1/env/lib/python3.10/site-packages/google/api_core/retry/retry_unary.py", line 293, in retry_wrapped_func
[2024-09-10T16:57:15.809+0530] {subprocess.py:93} INFO -     return retry_target(
[2024-09-10T16:57:15.809+0530] {subprocess.py:93} INFO -   File "/home/sst7260/airflow_projects/project1/env/lib/python3.10/site-packages/google/api_core/retry/retry_unary.py", line 153, in retry_target
[2024-09-10T16:57:15.809+0530] {subprocess.py:93} INFO -     _retry_error_helper(
[2024-09-10T16:57:15.809+0530] {subprocess.py:93} INFO -   File "/home/sst7260/airflow_projects/project1/env/lib/python3.10/site-packages/google/api_core/retry/retry_base.py", line 212, in _retry_error_helper
[2024-09-10T16:57:15.810+0530] {subprocess.py:93} INFO -     raise final_exc from source_exc
[2024-09-10T16:57:15.810+0530] {subprocess.py:93} INFO -   File "/home/sst7260/airflow_projects/project1/env/lib/python3.10/site-packages/google/api_core/retry/retry_unary.py", line 144, in retry_target
[2024-09-10T16:57:15.810+0530] {subprocess.py:93} INFO -     result = target()
[2024-09-10T16:57:15.810+0530] {subprocess.py:93} INFO -   File "/home/sst7260/airflow_projects/project1/env/lib/python3.10/site-packages/google/cloud/_http/__init__.py", line 482, in api_request
[2024-09-10T16:57:15.810+0530] {subprocess.py:93} INFO -     response = self._make_request(
[2024-09-10T16:57:15.810+0530] {subprocess.py:93} INFO -   File "/home/sst7260/airflow_projects/project1/env/lib/python3.10/site-packages/google/cloud/_http/__init__.py", line 341, in _make_request
[2024-09-10T16:57:15.810+0530] {subprocess.py:93} INFO -     return self._do_request(
[2024-09-10T16:57:15.810+0530] {subprocess.py:93} INFO -   File "/home/sst7260/airflow_projects/project1/env/lib/python3.10/site-packages/google/cloud/_http/__init__.py", line 379, in _do_request
[2024-09-10T16:57:15.810+0530] {subprocess.py:93} INFO -     return self.http.request(
[2024-09-10T16:57:15.810+0530] {subprocess.py:93} INFO -   File "/home/sst7260/airflow_projects/project1/env/lib/python3.10/site-packages/google/auth/transport/requests.py", line 574, in request
[2024-09-10T16:57:15.810+0530] {subprocess.py:93} INFO -     self.credentials.refresh(auth_request)
[2024-09-10T16:57:15.810+0530] {subprocess.py:93} INFO -   File "/home/sst7260/airflow_projects/project1/env/lib/python3.10/site-packages/google/auth/credentials.py", line 311, in refresh
[2024-09-10T16:57:15.810+0530] {subprocess.py:93} INFO -     raise exceptions.InvalidOperation("Anonymous credentials cannot be refreshed.")
[2024-09-10T16:57:15.810+0530] {subprocess.py:93} INFO - 
[2024-09-10T16:57:19.365+0530] {local_task_job_runner.py:318} WARNING - Recorded pid 207600 does not match the current pid 207201
[2024-09-10T16:57:19.366+0530] {local_task_job_runner.py:218} WARNING - Heartbeat failed with Exception: PID of job runner does not match
[2024-09-10T16:57:24.394+0530] {local_task_job_runner.py:318} WARNING - Recorded pid 207600 does not match the current pid 207201
[2024-09-10T16:57:24.395+0530] {local_task_job_runner.py:218} WARNING - Heartbeat failed with Exception: PID of job runner does not match
[2024-09-10T16:57:29.425+0530] {local_task_job_runner.py:318} WARNING - Recorded pid 207600 does not match the current pid 207201
[2024-09-10T16:57:29.425+0530] {local_task_job_runner.py:218} WARNING - Heartbeat failed with Exception: PID of job runner does not match
[2024-09-10T16:57:34.450+0530] {local_task_job_runner.py:318} WARNING - Recorded pid 207600 does not match the current pid 207201
[2024-09-10T16:57:34.451+0530] {local_task_job_runner.py:218} WARNING - Heartbeat failed with Exception: PID of job runner does not match
[2024-09-10T16:57:39.476+0530] {local_task_job_runner.py:318} WARNING - Recorded pid 207600 does not match the current pid 207201
[2024-09-10T16:57:39.477+0530] {local_task_job_runner.py:218} WARNING - Heartbeat failed with Exception: PID of job runner does not match
[2024-09-10T16:57:44.501+0530] {local_task_job_runner.py:318} WARNING - Recorded pid 207600 does not match the current pid 207201
[2024-09-10T16:57:44.501+0530] {local_task_job_runner.py:218} WARNING - Heartbeat failed with Exception: PID of job runner does not match
[2024-09-10T16:57:49.527+0530] {local_task_job_runner.py:318} WARNING - Recorded pid 207600 does not match the current pid 207201
[2024-09-10T16:57:49.527+0530] {local_task_job_runner.py:218} WARNING - Heartbeat failed with Exception: PID of job runner does not match
[2024-09-10T16:57:54.556+0530] {local_task_job_runner.py:318} WARNING - Recorded pid 207600 does not match the current pid 207201
[2024-09-10T16:57:54.557+0530] {local_task_job_runner.py:218} WARNING - Heartbeat failed with Exception: PID of job runner does not match
[2024-09-10T16:57:59.586+0530] {local_task_job_runner.py:318} WARNING - Recorded pid 207600 does not match the current pid 207201
[2024-09-10T16:57:59.587+0530] {local_task_job_runner.py:218} WARNING - Heartbeat failed with Exception: PID of job runner does not match
[2024-09-10T16:58:04.616+0530] {local_task_job_runner.py:318} WARNING - Recorded pid 207600 does not match the current pid 207201
[2024-09-10T16:58:04.616+0530] {local_task_job_runner.py:218} WARNING - Heartbeat failed with Exception: PID of job runner does not match
[2024-09-10T16:58:09.682+0530] {local_task_job_runner.py:318} WARNING - Recorded pid 207600 does not match the current pid 207201
[2024-09-10T16:58:09.683+0530] {local_task_job_runner.py:218} WARNING - Heartbeat failed with Exception: PID of job runner does not match
[2024-09-10T16:58:14.711+0530] {local_task_job_runner.py:318} WARNING - Recorded pid 207600 does not match the current pid 207201
[2024-09-10T16:58:14.712+0530] {local_task_job_runner.py:218} WARNING - Heartbeat failed with Exception: PID of job runner does not match
[2024-09-10T16:58:19.824+0530] {local_task_job_runner.py:318} WARNING - Recorded pid 207600 does not match the current pid 207201
[2024-09-10T16:58:19.824+0530] {local_task_job_runner.py:218} WARNING - Heartbeat failed with Exception: PID of job runner does not match
[2024-09-10T16:58:24.893+0530] {local_task_job_runner.py:318} WARNING - Recorded pid 207600 does not match the current pid 207201
[2024-09-10T16:58:24.894+0530] {local_task_job_runner.py:218} WARNING - Heartbeat failed with Exception: PID of job runner does not match
[2024-09-10T16:58:29.922+0530] {local_task_job_runner.py:318} WARNING - Recorded pid 207600 does not match the current pid 207201
[2024-09-10T16:58:29.922+0530] {local_task_job_runner.py:218} WARNING - Heartbeat failed with Exception: PID of job runner does not match
[2024-09-10T16:58:34.952+0530] {local_task_job_runner.py:318} WARNING - Recorded pid 207600 does not match the current pid 207201
[2024-09-10T16:58:34.953+0530] {local_task_job_runner.py:218} WARNING - Heartbeat failed with Exception: PID of job runner does not match
[2024-09-10T16:58:39.985+0530] {local_task_job_runner.py:318} WARNING - Recorded pid 207600 does not match the current pid 207201
[2024-09-10T16:58:39.985+0530] {local_task_job_runner.py:218} WARNING - Heartbeat failed with Exception: PID of job runner does not match
[2024-09-10T16:58:40.487+0530] {subprocess.py:93} INFO - WARNING:apache_beam.utils.retry:Retry with exponential backoff: waiting for 194.5018499865531 seconds before retrying _gcs_object because we caught exception: google.auth.exceptions.InvalidOperation: Anonymous credentials cannot be refreshed.
[2024-09-10T16:58:40.488+0530] {subprocess.py:93} INFO -  Traceback for above exception (most recent call last):
[2024-09-10T16:58:40.488+0530] {subprocess.py:93} INFO -   File "/home/sst7260/airflow_projects/project1/env/lib/python3.10/site-packages/apache_beam/utils/retry.py", line 298, in wrapper
[2024-09-10T16:58:40.488+0530] {subprocess.py:93} INFO -     return fun(*args, **kwargs)
[2024-09-10T16:58:40.488+0530] {subprocess.py:93} INFO -   File "/home/sst7260/airflow_projects/project1/env/lib/python3.10/site-packages/apache_beam/io/gcp/gcsio.py", line 462, in _gcs_object
[2024-09-10T16:58:40.488+0530] {subprocess.py:93} INFO -     blob = bucket.get_blob(blob_name)
[2024-09-10T16:58:40.488+0530] {subprocess.py:93} INFO -   File "/usr/lib/python3.10/contextlib.py", line 79, in inner
[2024-09-10T16:58:40.489+0530] {subprocess.py:93} INFO -     return func(*args, **kwds)
[2024-09-10T16:58:40.489+0530] {subprocess.py:93} INFO -   File "/home/sst7260/airflow_projects/project1/env/lib/python3.10/site-packages/google/cloud/storage/bucket.py", line 1283, in get_blob
[2024-09-10T16:58:40.489+0530] {subprocess.py:93} INFO -     blob.reload(
[2024-09-10T16:58:40.489+0530] {subprocess.py:93} INFO -   File "/home/sst7260/airflow_projects/project1/env/lib/python3.10/site-packages/google/cloud/storage/_helpers.py", line 300, in reload
[2024-09-10T16:58:40.489+0530] {subprocess.py:93} INFO -     api_response = client._get_resource(
[2024-09-10T16:58:40.489+0530] {subprocess.py:93} INFO -   File "/home/sst7260/airflow_projects/project1/env/lib/python3.10/site-packages/google/cloud/storage/client.py", line 464, in _get_resource
[2024-09-10T16:58:40.489+0530] {subprocess.py:93} INFO -     return self._connection.api_request(
[2024-09-10T16:58:40.489+0530] {subprocess.py:93} INFO -   File "/home/sst7260/airflow_projects/project1/env/lib/python3.10/site-packages/google/cloud/storage/_http.py", line 90, in api_request
[2024-09-10T16:58:40.489+0530] {subprocess.py:93} INFO -     return call()
[2024-09-10T16:58:40.489+0530] {subprocess.py:93} INFO -   File "/home/sst7260/airflow_projects/project1/env/lib/python3.10/site-packages/google/api_core/retry/retry_unary.py", line 293, in retry_wrapped_func
[2024-09-10T16:58:40.489+0530] {subprocess.py:93} INFO -     return retry_target(
[2024-09-10T16:58:40.490+0530] {subprocess.py:93} INFO -   File "/home/sst7260/airflow_projects/project1/env/lib/python3.10/site-packages/google/api_core/retry/retry_unary.py", line 153, in retry_target
[2024-09-10T16:58:40.490+0530] {subprocess.py:93} INFO -     _retry_error_helper(
[2024-09-10T16:58:40.490+0530] {subprocess.py:93} INFO -   File "/home/sst7260/airflow_projects/project1/env/lib/python3.10/site-packages/google/api_core/retry/retry_base.py", line 212, in _retry_error_helper
[2024-09-10T16:58:40.490+0530] {subprocess.py:93} INFO -     raise final_exc from source_exc
[2024-09-10T16:58:40.490+0530] {subprocess.py:93} INFO -   File "/home/sst7260/airflow_projects/project1/env/lib/python3.10/site-packages/google/api_core/retry/retry_unary.py", line 144, in retry_target
[2024-09-10T16:58:40.490+0530] {subprocess.py:93} INFO -     result = target()
[2024-09-10T16:58:40.490+0530] {subprocess.py:93} INFO -   File "/home/sst7260/airflow_projects/project1/env/lib/python3.10/site-packages/google/cloud/_http/__init__.py", line 482, in api_request
[2024-09-10T16:58:40.490+0530] {subprocess.py:93} INFO -     response = self._make_request(
[2024-09-10T16:58:40.490+0530] {subprocess.py:93} INFO -   File "/home/sst7260/airflow_projects/project1/env/lib/python3.10/site-packages/google/cloud/_http/__init__.py", line 341, in _make_request
[2024-09-10T16:58:40.490+0530] {subprocess.py:93} INFO -     return self._do_request(
[2024-09-10T16:58:40.490+0530] {subprocess.py:93} INFO -   File "/home/sst7260/airflow_projects/project1/env/lib/python3.10/site-packages/google/cloud/_http/__init__.py", line 379, in _do_request
[2024-09-10T16:58:40.490+0530] {subprocess.py:93} INFO -     return self.http.request(
[2024-09-10T16:58:40.490+0530] {subprocess.py:93} INFO -   File "/home/sst7260/airflow_projects/project1/env/lib/python3.10/site-packages/google/auth/transport/requests.py", line 574, in request
[2024-09-10T16:58:40.490+0530] {subprocess.py:93} INFO -     self.credentials.refresh(auth_request)
[2024-09-10T16:58:40.490+0530] {subprocess.py:93} INFO -   File "/home/sst7260/airflow_projects/project1/env/lib/python3.10/site-packages/google/auth/credentials.py", line 311, in refresh
[2024-09-10T16:58:40.490+0530] {subprocess.py:93} INFO -     raise exceptions.InvalidOperation("Anonymous credentials cannot be refreshed.")
[2024-09-10T16:58:40.490+0530] {subprocess.py:93} INFO - 
[2024-09-10T16:58:45.011+0530] {local_task_job_runner.py:318} WARNING - Recorded pid 207600 does not match the current pid 207201
[2024-09-10T16:58:45.012+0530] {local_task_job_runner.py:218} WARNING - Heartbeat failed with Exception: PID of job runner does not match
[2024-09-10T16:58:50.046+0530] {local_task_job_runner.py:318} WARNING - Recorded pid 207600 does not match the current pid 207201
[2024-09-10T16:58:50.047+0530] {local_task_job_runner.py:218} WARNING - Heartbeat failed with Exception: PID of job runner does not match
[2024-09-10T16:58:55.114+0530] {local_task_job_runner.py:318} WARNING - Recorded pid 207600 does not match the current pid 207201
[2024-09-10T16:58:55.115+0530] {local_task_job_runner.py:218} WARNING - Heartbeat failed with Exception: PID of job runner does not match
[2024-09-10T16:59:00.180+0530] {local_task_job_runner.py:318} WARNING - Recorded pid 207600 does not match the current pid 207201
[2024-09-10T16:59:00.181+0530] {local_task_job_runner.py:218} WARNING - Heartbeat failed with Exception: PID of job runner does not match
[2024-09-10T16:59:05.220+0530] {local_task_job_runner.py:318} WARNING - Recorded pid 207600 does not match the current pid 207201
[2024-09-10T16:59:05.220+0530] {local_task_job_runner.py:218} WARNING - Heartbeat failed with Exception: PID of job runner does not match
[2024-09-10T16:59:10.255+0530] {local_task_job_runner.py:318} WARNING - Recorded pid 207600 does not match the current pid 207201
[2024-09-10T16:59:10.255+0530] {local_task_job_runner.py:218} WARNING - Heartbeat failed with Exception: PID of job runner does not match
[2024-09-10T16:59:15.320+0530] {local_task_job_runner.py:318} WARNING - Recorded pid 207600 does not match the current pid 207201
[2024-09-10T16:59:15.321+0530] {local_task_job_runner.py:218} WARNING - Heartbeat failed with Exception: PID of job runner does not match
[2024-09-10T16:59:20.353+0530] {local_task_job_runner.py:318} WARNING - Recorded pid 207600 does not match the current pid 207201
[2024-09-10T16:59:20.353+0530] {local_task_job_runner.py:218} WARNING - Heartbeat failed with Exception: PID of job runner does not match
[2024-09-10T16:59:25.382+0530] {local_task_job_runner.py:318} WARNING - Recorded pid 207600 does not match the current pid 207201
[2024-09-10T16:59:25.383+0530] {local_task_job_runner.py:218} WARNING - Heartbeat failed with Exception: PID of job runner does not match
[2024-09-10T16:59:30.456+0530] {local_task_job_runner.py:318} WARNING - Recorded pid 207600 does not match the current pid 207201
[2024-09-10T16:59:30.456+0530] {local_task_job_runner.py:218} WARNING - Heartbeat failed with Exception: PID of job runner does not match
[2024-09-10T16:59:35.610+0530] {local_task_job_runner.py:318} WARNING - Recorded pid 207600 does not match the current pid 207201
[2024-09-10T16:59:35.611+0530] {local_task_job_runner.py:218} WARNING - Heartbeat failed with Exception: PID of job runner does not match
[2024-09-10T16:59:40.665+0530] {local_task_job_runner.py:318} WARNING - Recorded pid 207600 does not match the current pid 207201
[2024-09-10T16:59:40.666+0530] {local_task_job_runner.py:218} WARNING - Heartbeat failed with Exception: PID of job runner does not match
[2024-09-10T16:59:45.694+0530] {local_task_job_runner.py:318} WARNING - Recorded pid 207600 does not match the current pid 207201
[2024-09-10T16:59:45.695+0530] {local_task_job_runner.py:218} WARNING - Heartbeat failed with Exception: PID of job runner does not match
[2024-09-10T16:59:50.733+0530] {local_task_job_runner.py:318} WARNING - Recorded pid 207600 does not match the current pid 207201
[2024-09-10T16:59:50.733+0530] {local_task_job_runner.py:218} WARNING - Heartbeat failed with Exception: PID of job runner does not match
[2024-09-10T16:59:55.764+0530] {local_task_job_runner.py:318} WARNING - Recorded pid 207600 does not match the current pid 207201
[2024-09-10T16:59:55.764+0530] {local_task_job_runner.py:218} WARNING - Heartbeat failed with Exception: PID of job runner does not match
[2024-09-10T17:00:00.807+0530] {local_task_job_runner.py:318} WARNING - Recorded pid 207600 does not match the current pid 207201
[2024-09-10T17:00:00.808+0530] {local_task_job_runner.py:218} WARNING - Heartbeat failed with Exception: PID of job runner does not match
[2024-09-10T17:00:05.852+0530] {local_task_job_runner.py:318} WARNING - Recorded pid 207600 does not match the current pid 207201
[2024-09-10T17:00:05.852+0530] {local_task_job_runner.py:218} WARNING - Heartbeat failed with Exception: PID of job runner does not match
[2024-09-10T17:00:10.914+0530] {local_task_job_runner.py:318} WARNING - Recorded pid 207600 does not match the current pid 207201
[2024-09-10T17:00:10.914+0530] {local_task_job_runner.py:218} WARNING - Heartbeat failed with Exception: PID of job runner does not match
[2024-09-10T17:00:16.045+0530] {local_task_job_runner.py:318} WARNING - Recorded pid 207600 does not match the current pid 207201
[2024-09-10T17:00:16.045+0530] {local_task_job_runner.py:218} WARNING - Heartbeat failed with Exception: PID of job runner does not match
[2024-09-10T17:00:21.123+0530] {local_task_job_runner.py:318} WARNING - Recorded pid 207600 does not match the current pid 207201
[2024-09-10T17:00:21.123+0530] {local_task_job_runner.py:218} WARNING - Heartbeat failed with Exception: PID of job runner does not match
[2024-09-10T17:00:26.155+0530] {local_task_job_runner.py:318} WARNING - Recorded pid 207600 does not match the current pid 207201
[2024-09-10T17:00:26.155+0530] {local_task_job_runner.py:218} WARNING - Heartbeat failed with Exception: PID of job runner does not match
[2024-09-10T17:00:31.187+0530] {local_task_job_runner.py:318} WARNING - Recorded pid 207600 does not match the current pid 207201
[2024-09-10T17:00:31.188+0530] {local_task_job_runner.py:218} WARNING - Heartbeat failed with Exception: PID of job runner does not match
[2024-09-10T17:00:36.228+0530] {local_task_job_runner.py:318} WARNING - Recorded pid 207600 does not match the current pid 207201
[2024-09-10T17:00:36.228+0530] {local_task_job_runner.py:218} WARNING - Heartbeat failed with Exception: PID of job runner does not match
[2024-09-10T17:00:41.255+0530] {local_task_job_runner.py:318} WARNING - Recorded pid 207600 does not match the current pid 207201
[2024-09-10T17:00:41.256+0530] {local_task_job_runner.py:218} WARNING - Heartbeat failed with Exception: PID of job runner does not match
[2024-09-10T17:00:46.286+0530] {local_task_job_runner.py:318} WARNING - Recorded pid 207600 does not match the current pid 207201
[2024-09-10T17:00:46.286+0530] {local_task_job_runner.py:218} WARNING - Heartbeat failed with Exception: PID of job runner does not match
[2024-09-10T17:00:51.335+0530] {local_task_job_runner.py:318} WARNING - Recorded pid 207600 does not match the current pid 207201
[2024-09-10T17:00:51.335+0530] {local_task_job_runner.py:218} WARNING - Heartbeat failed with Exception: PID of job runner does not match
[2024-09-10T17:00:56.373+0530] {local_task_job_runner.py:318} WARNING - Recorded pid 207600 does not match the current pid 207201
[2024-09-10T17:00:56.373+0530] {local_task_job_runner.py:218} WARNING - Heartbeat failed with Exception: PID of job runner does not match
[2024-09-10T17:01:01.408+0530] {local_task_job_runner.py:318} WARNING - Recorded pid 207600 does not match the current pid 207201
[2024-09-10T17:01:01.409+0530] {local_task_job_runner.py:218} WARNING - Heartbeat failed with Exception: PID of job runner does not match
[2024-09-10T17:01:06.442+0530] {local_task_job_runner.py:318} WARNING - Recorded pid 207600 does not match the current pid 207201
[2024-09-10T17:01:06.443+0530] {local_task_job_runner.py:218} WARNING - Heartbeat failed with Exception: PID of job runner does not match
[2024-09-10T17:01:11.471+0530] {local_task_job_runner.py:318} WARNING - Recorded pid 207600 does not match the current pid 207201
[2024-09-10T17:01:11.471+0530] {local_task_job_runner.py:218} WARNING - Heartbeat failed with Exception: PID of job runner does not match
[2024-09-10T17:01:16.507+0530] {local_task_job_runner.py:318} WARNING - Recorded pid 207600 does not match the current pid 207201
[2024-09-10T17:01:16.507+0530] {local_task_job_runner.py:218} WARNING - Heartbeat failed with Exception: PID of job runner does not match
[2024-09-10T17:01:21.549+0530] {local_task_job_runner.py:318} WARNING - Recorded pid 207600 does not match the current pid 207201
[2024-09-10T17:01:21.549+0530] {local_task_job_runner.py:218} WARNING - Heartbeat failed with Exception: PID of job runner does not match
[2024-09-10T17:01:26.593+0530] {local_task_job_runner.py:318} WARNING - Recorded pid 207600 does not match the current pid 207201
[2024-09-10T17:01:26.593+0530] {local_task_job_runner.py:218} WARNING - Heartbeat failed with Exception: PID of job runner does not match
[2024-09-10T17:01:31.665+0530] {local_task_job_runner.py:318} WARNING - Recorded pid 207600 does not match the current pid 207201
[2024-09-10T17:01:31.665+0530] {local_task_job_runner.py:218} WARNING - Heartbeat failed with Exception: PID of job runner does not match
[2024-09-10T17:01:36.705+0530] {local_task_job_runner.py:318} WARNING - Recorded pid 207600 does not match the current pid 207201
[2024-09-10T17:01:36.705+0530] {local_task_job_runner.py:218} WARNING - Heartbeat failed with Exception: PID of job runner does not match
[2024-09-10T17:01:41.761+0530] {local_task_job_runner.py:318} WARNING - Recorded pid 207600 does not match the current pid 207201
[2024-09-10T17:01:41.762+0530] {local_task_job_runner.py:218} WARNING - Heartbeat failed with Exception: PID of job runner does not match
[2024-09-10T17:01:46.793+0530] {local_task_job_runner.py:318} WARNING - Recorded pid 207600 does not match the current pid 207201
[2024-09-10T17:01:46.794+0530] {local_task_job_runner.py:218} WARNING - Heartbeat failed with Exception: PID of job runner does not match
[2024-09-10T17:01:51.828+0530] {local_task_job_runner.py:318} WARNING - Recorded pid 207600 does not match the current pid 207201
[2024-09-10T17:01:51.828+0530] {local_task_job_runner.py:218} WARNING - Heartbeat failed with Exception: PID of job runner does not match
[2024-09-10T17:01:55.554+0530] {subprocess.py:93} INFO - Traceback (most recent call last):
[2024-09-10T17:01:55.576+0530] {subprocess.py:93} INFO -   File "/home/sst7260/airflow_projects/project1/beam_scripts/etl_pipe_1.py", line 53, in <module>
[2024-09-10T17:01:55.576+0530] {subprocess.py:93} INFO -     )
[2024-09-10T17:01:55.577+0530] {subprocess.py:93} INFO -   File "/home/sst7260/airflow_projects/project1/beam_scripts/etl_pipe_1.py", line 37, in transform_load
[2024-09-10T17:01:55.578+0530] {subprocess.py:93} INFO -     | 'Filter' >> beam.Filter(lambda x: x[1] in ['85123A', '71053', '84406B', '84029G'])
[2024-09-10T17:01:55.578+0530] {subprocess.py:93} INFO -   File "/home/sst7260/airflow_projects/project1/env/lib/python3.10/site-packages/apache_beam/io/textio.py", line 781, in __init__
[2024-09-10T17:01:55.579+0530] {subprocess.py:93} INFO -     self._source = self._source_class(
[2024-09-10T17:01:55.579+0530] {subprocess.py:93} INFO -   File "/home/sst7260/airflow_projects/project1/env/lib/python3.10/site-packages/apache_beam/io/textio.py", line 140, in __init__
[2024-09-10T17:01:55.579+0530] {subprocess.py:93} INFO -     super().__init__(
[2024-09-10T17:01:55.579+0530] {subprocess.py:93} INFO -   File "/home/sst7260/airflow_projects/project1/env/lib/python3.10/site-packages/apache_beam/io/filebasedsource.py", line 127, in __init__
[2024-09-10T17:01:55.580+0530] {subprocess.py:93} INFO -     self._validate()
[2024-09-10T17:01:55.580+0530] {subprocess.py:93} INFO -   File "/home/sst7260/airflow_projects/project1/env/lib/python3.10/site-packages/apache_beam/options/value_provider.py", line 193, in _f
[2024-09-10T17:01:55.580+0530] {subprocess.py:93} INFO -     return fnc(self, *args, **kwargs)
[2024-09-10T17:01:55.580+0530] {subprocess.py:93} INFO -   File "/home/sst7260/airflow_projects/project1/env/lib/python3.10/site-packages/apache_beam/io/filebasedsource.py", line 188, in _validate
[2024-09-10T17:01:55.580+0530] {subprocess.py:93} INFO -     match_result = FileSystems.match([pattern], limits=[1])[0]
[2024-09-10T17:01:55.580+0530] {subprocess.py:93} INFO -   File "/home/sst7260/airflow_projects/project1/env/lib/python3.10/site-packages/apache_beam/io/filesystems.py", line 239, in match
[2024-09-10T17:01:55.581+0530] {subprocess.py:93} INFO -     return filesystem.match(patterns, limits)
[2024-09-10T17:01:55.581+0530] {subprocess.py:93} INFO -   File "/home/sst7260/airflow_projects/project1/env/lib/python3.10/site-packages/apache_beam/io/filesystem.py", line 804, in match
[2024-09-10T17:01:55.581+0530] {subprocess.py:93} INFO -     raise BeamIOError("Match operation failed", exceptions)
[2024-09-10T17:01:55.581+0530] {subprocess.py:93} INFO - apache_beam.io.filesystem.BeamIOError: Match operation failed with exceptions {'gs://sn_insights_test/input/OnlineRetail.csv': InvalidOperation('Anonymous credentials cannot be refreshed.')}
[2024-09-10T17:01:56.857+0530] {local_task_job_runner.py:318} WARNING - Recorded pid 207600 does not match the current pid 207201
[2024-09-10T17:01:56.858+0530] {local_task_job_runner.py:218} WARNING - Heartbeat failed with Exception: PID of job runner does not match
[2024-09-10T17:01:56.862+0530] {subprocess.py:97} INFO - Command exited with return code 1
[2024-09-10T17:01:57.218+0530] {taskinstance.py:3310} ERROR - Task failed with exception
Traceback (most recent call last):
  File "/home/sst7260/airflow_projects/project1/env/lib/python3.10/site-packages/airflow/models/taskinstance.py", line 767, in _execute_task
    result = _execute_callable(context=context, **execute_callable_kwargs)
  File "/home/sst7260/airflow_projects/project1/env/lib/python3.10/site-packages/airflow/models/taskinstance.py", line 733, in _execute_callable
    return ExecutionCallableRunner(
  File "/home/sst7260/airflow_projects/project1/env/lib/python3.10/site-packages/airflow/utils/operator_helpers.py", line 252, in run
    return self.func(*args, **kwargs)
  File "/home/sst7260/airflow_projects/project1/env/lib/python3.10/site-packages/airflow/models/baseoperator.py", line 406, in wrapper
    return func(self, *args, **kwargs)
  File "/home/sst7260/airflow_projects/project1/env/lib/python3.10/site-packages/airflow/operators/bash.py", line 249, in execute
    raise AirflowException(
airflow.exceptions.AirflowException: Bash command failed. The command returned a non-zero exit code 1.
[2024-09-10T17:01:57.305+0530] {logging_mixin.py:190} INFO - Task instance in failure state
[2024-09-10T17:01:57.306+0530] {logging_mixin.py:190} INFO - Task start:2024-09-10 11:24:28.219822+00:00 end:2024-09-10 11:31:57.275767+00:00 duration:449.055945
[2024-09-10T17:01:57.312+0530] {logging_mixin.py:190} INFO - Task:<Task(BashOperator): run_beam_pipeline2> dag:<DAG: apache_beam_etl_pipeline> dagrun:<DagRun apache_beam_etl_pipeline @ 2024-09-10 11:23:22.649352+00:00: manual__2024-09-10T11:23:22.649352+00:00, state:running, queued_at: 2024-09-10 11:23:22.708522+00:00. externally triggered: True>
[2024-09-10T17:01:57.313+0530] {logging_mixin.py:190} INFO - Failure caused by Bash command failed. The command returned a non-zero exit code 1.
[2024-09-10T17:01:57.314+0530] {taskinstance.py:1225} INFO - Marking task as FAILED. dag_id=apache_beam_etl_pipeline, task_id=run_beam_pipeline2, run_id=manual__2024-09-10T11:23:22.649352+00:00, execution_date=20240910T112322, start_date=20240910T112428, end_date=20240910T113157
[2024-09-10T17:01:57.430+0530] {taskinstance.py:340} INFO - ::group::Post task execution logs
[2024-09-10T17:01:57.439+0530] {standard_task_runner.py:124} ERROR - Failed to execute job 90 for task run_beam_pipeline2 (Bash command failed. The command returned a non-zero exit code 1.; 207201)
Traceback (most recent call last):
  File "/home/sst7260/airflow_projects/project1/env/lib/python3.10/site-packages/airflow/task/task_runner/standard_task_runner.py", line 117, in _start_by_fork
    ret = args.func(args, dag=self.dag)
  File "/home/sst7260/airflow_projects/project1/env/lib/python3.10/site-packages/airflow/cli/cli_config.py", line 49, in command
    return func(*args, **kwargs)
  File "/home/sst7260/airflow_projects/project1/env/lib/python3.10/site-packages/airflow/utils/cli.py", line 115, in wrapper
    return f(*args, **kwargs)
  File "/home/sst7260/airflow_projects/project1/env/lib/python3.10/site-packages/airflow/cli/commands/task_command.py", line 483, in task_run
    task_return_code = _run_task_by_selected_method(args, _dag, ti)
  File "/home/sst7260/airflow_projects/project1/env/lib/python3.10/site-packages/airflow/cli/commands/task_command.py", line 256, in _run_task_by_selected_method
    return _run_raw_task(args, ti)
  File "/home/sst7260/airflow_projects/project1/env/lib/python3.10/site-packages/airflow/cli/commands/task_command.py", line 341, in _run_raw_task
    return ti._run_raw_task(
  File "/home/sst7260/airflow_projects/project1/env/lib/python3.10/site-packages/airflow/utils/session.py", line 97, in wrapper
    return func(*args, session=session, **kwargs)
  File "/home/sst7260/airflow_projects/project1/env/lib/python3.10/site-packages/airflow/models/taskinstance.py", line 3004, in _run_raw_task
    return _run_raw_task(
  File "/home/sst7260/airflow_projects/project1/env/lib/python3.10/site-packages/airflow/models/taskinstance.py", line 273, in _run_raw_task
    TaskInstance._execute_task_with_callbacks(
  File "/home/sst7260/airflow_projects/project1/env/lib/python3.10/site-packages/airflow/models/taskinstance.py", line 3158, in _execute_task_with_callbacks
    result = self._execute_task(context, task_orig)
  File "/home/sst7260/airflow_projects/project1/env/lib/python3.10/site-packages/airflow/models/taskinstance.py", line 3182, in _execute_task
    return _execute_task(self, context, task_orig)
  File "/home/sst7260/airflow_projects/project1/env/lib/python3.10/site-packages/airflow/models/taskinstance.py", line 767, in _execute_task
    result = _execute_callable(context=context, **execute_callable_kwargs)
  File "/home/sst7260/airflow_projects/project1/env/lib/python3.10/site-packages/airflow/models/taskinstance.py", line 733, in _execute_callable
    return ExecutionCallableRunner(
  File "/home/sst7260/airflow_projects/project1/env/lib/python3.10/site-packages/airflow/utils/operator_helpers.py", line 252, in run
    return self.func(*args, **kwargs)
  File "/home/sst7260/airflow_projects/project1/env/lib/python3.10/site-packages/airflow/models/baseoperator.py", line 406, in wrapper
    return func(self, *args, **kwargs)
  File "/home/sst7260/airflow_projects/project1/env/lib/python3.10/site-packages/airflow/operators/bash.py", line 249, in execute
    raise AirflowException(
airflow.exceptions.AirflowException: Bash command failed. The command returned a non-zero exit code 1.
[2024-09-10T17:01:57.482+0530] {local_task_job_runner.py:266} INFO - Task exited with return code 1
[2024-09-10T17:01:57.604+0530] {taskinstance.py:3900} INFO - 0 downstream tasks scheduled from follow-on schedule check
[2024-09-10T17:01:57.606+0530] {local_task_job_runner.py:245} INFO - ::endgroup::
