[2024-09-10T15:33:13.381+0530] {local_task_job_runner.py:123} INFO - ::group::Pre task execution logs
[2024-09-10T15:33:13.392+0530] {taskinstance.py:2612} INFO - Dependencies all met for dep_context=non-requeueable deps ti=<TaskInstance: beam_etl_dag_with_credentials.run_beam_pipeline manual__2024-09-10T09:58:49.857193+00:00 [queued]>
[2024-09-10T15:33:13.399+0530] {taskinstance.py:2612} INFO - Dependencies all met for dep_context=requeueable deps ti=<TaskInstance: beam_etl_dag_with_credentials.run_beam_pipeline manual__2024-09-10T09:58:49.857193+00:00 [queued]>
[2024-09-10T15:33:13.399+0530] {taskinstance.py:2865} INFO - Starting attempt 2 of 2
[2024-09-10T15:33:13.427+0530] {taskinstance.py:2888} INFO - Executing <Task(PythonOperator): run_beam_pipeline> on 2024-09-10 09:58:49.857193+00:00
[2024-09-10T15:33:13.433+0530] {standard_task_runner.py:72} INFO - Started process 190420 to run task
[2024-09-10T15:33:13.436+0530] {standard_task_runner.py:104} INFO - Running: ['airflow', 'tasks', 'run', 'beam_etl_dag_with_credentials', 'run_beam_pipeline', 'manual__2024-09-10T09:58:49.857193+00:00', '--job-id', '68', '--raw', '--subdir', 'DAGS_FOLDER/beam_etl_dag.py', '--cfg-path', '/tmp/tmpl3fbw1tu']
[2024-09-10T15:33:13.437+0530] {standard_task_runner.py:105} INFO - Job 68: Subtask run_beam_pipeline
[2024-09-10T15:33:13.546+0530] {task_command.py:467} INFO - Running <TaskInstance: beam_etl_dag_with_credentials.run_beam_pipeline manual__2024-09-10T09:58:49.857193+00:00 [running]> on host PG0392KD.springernature.com
[2024-09-10T15:33:13.674+0530] {taskinstance.py:3131} INFO - Exporting env vars: AIRFLOW_CTX_DAG_OWNER='airflow' AIRFLOW_CTX_DAG_ID='beam_etl_dag_with_credentials' AIRFLOW_CTX_TASK_ID='run_beam_pipeline' AIRFLOW_CTX_EXECUTION_DATE='2024-09-10T09:58:49.857193+00:00' AIRFLOW_CTX_TRY_NUMBER='2' AIRFLOW_CTX_DAG_RUN_ID='manual__2024-09-10T09:58:49.857193+00:00'
[2024-09-10T15:33:13.686+0530] {logging_mixin.py:190} INFO - Task instance is in running state
[2024-09-10T15:33:13.688+0530] {logging_mixin.py:190} INFO -  Previous state of the Task instance: queued
[2024-09-10T15:33:13.688+0530] {logging_mixin.py:190} INFO - Current task name:run_beam_pipeline state:running start_date:2024-09-10 10:03:13.393149+00:00
[2024-09-10T15:33:13.688+0530] {logging_mixin.py:190} INFO - Dag name:beam_etl_dag_with_credentials and current dag run status:running
[2024-09-10T15:33:13.689+0530] {taskinstance.py:731} INFO - ::endgroup::
[2024-09-10T15:33:16.841+0530] {_metadata.py:142} WARNING - Compute Engine Metadata server unavailable on attempt 1 of 3. Reason: timed out
[2024-09-10T15:33:20.849+0530] {_metadata.py:142} WARNING - Compute Engine Metadata server unavailable on attempt 2 of 3. Reason: timed out
[2024-09-10T15:33:25.986+0530] {_metadata.py:142} WARNING - Compute Engine Metadata server unavailable on attempt 3 of 3. Reason: timed out
[2024-09-10T15:33:25.986+0530] {_default.py:338} WARNING - Authentication failed using Compute Engine authentication due to unavailable metadata server.
[2024-09-10T15:33:25.992+0530] {retry.py:313} WARNING - Retry with exponential backoff: waiting for 1.3670679446243739 seconds before retrying _get_credentials_with_retrys because we caught exception: google.auth.exceptions.DefaultCredentialsError: Your default credentials were not found. To set up Application Default Credentials, see https://cloud.google.com/docs/authentication/external/set-up-adc for more information.
 Traceback for above exception (most recent call last):
  File "/home/sst7260/airflow_projects/project1/env/lib/python3.10/site-packages/apache_beam/utils/retry.py", line 298, in wrapper
    return fun(*args, **kwargs)
  File "/home/sst7260/airflow_projects/project1/env/lib/python3.10/site-packages/apache_beam/internal/gcp/auth.py", line 175, in _get_credentials_with_retrys
    credentials, _ = google.auth.default(
  File "/home/sst7260/airflow_projects/project1/env/lib/python3.10/site-packages/google/auth/_default.py", line 691, in default
    raise exceptions.DefaultCredentialsError(_CLOUD_SDK_MISSING_CREDENTIALS)

[2024-09-10T15:33:30.368+0530] {_metadata.py:142} WARNING - Compute Engine Metadata server unavailable on attempt 1 of 3. Reason: timed out
[2024-09-10T15:33:34.303+0530] {_metadata.py:142} WARNING - Compute Engine Metadata server unavailable on attempt 2 of 3. Reason: timed out
[2024-09-10T15:33:39.490+0530] {_metadata.py:142} WARNING - Compute Engine Metadata server unavailable on attempt 3 of 3. Reason: timed out
[2024-09-10T15:33:39.490+0530] {_default.py:338} WARNING - Authentication failed using Compute Engine authentication due to unavailable metadata server.
[2024-09-10T15:33:39.490+0530] {retry.py:313} WARNING - Retry with exponential backoff: waiting for 3.410515678977253 seconds before retrying _get_credentials_with_retrys because we caught exception: google.auth.exceptions.DefaultCredentialsError: Your default credentials were not found. To set up Application Default Credentials, see https://cloud.google.com/docs/authentication/external/set-up-adc for more information.
 Traceback for above exception (most recent call last):
  File "/home/sst7260/airflow_projects/project1/env/lib/python3.10/site-packages/apache_beam/utils/retry.py", line 298, in wrapper
    return fun(*args, **kwargs)
  File "/home/sst7260/airflow_projects/project1/env/lib/python3.10/site-packages/apache_beam/internal/gcp/auth.py", line 175, in _get_credentials_with_retrys
    credentials, _ = google.auth.default(
  File "/home/sst7260/airflow_projects/project1/env/lib/python3.10/site-packages/google/auth/_default.py", line 691, in default
    raise exceptions.DefaultCredentialsError(_CLOUD_SDK_MISSING_CREDENTIALS)

[2024-09-10T15:33:45.909+0530] {_metadata.py:142} WARNING - Compute Engine Metadata server unavailable on attempt 1 of 3. Reason: timed out
[2024-09-10T15:33:49.884+0530] {_metadata.py:142} WARNING - Compute Engine Metadata server unavailable on attempt 2 of 3. Reason: timed out
[2024-09-10T15:33:54.871+0530] {_metadata.py:142} WARNING - Compute Engine Metadata server unavailable on attempt 3 of 3. Reason: timed out
[2024-09-10T15:33:54.872+0530] {_default.py:338} WARNING - Authentication failed using Compute Engine authentication due to unavailable metadata server.
[2024-09-10T15:33:54.872+0530] {retry.py:313} WARNING - Retry with exponential backoff: waiting for 6.241274925849426 seconds before retrying _get_credentials_with_retrys because we caught exception: google.auth.exceptions.DefaultCredentialsError: Your default credentials were not found. To set up Application Default Credentials, see https://cloud.google.com/docs/authentication/external/set-up-adc for more information.
 Traceback for above exception (most recent call last):
  File "/home/sst7260/airflow_projects/project1/env/lib/python3.10/site-packages/apache_beam/utils/retry.py", line 298, in wrapper
    return fun(*args, **kwargs)
  File "/home/sst7260/airflow_projects/project1/env/lib/python3.10/site-packages/apache_beam/internal/gcp/auth.py", line 175, in _get_credentials_with_retrys
    credentials, _ = google.auth.default(
  File "/home/sst7260/airflow_projects/project1/env/lib/python3.10/site-packages/google/auth/_default.py", line 691, in default
    raise exceptions.DefaultCredentialsError(_CLOUD_SDK_MISSING_CREDENTIALS)

[2024-09-10T15:34:04.125+0530] {_metadata.py:142} WARNING - Compute Engine Metadata server unavailable on attempt 1 of 3. Reason: timed out
[2024-09-10T15:34:08.177+0530] {_metadata.py:142} WARNING - Compute Engine Metadata server unavailable on attempt 2 of 3. Reason: timed out
[2024-09-10T15:34:13.295+0530] {_metadata.py:142} WARNING - Compute Engine Metadata server unavailable on attempt 3 of 3. Reason: timed out
[2024-09-10T15:34:13.295+0530] {_default.py:338} WARNING - Authentication failed using Compute Engine authentication due to unavailable metadata server.
[2024-09-10T15:34:13.296+0530] {retry.py:313} WARNING - Retry with exponential backoff: waiting for 13.632526021056014 seconds before retrying _get_credentials_with_retrys because we caught exception: google.auth.exceptions.DefaultCredentialsError: Your default credentials were not found. To set up Application Default Credentials, see https://cloud.google.com/docs/authentication/external/set-up-adc for more information.
 Traceback for above exception (most recent call last):
  File "/home/sst7260/airflow_projects/project1/env/lib/python3.10/site-packages/apache_beam/utils/retry.py", line 298, in wrapper
    return fun(*args, **kwargs)
  File "/home/sst7260/airflow_projects/project1/env/lib/python3.10/site-packages/apache_beam/internal/gcp/auth.py", line 175, in _get_credentials_with_retrys
    credentials, _ = google.auth.default(
  File "/home/sst7260/airflow_projects/project1/env/lib/python3.10/site-packages/google/auth/_default.py", line 691, in default
    raise exceptions.DefaultCredentialsError(_CLOUD_SDK_MISSING_CREDENTIALS)

[2024-09-10T15:34:29.936+0530] {_metadata.py:142} WARNING - Compute Engine Metadata server unavailable on attempt 1 of 3. Reason: timed out
[2024-09-10T15:34:33.984+0530] {_metadata.py:142} WARNING - Compute Engine Metadata server unavailable on attempt 2 of 3. Reason: timed out
[2024-09-10T15:34:38.797+0530] {_metadata.py:142} WARNING - Compute Engine Metadata server unavailable on attempt 3 of 3. Reason: timed out
[2024-09-10T15:34:38.798+0530] {_default.py:338} WARNING - Authentication failed using Compute Engine authentication due to unavailable metadata server.
[2024-09-10T15:34:38.799+0530] {auth.py:165} WARNING - Unable to find default credentials to use: Your default credentials were not found. To set up Application Default Credentials, see https://cloud.google.com/docs/authentication/external/set-up-adc for more information.
Connecting anonymously. This is expected if no credentials are needed to access GCP resources.
[2024-09-10T15:34:38.810+0530] {pipeline_options.py:372} WARNING - Discarding unparseable args: ['tasks', 'run', 'beam_etl_dag_with_credentials', 'run_beam_pipeline', 'manual__2024-09-10T09:58:49.857193+00:00', '--local', '--subdir', 'DAGS_FOLDER/beam_etl_dag.py']
[2024-09-10T15:34:38.814+0530] {pipeline_options.py:372} WARNING - Discarding unparseable args: ['tasks', 'run', 'beam_etl_dag_with_credentials', 'run_beam_pipeline', 'manual__2024-09-10T09:58:49.857193+00:00', '--local', '--subdir', 'DAGS_FOLDER/beam_etl_dag.py']
[2024-09-10T15:34:39.473+0530] {requests.py:558} INFO - Refreshing credentials due to a 401 response. Attempt 1/2.
[2024-09-10T15:34:39.473+0530] {gcsio.py:552} WARNING - Unexpected error occurred when checking soft delete policy for gs://sn_insights_test/temp
[2024-09-10T15:34:39.478+0530] {pipeline_options.py:372} WARNING - Discarding unparseable args: ['tasks', 'run', 'beam_etl_dag_with_credentials', 'run_beam_pipeline', 'manual__2024-09-10T09:58:49.857193+00:00', '--local', '--subdir', 'DAGS_FOLDER/beam_etl_dag.py']
[2024-09-10T15:34:39.485+0530] {pipeline_options.py:372} WARNING - Discarding unparseable args: ['tasks', 'run', 'beam_etl_dag_with_credentials', 'run_beam_pipeline', 'manual__2024-09-10T09:58:49.857193+00:00', '--local', '--subdir', 'DAGS_FOLDER/beam_etl_dag.py']
[2024-09-10T15:34:40.088+0530] {requests.py:558} INFO - Refreshing credentials due to a 401 response. Attempt 1/2.
[2024-09-10T15:34:40.088+0530] {gcsio.py:552} WARNING - Unexpected error occurred when checking soft delete policy for gs://sn_insights_test/staging
[2024-09-10T15:34:40.757+0530] {requests.py:558} INFO - Refreshing credentials due to a 401 response. Attempt 1/2.
[2024-09-10T15:34:40.766+0530] {retry.py:313} WARNING - Retry with exponential backoff: waiting for 4.4839764151239345 seconds before retrying _gcs_object because we caught exception: google.auth.exceptions.InvalidOperation: Anonymous credentials cannot be refreshed.
 Traceback for above exception (most recent call last):
  File "/home/sst7260/airflow_projects/project1/env/lib/python3.10/site-packages/apache_beam/utils/retry.py", line 298, in wrapper
    return fun(*args, **kwargs)
  File "/home/sst7260/airflow_projects/project1/env/lib/python3.10/site-packages/apache_beam/io/gcp/gcsio.py", line 462, in _gcs_object
    blob = bucket.get_blob(blob_name)
  File "/usr/lib/python3.10/contextlib.py", line 79, in inner
    return func(*args, **kwds)
  File "/home/sst7260/airflow_projects/project1/env/lib/python3.10/site-packages/google/cloud/storage/bucket.py", line 1283, in get_blob
    blob.reload(
  File "/home/sst7260/airflow_projects/project1/env/lib/python3.10/site-packages/google/cloud/storage/_helpers.py", line 300, in reload
    api_response = client._get_resource(
  File "/home/sst7260/airflow_projects/project1/env/lib/python3.10/site-packages/google/cloud/storage/client.py", line 464, in _get_resource
    return self._connection.api_request(
  File "/home/sst7260/airflow_projects/project1/env/lib/python3.10/site-packages/google/cloud/storage/_http.py", line 90, in api_request
    return call()
  File "/home/sst7260/airflow_projects/project1/env/lib/python3.10/site-packages/google/api_core/retry/retry_unary.py", line 293, in retry_wrapped_func
    return retry_target(
  File "/home/sst7260/airflow_projects/project1/env/lib/python3.10/site-packages/google/api_core/retry/retry_unary.py", line 153, in retry_target
    _retry_error_helper(
  File "/home/sst7260/airflow_projects/project1/env/lib/python3.10/site-packages/google/api_core/retry/retry_base.py", line 212, in _retry_error_helper
    raise final_exc from source_exc
  File "/home/sst7260/airflow_projects/project1/env/lib/python3.10/site-packages/google/api_core/retry/retry_unary.py", line 144, in retry_target
    result = target()
  File "/home/sst7260/airflow_projects/project1/env/lib/python3.10/site-packages/google/cloud/_http/__init__.py", line 482, in api_request
    response = self._make_request(
  File "/home/sst7260/airflow_projects/project1/env/lib/python3.10/site-packages/google/cloud/_http/__init__.py", line 341, in _make_request
    return self._do_request(
  File "/home/sst7260/airflow_projects/project1/env/lib/python3.10/site-packages/google/cloud/_http/__init__.py", line 379, in _do_request
    return self.http.request(
  File "/home/sst7260/airflow_projects/project1/env/lib/python3.10/site-packages/google/auth/transport/requests.py", line 574, in request
    self.credentials.refresh(auth_request)
  File "/home/sst7260/airflow_projects/project1/env/lib/python3.10/site-packages/google/auth/credentials.py", line 311, in refresh
    raise exceptions.InvalidOperation("Anonymous credentials cannot be refreshed.")

[2024-09-10T15:34:45.651+0530] {requests.py:558} INFO - Refreshing credentials due to a 401 response. Attempt 1/2.
[2024-09-10T15:34:45.652+0530] {retry.py:313} WARNING - Retry with exponential backoff: waiting for 5.6772857653994215 seconds before retrying _gcs_object because we caught exception: google.auth.exceptions.InvalidOperation: Anonymous credentials cannot be refreshed.
 Traceback for above exception (most recent call last):
  File "/home/sst7260/airflow_projects/project1/env/lib/python3.10/site-packages/apache_beam/utils/retry.py", line 298, in wrapper
    return fun(*args, **kwargs)
  File "/home/sst7260/airflow_projects/project1/env/lib/python3.10/site-packages/apache_beam/io/gcp/gcsio.py", line 462, in _gcs_object
    blob = bucket.get_blob(blob_name)
  File "/usr/lib/python3.10/contextlib.py", line 79, in inner
    return func(*args, **kwds)
  File "/home/sst7260/airflow_projects/project1/env/lib/python3.10/site-packages/google/cloud/storage/bucket.py", line 1283, in get_blob
    blob.reload(
  File "/home/sst7260/airflow_projects/project1/env/lib/python3.10/site-packages/google/cloud/storage/_helpers.py", line 300, in reload
    api_response = client._get_resource(
  File "/home/sst7260/airflow_projects/project1/env/lib/python3.10/site-packages/google/cloud/storage/client.py", line 464, in _get_resource
    return self._connection.api_request(
  File "/home/sst7260/airflow_projects/project1/env/lib/python3.10/site-packages/google/cloud/storage/_http.py", line 90, in api_request
    return call()
  File "/home/sst7260/airflow_projects/project1/env/lib/python3.10/site-packages/google/api_core/retry/retry_unary.py", line 293, in retry_wrapped_func
    return retry_target(
  File "/home/sst7260/airflow_projects/project1/env/lib/python3.10/site-packages/google/api_core/retry/retry_unary.py", line 153, in retry_target
    _retry_error_helper(
  File "/home/sst7260/airflow_projects/project1/env/lib/python3.10/site-packages/google/api_core/retry/retry_base.py", line 212, in _retry_error_helper
    raise final_exc from source_exc
  File "/home/sst7260/airflow_projects/project1/env/lib/python3.10/site-packages/google/api_core/retry/retry_unary.py", line 144, in retry_target
    result = target()
  File "/home/sst7260/airflow_projects/project1/env/lib/python3.10/site-packages/google/cloud/_http/__init__.py", line 482, in api_request
    response = self._make_request(
  File "/home/sst7260/airflow_projects/project1/env/lib/python3.10/site-packages/google/cloud/_http/__init__.py", line 341, in _make_request
    return self._do_request(
  File "/home/sst7260/airflow_projects/project1/env/lib/python3.10/site-packages/google/cloud/_http/__init__.py", line 379, in _do_request
    return self.http.request(
  File "/home/sst7260/airflow_projects/project1/env/lib/python3.10/site-packages/google/auth/transport/requests.py", line 574, in request
    self.credentials.refresh(auth_request)
  File "/home/sst7260/airflow_projects/project1/env/lib/python3.10/site-packages/google/auth/credentials.py", line 311, in refresh
    raise exceptions.InvalidOperation("Anonymous credentials cannot be refreshed.")

[2024-09-10T15:34:51.721+0530] {requests.py:558} INFO - Refreshing credentials due to a 401 response. Attempt 1/2.
[2024-09-10T15:34:51.722+0530] {retry.py:313} WARNING - Retry with exponential backoff: waiting for 18.85760872295063 seconds before retrying _gcs_object because we caught exception: google.auth.exceptions.InvalidOperation: Anonymous credentials cannot be refreshed.
 Traceback for above exception (most recent call last):
  File "/home/sst7260/airflow_projects/project1/env/lib/python3.10/site-packages/apache_beam/utils/retry.py", line 298, in wrapper
    return fun(*args, **kwargs)
  File "/home/sst7260/airflow_projects/project1/env/lib/python3.10/site-packages/apache_beam/io/gcp/gcsio.py", line 462, in _gcs_object
    blob = bucket.get_blob(blob_name)
  File "/usr/lib/python3.10/contextlib.py", line 79, in inner
    return func(*args, **kwds)
  File "/home/sst7260/airflow_projects/project1/env/lib/python3.10/site-packages/google/cloud/storage/bucket.py", line 1283, in get_blob
    blob.reload(
  File "/home/sst7260/airflow_projects/project1/env/lib/python3.10/site-packages/google/cloud/storage/_helpers.py", line 300, in reload
    api_response = client._get_resource(
  File "/home/sst7260/airflow_projects/project1/env/lib/python3.10/site-packages/google/cloud/storage/client.py", line 464, in _get_resource
    return self._connection.api_request(
  File "/home/sst7260/airflow_projects/project1/env/lib/python3.10/site-packages/google/cloud/storage/_http.py", line 90, in api_request
    return call()
  File "/home/sst7260/airflow_projects/project1/env/lib/python3.10/site-packages/google/api_core/retry/retry_unary.py", line 293, in retry_wrapped_func
    return retry_target(
  File "/home/sst7260/airflow_projects/project1/env/lib/python3.10/site-packages/google/api_core/retry/retry_unary.py", line 153, in retry_target
    _retry_error_helper(
  File "/home/sst7260/airflow_projects/project1/env/lib/python3.10/site-packages/google/api_core/retry/retry_base.py", line 212, in _retry_error_helper
    raise final_exc from source_exc
  File "/home/sst7260/airflow_projects/project1/env/lib/python3.10/site-packages/google/api_core/retry/retry_unary.py", line 144, in retry_target
    result = target()
  File "/home/sst7260/airflow_projects/project1/env/lib/python3.10/site-packages/google/cloud/_http/__init__.py", line 482, in api_request
    response = self._make_request(
  File "/home/sst7260/airflow_projects/project1/env/lib/python3.10/site-packages/google/cloud/_http/__init__.py", line 341, in _make_request
    return self._do_request(
  File "/home/sst7260/airflow_projects/project1/env/lib/python3.10/site-packages/google/cloud/_http/__init__.py", line 379, in _do_request
    return self.http.request(
  File "/home/sst7260/airflow_projects/project1/env/lib/python3.10/site-packages/google/auth/transport/requests.py", line 574, in request
    self.credentials.refresh(auth_request)
  File "/home/sst7260/airflow_projects/project1/env/lib/python3.10/site-packages/google/auth/credentials.py", line 311, in refresh
    raise exceptions.InvalidOperation("Anonymous credentials cannot be refreshed.")

[2024-09-10T15:35:10.984+0530] {requests.py:558} INFO - Refreshing credentials due to a 401 response. Attempt 1/2.
[2024-09-10T15:35:10.984+0530] {retry.py:313} WARNING - Retry with exponential backoff: waiting for 24.754409936497915 seconds before retrying _gcs_object because we caught exception: google.auth.exceptions.InvalidOperation: Anonymous credentials cannot be refreshed.
 Traceback for above exception (most recent call last):
  File "/home/sst7260/airflow_projects/project1/env/lib/python3.10/site-packages/apache_beam/utils/retry.py", line 298, in wrapper
    return fun(*args, **kwargs)
  File "/home/sst7260/airflow_projects/project1/env/lib/python3.10/site-packages/apache_beam/io/gcp/gcsio.py", line 462, in _gcs_object
    blob = bucket.get_blob(blob_name)
  File "/usr/lib/python3.10/contextlib.py", line 79, in inner
    return func(*args, **kwds)
  File "/home/sst7260/airflow_projects/project1/env/lib/python3.10/site-packages/google/cloud/storage/bucket.py", line 1283, in get_blob
    blob.reload(
  File "/home/sst7260/airflow_projects/project1/env/lib/python3.10/site-packages/google/cloud/storage/_helpers.py", line 300, in reload
    api_response = client._get_resource(
  File "/home/sst7260/airflow_projects/project1/env/lib/python3.10/site-packages/google/cloud/storage/client.py", line 464, in _get_resource
    return self._connection.api_request(
  File "/home/sst7260/airflow_projects/project1/env/lib/python3.10/site-packages/google/cloud/storage/_http.py", line 90, in api_request
    return call()
  File "/home/sst7260/airflow_projects/project1/env/lib/python3.10/site-packages/google/api_core/retry/retry_unary.py", line 293, in retry_wrapped_func
    return retry_target(
  File "/home/sst7260/airflow_projects/project1/env/lib/python3.10/site-packages/google/api_core/retry/retry_unary.py", line 153, in retry_target
    _retry_error_helper(
  File "/home/sst7260/airflow_projects/project1/env/lib/python3.10/site-packages/google/api_core/retry/retry_base.py", line 212, in _retry_error_helper
    raise final_exc from source_exc
  File "/home/sst7260/airflow_projects/project1/env/lib/python3.10/site-packages/google/api_core/retry/retry_unary.py", line 144, in retry_target
    result = target()
  File "/home/sst7260/airflow_projects/project1/env/lib/python3.10/site-packages/google/cloud/_http/__init__.py", line 482, in api_request
    response = self._make_request(
  File "/home/sst7260/airflow_projects/project1/env/lib/python3.10/site-packages/google/cloud/_http/__init__.py", line 341, in _make_request
    return self._do_request(
  File "/home/sst7260/airflow_projects/project1/env/lib/python3.10/site-packages/google/cloud/_http/__init__.py", line 379, in _do_request
    return self.http.request(
  File "/home/sst7260/airflow_projects/project1/env/lib/python3.10/site-packages/google/auth/transport/requests.py", line 574, in request
    self.credentials.refresh(auth_request)
  File "/home/sst7260/airflow_projects/project1/env/lib/python3.10/site-packages/google/auth/credentials.py", line 311, in refresh
    raise exceptions.InvalidOperation("Anonymous credentials cannot be refreshed.")

[2024-09-10T15:35:36.152+0530] {requests.py:558} INFO - Refreshing credentials due to a 401 response. Attempt 1/2.
[2024-09-10T15:35:36.154+0530] {retry.py:313} WARNING - Retry with exponential backoff: waiting for 76.24857238581683 seconds before retrying _gcs_object because we caught exception: google.auth.exceptions.InvalidOperation: Anonymous credentials cannot be refreshed.
 Traceback for above exception (most recent call last):
  File "/home/sst7260/airflow_projects/project1/env/lib/python3.10/site-packages/apache_beam/utils/retry.py", line 298, in wrapper
    return fun(*args, **kwargs)
  File "/home/sst7260/airflow_projects/project1/env/lib/python3.10/site-packages/apache_beam/io/gcp/gcsio.py", line 462, in _gcs_object
    blob = bucket.get_blob(blob_name)
  File "/usr/lib/python3.10/contextlib.py", line 79, in inner
    return func(*args, **kwds)
  File "/home/sst7260/airflow_projects/project1/env/lib/python3.10/site-packages/google/cloud/storage/bucket.py", line 1283, in get_blob
    blob.reload(
  File "/home/sst7260/airflow_projects/project1/env/lib/python3.10/site-packages/google/cloud/storage/_helpers.py", line 300, in reload
    api_response = client._get_resource(
  File "/home/sst7260/airflow_projects/project1/env/lib/python3.10/site-packages/google/cloud/storage/client.py", line 464, in _get_resource
    return self._connection.api_request(
  File "/home/sst7260/airflow_projects/project1/env/lib/python3.10/site-packages/google/cloud/storage/_http.py", line 90, in api_request
    return call()
  File "/home/sst7260/airflow_projects/project1/env/lib/python3.10/site-packages/google/api_core/retry/retry_unary.py", line 293, in retry_wrapped_func
    return retry_target(
  File "/home/sst7260/airflow_projects/project1/env/lib/python3.10/site-packages/google/api_core/retry/retry_unary.py", line 153, in retry_target
    _retry_error_helper(
  File "/home/sst7260/airflow_projects/project1/env/lib/python3.10/site-packages/google/api_core/retry/retry_base.py", line 212, in _retry_error_helper
    raise final_exc from source_exc
  File "/home/sst7260/airflow_projects/project1/env/lib/python3.10/site-packages/google/api_core/retry/retry_unary.py", line 144, in retry_target
    result = target()
  File "/home/sst7260/airflow_projects/project1/env/lib/python3.10/site-packages/google/cloud/_http/__init__.py", line 482, in api_request
    response = self._make_request(
  File "/home/sst7260/airflow_projects/project1/env/lib/python3.10/site-packages/google/cloud/_http/__init__.py", line 341, in _make_request
    return self._do_request(
  File "/home/sst7260/airflow_projects/project1/env/lib/python3.10/site-packages/google/cloud/_http/__init__.py", line 379, in _do_request
    return self.http.request(
  File "/home/sst7260/airflow_projects/project1/env/lib/python3.10/site-packages/google/auth/transport/requests.py", line 574, in request
    self.credentials.refresh(auth_request)
  File "/home/sst7260/airflow_projects/project1/env/lib/python3.10/site-packages/google/auth/credentials.py", line 311, in refresh
    raise exceptions.InvalidOperation("Anonymous credentials cannot be refreshed.")

[2024-09-10T15:36:52.869+0530] {requests.py:558} INFO - Refreshing credentials due to a 401 response. Attempt 1/2.
[2024-09-10T15:36:52.872+0530] {retry.py:313} WARNING - Retry with exponential backoff: waiting for 85.48988972973086 seconds before retrying _gcs_object because we caught exception: google.auth.exceptions.InvalidOperation: Anonymous credentials cannot be refreshed.
 Traceback for above exception (most recent call last):
  File "/home/sst7260/airflow_projects/project1/env/lib/python3.10/site-packages/apache_beam/utils/retry.py", line 298, in wrapper
    return fun(*args, **kwargs)
  File "/home/sst7260/airflow_projects/project1/env/lib/python3.10/site-packages/apache_beam/io/gcp/gcsio.py", line 462, in _gcs_object
    blob = bucket.get_blob(blob_name)
  File "/usr/lib/python3.10/contextlib.py", line 79, in inner
    return func(*args, **kwds)
  File "/home/sst7260/airflow_projects/project1/env/lib/python3.10/site-packages/google/cloud/storage/bucket.py", line 1283, in get_blob
    blob.reload(
  File "/home/sst7260/airflow_projects/project1/env/lib/python3.10/site-packages/google/cloud/storage/_helpers.py", line 300, in reload
    api_response = client._get_resource(
  File "/home/sst7260/airflow_projects/project1/env/lib/python3.10/site-packages/google/cloud/storage/client.py", line 464, in _get_resource
    return self._connection.api_request(
  File "/home/sst7260/airflow_projects/project1/env/lib/python3.10/site-packages/google/cloud/storage/_http.py", line 90, in api_request
    return call()
  File "/home/sst7260/airflow_projects/project1/env/lib/python3.10/site-packages/google/api_core/retry/retry_unary.py", line 293, in retry_wrapped_func
    return retry_target(
  File "/home/sst7260/airflow_projects/project1/env/lib/python3.10/site-packages/google/api_core/retry/retry_unary.py", line 153, in retry_target
    _retry_error_helper(
  File "/home/sst7260/airflow_projects/project1/env/lib/python3.10/site-packages/google/api_core/retry/retry_base.py", line 212, in _retry_error_helper
    raise final_exc from source_exc
  File "/home/sst7260/airflow_projects/project1/env/lib/python3.10/site-packages/google/api_core/retry/retry_unary.py", line 144, in retry_target
    result = target()
  File "/home/sst7260/airflow_projects/project1/env/lib/python3.10/site-packages/google/cloud/_http/__init__.py", line 482, in api_request
    response = self._make_request(
  File "/home/sst7260/airflow_projects/project1/env/lib/python3.10/site-packages/google/cloud/_http/__init__.py", line 341, in _make_request
    return self._do_request(
  File "/home/sst7260/airflow_projects/project1/env/lib/python3.10/site-packages/google/cloud/_http/__init__.py", line 379, in _do_request
    return self.http.request(
  File "/home/sst7260/airflow_projects/project1/env/lib/python3.10/site-packages/google/auth/transport/requests.py", line 574, in request
    self.credentials.refresh(auth_request)
  File "/home/sst7260/airflow_projects/project1/env/lib/python3.10/site-packages/google/auth/credentials.py", line 311, in refresh
    raise exceptions.InvalidOperation("Anonymous credentials cannot be refreshed.")

[2024-09-10T15:38:18.837+0530] {requests.py:558} INFO - Refreshing credentials due to a 401 response. Attempt 1/2.
[2024-09-10T15:38:18.837+0530] {retry.py:313} WARNING - Retry with exponential backoff: waiting for 304.5962546559934 seconds before retrying _gcs_object because we caught exception: google.auth.exceptions.InvalidOperation: Anonymous credentials cannot be refreshed.
 Traceback for above exception (most recent call last):
  File "/home/sst7260/airflow_projects/project1/env/lib/python3.10/site-packages/apache_beam/utils/retry.py", line 298, in wrapper
    return fun(*args, **kwargs)
  File "/home/sst7260/airflow_projects/project1/env/lib/python3.10/site-packages/apache_beam/io/gcp/gcsio.py", line 462, in _gcs_object
    blob = bucket.get_blob(blob_name)
  File "/usr/lib/python3.10/contextlib.py", line 79, in inner
    return func(*args, **kwds)
  File "/home/sst7260/airflow_projects/project1/env/lib/python3.10/site-packages/google/cloud/storage/bucket.py", line 1283, in get_blob
    blob.reload(
  File "/home/sst7260/airflow_projects/project1/env/lib/python3.10/site-packages/google/cloud/storage/_helpers.py", line 300, in reload
    api_response = client._get_resource(
  File "/home/sst7260/airflow_projects/project1/env/lib/python3.10/site-packages/google/cloud/storage/client.py", line 464, in _get_resource
    return self._connection.api_request(
  File "/home/sst7260/airflow_projects/project1/env/lib/python3.10/site-packages/google/cloud/storage/_http.py", line 90, in api_request
    return call()
  File "/home/sst7260/airflow_projects/project1/env/lib/python3.10/site-packages/google/api_core/retry/retry_unary.py", line 293, in retry_wrapped_func
    return retry_target(
  File "/home/sst7260/airflow_projects/project1/env/lib/python3.10/site-packages/google/api_core/retry/retry_unary.py", line 153, in retry_target
    _retry_error_helper(
  File "/home/sst7260/airflow_projects/project1/env/lib/python3.10/site-packages/google/api_core/retry/retry_base.py", line 212, in _retry_error_helper
    raise final_exc from source_exc
  File "/home/sst7260/airflow_projects/project1/env/lib/python3.10/site-packages/google/api_core/retry/retry_unary.py", line 144, in retry_target
    result = target()
  File "/home/sst7260/airflow_projects/project1/env/lib/python3.10/site-packages/google/cloud/_http/__init__.py", line 482, in api_request
    response = self._make_request(
  File "/home/sst7260/airflow_projects/project1/env/lib/python3.10/site-packages/google/cloud/_http/__init__.py", line 341, in _make_request
    return self._do_request(
  File "/home/sst7260/airflow_projects/project1/env/lib/python3.10/site-packages/google/cloud/_http/__init__.py", line 379, in _do_request
    return self.http.request(
  File "/home/sst7260/airflow_projects/project1/env/lib/python3.10/site-packages/google/auth/transport/requests.py", line 574, in request
    self.credentials.refresh(auth_request)
  File "/home/sst7260/airflow_projects/project1/env/lib/python3.10/site-packages/google/auth/credentials.py", line 311, in refresh
    raise exceptions.InvalidOperation("Anonymous credentials cannot be refreshed.")

[2024-09-10T15:39:10.648+0530] {local_task_job_runner.py:346} WARNING - State of this instance has been externally set to failed. Terminating instance.
[2024-09-10T15:39:10.657+0530] {local_task_job_runner.py:245} INFO - ::endgroup::
[2024-09-10T15:39:10.661+0530] {process_utils.py:132} INFO - Sending Signals.SIGTERM to group 190420. PIDs of all processes in the group: [190420]
[2024-09-10T15:39:10.662+0530] {process_utils.py:87} INFO - Sending the signal Signals.SIGTERM to group 190420
[2024-09-10T15:39:10.665+0530] {taskinstance.py:3092} ERROR - Received SIGTERM. Terminating subprocesses.
[2024-09-10T15:39:10.866+0530] {taskinstance.py:340} INFO - ::group::Post task execution logs
[2024-09-10T15:39:10.891+0530] {process_utils.py:80} INFO - Process psutil.Process(pid=190420, status='terminated', exitcode=0, started='15:33:12') (190420) terminated with exit code 0
