[2024-09-10T15:50:12.370+0530] {local_task_job_runner.py:123} INFO - ::group::Pre task execution logs
[2024-09-10T15:50:12.380+0530] {taskinstance.py:2612} INFO - Dependencies all met for dep_context=non-requeueable deps ti=<TaskInstance: beam_etl_dag_with_credentials.run_beam_pipeline manual__2024-09-10T10:04:53.865121+00:00 [queued]>
[2024-09-10T15:50:12.386+0530] {taskinstance.py:2612} INFO - Dependencies all met for dep_context=requeueable deps ti=<TaskInstance: beam_etl_dag_with_credentials.run_beam_pipeline manual__2024-09-10T10:04:53.865121+00:00 [queued]>
[2024-09-10T15:50:12.386+0530] {taskinstance.py:2865} INFO - Starting attempt 2 of 2
[2024-09-10T15:50:12.412+0530] {taskinstance.py:2888} INFO - Executing <Task(PythonOperator): run_beam_pipeline> on 2024-09-10 10:04:53.865121+00:00
[2024-09-10T15:50:12.421+0530] {standard_task_runner.py:72} INFO - Started process 194150 to run task
[2024-09-10T15:50:12.515+0530] {standard_task_runner.py:104} INFO - Running: ['airflow', 'tasks', 'run', 'beam_etl_dag_with_credentials', 'run_beam_pipeline', 'manual__2024-09-10T10:04:53.865121+00:00', '--job-id', '73', '--raw', '--subdir', 'DAGS_FOLDER/beam_etl_dag.py', '--cfg-path', '/tmp/tmpof8qi6h2']
[2024-09-10T15:50:12.516+0530] {standard_task_runner.py:105} INFO - Job 73: Subtask run_beam_pipeline
[2024-09-10T15:50:13.012+0530] {task_command.py:467} INFO - Running <TaskInstance: beam_etl_dag_with_credentials.run_beam_pipeline manual__2024-09-10T10:04:53.865121+00:00 [running]> on host PG0392KD.springernature.com
[2024-09-10T15:50:13.126+0530] {taskinstance.py:3131} INFO - Exporting env vars: AIRFLOW_CTX_DAG_OWNER='airflow' AIRFLOW_CTX_DAG_ID='beam_etl_dag_with_credentials' AIRFLOW_CTX_TASK_ID='run_beam_pipeline' AIRFLOW_CTX_EXECUTION_DATE='2024-09-10T10:04:53.865121+00:00' AIRFLOW_CTX_TRY_NUMBER='2' AIRFLOW_CTX_DAG_RUN_ID='manual__2024-09-10T10:04:53.865121+00:00'
[2024-09-10T15:50:13.131+0530] {logging_mixin.py:190} INFO - Task instance is in running state
[2024-09-10T15:50:13.131+0530] {logging_mixin.py:190} INFO -  Previous state of the Task instance: queued
[2024-09-10T15:50:13.131+0530] {logging_mixin.py:190} INFO - Current task name:run_beam_pipeline state:running start_date:2024-09-10 10:20:12.381135+00:00
[2024-09-10T15:50:13.131+0530] {logging_mixin.py:190} INFO - Dag name:beam_etl_dag_with_credentials and current dag run status:running
[2024-09-10T15:50:13.132+0530] {taskinstance.py:731} INFO - ::endgroup::
[2024-09-10T15:50:13.450+0530] {pipeline.py:197} INFO - Missing pipeline option (runner). Executing pipeline using the default runner: DirectRunner.
[2024-09-10T15:50:16.474+0530] {_metadata.py:142} WARNING - Compute Engine Metadata server unavailable on attempt 1 of 3. Reason: timed out
[2024-09-10T15:50:20.501+0530] {_metadata.py:142} WARNING - Compute Engine Metadata server unavailable on attempt 2 of 3. Reason: timed out
[2024-09-10T15:50:25.457+0530] {_metadata.py:142} WARNING - Compute Engine Metadata server unavailable on attempt 3 of 3. Reason: timed out
[2024-09-10T15:50:25.458+0530] {_default.py:338} WARNING - Authentication failed using Compute Engine authentication due to unavailable metadata server.
[2024-09-10T15:50:25.459+0530] {retry.py:313} WARNING - Retry with exponential backoff: waiting for 1.4258679134028096 seconds before retrying _get_credentials_with_retrys because we caught exception: google.auth.exceptions.DefaultCredentialsError: Your default credentials were not found. To set up Application Default Credentials, see https://cloud.google.com/docs/authentication/external/set-up-adc for more information.
 Traceback for above exception (most recent call last):
  File "/home/sst7260/airflow_projects/project1/env/lib/python3.10/site-packages/apache_beam/utils/retry.py", line 298, in wrapper
    return fun(*args, **kwargs)
  File "/home/sst7260/airflow_projects/project1/env/lib/python3.10/site-packages/apache_beam/internal/gcp/auth.py", line 175, in _get_credentials_with_retrys
    credentials, _ = google.auth.default(
  File "/home/sst7260/airflow_projects/project1/env/lib/python3.10/site-packages/google/auth/_default.py", line 691, in default
    raise exceptions.DefaultCredentialsError(_CLOUD_SDK_MISSING_CREDENTIALS)

[2024-09-10T15:50:29.891+0530] {_metadata.py:142} WARNING - Compute Engine Metadata server unavailable on attempt 1 of 3. Reason: timed out
[2024-09-10T15:50:33.924+0530] {_metadata.py:142} WARNING - Compute Engine Metadata server unavailable on attempt 2 of 3. Reason: timed out
[2024-09-10T15:50:38.867+0530] {_metadata.py:142} WARNING - Compute Engine Metadata server unavailable on attempt 3 of 3. Reason: timed out
[2024-09-10T15:50:38.867+0530] {_default.py:338} WARNING - Authentication failed using Compute Engine authentication due to unavailable metadata server.
[2024-09-10T15:50:38.867+0530] {retry.py:313} WARNING - Retry with exponential backoff: waiting for 3.1857811562687717 seconds before retrying _get_credentials_with_retrys because we caught exception: google.auth.exceptions.DefaultCredentialsError: Your default credentials were not found. To set up Application Default Credentials, see https://cloud.google.com/docs/authentication/external/set-up-adc for more information.
 Traceback for above exception (most recent call last):
  File "/home/sst7260/airflow_projects/project1/env/lib/python3.10/site-packages/apache_beam/utils/retry.py", line 298, in wrapper
    return fun(*args, **kwargs)
  File "/home/sst7260/airflow_projects/project1/env/lib/python3.10/site-packages/apache_beam/internal/gcp/auth.py", line 175, in _get_credentials_with_retrys
    credentials, _ = google.auth.default(
  File "/home/sst7260/airflow_projects/project1/env/lib/python3.10/site-packages/google/auth/_default.py", line 691, in default
    raise exceptions.DefaultCredentialsError(_CLOUD_SDK_MISSING_CREDENTIALS)

[2024-09-10T15:50:45.061+0530] {_metadata.py:142} WARNING - Compute Engine Metadata server unavailable on attempt 1 of 3. Reason: timed out
[2024-09-10T15:50:49.084+0530] {_metadata.py:142} WARNING - Compute Engine Metadata server unavailable on attempt 2 of 3. Reason: timed out
[2024-09-10T15:50:53.950+0530] {_metadata.py:142} WARNING - Compute Engine Metadata server unavailable on attempt 3 of 3. Reason: timed out
[2024-09-10T15:50:53.950+0530] {_default.py:338} WARNING - Authentication failed using Compute Engine authentication due to unavailable metadata server.
[2024-09-10T15:50:53.951+0530] {retry.py:313} WARNING - Retry with exponential backoff: waiting for 5.046735697845058 seconds before retrying _get_credentials_with_retrys because we caught exception: google.auth.exceptions.DefaultCredentialsError: Your default credentials were not found. To set up Application Default Credentials, see https://cloud.google.com/docs/authentication/external/set-up-adc for more information.
 Traceback for above exception (most recent call last):
  File "/home/sst7260/airflow_projects/project1/env/lib/python3.10/site-packages/apache_beam/utils/retry.py", line 298, in wrapper
    return fun(*args, **kwargs)
  File "/home/sst7260/airflow_projects/project1/env/lib/python3.10/site-packages/apache_beam/internal/gcp/auth.py", line 175, in _get_credentials_with_retrys
    credentials, _ = google.auth.default(
  File "/home/sst7260/airflow_projects/project1/env/lib/python3.10/site-packages/google/auth/_default.py", line 691, in default
    raise exceptions.DefaultCredentialsError(_CLOUD_SDK_MISSING_CREDENTIALS)

[2024-09-10T15:51:02.013+0530] {_metadata.py:142} WARNING - Compute Engine Metadata server unavailable on attempt 1 of 3. Reason: timed out
[2024-09-10T15:51:05.940+0530] {_metadata.py:142} WARNING - Compute Engine Metadata server unavailable on attempt 2 of 3. Reason: timed out
[2024-09-10T15:51:10.891+0530] {_metadata.py:142} WARNING - Compute Engine Metadata server unavailable on attempt 3 of 3. Reason: timed out
[2024-09-10T15:51:10.892+0530] {_default.py:338} WARNING - Authentication failed using Compute Engine authentication due to unavailable metadata server.
[2024-09-10T15:51:10.892+0530] {retry.py:313} WARNING - Retry with exponential backoff: waiting for 9.817998813076443 seconds before retrying _get_credentials_with_retrys because we caught exception: google.auth.exceptions.DefaultCredentialsError: Your default credentials were not found. To set up Application Default Credentials, see https://cloud.google.com/docs/authentication/external/set-up-adc for more information.
 Traceback for above exception (most recent call last):
  File "/home/sst7260/airflow_projects/project1/env/lib/python3.10/site-packages/apache_beam/utils/retry.py", line 298, in wrapper
    return fun(*args, **kwargs)
  File "/home/sst7260/airflow_projects/project1/env/lib/python3.10/site-packages/apache_beam/internal/gcp/auth.py", line 175, in _get_credentials_with_retrys
    credentials, _ = google.auth.default(
  File "/home/sst7260/airflow_projects/project1/env/lib/python3.10/site-packages/google/auth/_default.py", line 691, in default
    raise exceptions.DefaultCredentialsError(_CLOUD_SDK_MISSING_CREDENTIALS)

[2024-09-10T15:51:23.726+0530] {_metadata.py:142} WARNING - Compute Engine Metadata server unavailable on attempt 1 of 3. Reason: timed out
[2024-09-10T15:51:27.662+0530] {_metadata.py:142} WARNING - Compute Engine Metadata server unavailable on attempt 2 of 3. Reason: timed out
[2024-09-10T15:51:32.836+0530] {_metadata.py:142} WARNING - Compute Engine Metadata server unavailable on attempt 3 of 3. Reason: timed out
[2024-09-10T15:51:32.836+0530] {_default.py:338} WARNING - Authentication failed using Compute Engine authentication due to unavailable metadata server.
[2024-09-10T15:51:32.836+0530] {auth.py:165} WARNING - Unable to find default credentials to use: Your default credentials were not found. To set up Application Default Credentials, see https://cloud.google.com/docs/authentication/external/set-up-adc for more information.
Connecting anonymously. This is expected if no credentials are needed to access GCP resources.
[2024-09-10T15:51:33.390+0530] {requests.py:558} INFO - Refreshing credentials due to a 401 response. Attempt 1/2.
[2024-09-10T15:51:33.392+0530] {retry.py:313} WARNING - Retry with exponential backoff: waiting for 4.337132644844457 seconds before retrying _gcs_object because we caught exception: google.auth.exceptions.InvalidOperation: Anonymous credentials cannot be refreshed.
 Traceback for above exception (most recent call last):
  File "/home/sst7260/airflow_projects/project1/env/lib/python3.10/site-packages/apache_beam/utils/retry.py", line 298, in wrapper
    return fun(*args, **kwargs)
  File "/home/sst7260/airflow_projects/project1/env/lib/python3.10/site-packages/apache_beam/io/gcp/gcsio.py", line 462, in _gcs_object
    blob = bucket.get_blob(blob_name)
  File "/usr/lib/python3.10/contextlib.py", line 79, in inner
    return func(*args, **kwds)
  File "/home/sst7260/airflow_projects/project1/env/lib/python3.10/site-packages/google/cloud/storage/bucket.py", line 1283, in get_blob
    blob.reload(
  File "/home/sst7260/airflow_projects/project1/env/lib/python3.10/site-packages/google/cloud/storage/_helpers.py", line 300, in reload
    api_response = client._get_resource(
  File "/home/sst7260/airflow_projects/project1/env/lib/python3.10/site-packages/google/cloud/storage/client.py", line 464, in _get_resource
    return self._connection.api_request(
  File "/home/sst7260/airflow_projects/project1/env/lib/python3.10/site-packages/google/cloud/storage/_http.py", line 90, in api_request
    return call()
  File "/home/sst7260/airflow_projects/project1/env/lib/python3.10/site-packages/google/api_core/retry/retry_unary.py", line 293, in retry_wrapped_func
    return retry_target(
  File "/home/sst7260/airflow_projects/project1/env/lib/python3.10/site-packages/google/api_core/retry/retry_unary.py", line 153, in retry_target
    _retry_error_helper(
  File "/home/sst7260/airflow_projects/project1/env/lib/python3.10/site-packages/google/api_core/retry/retry_base.py", line 212, in _retry_error_helper
    raise final_exc from source_exc
  File "/home/sst7260/airflow_projects/project1/env/lib/python3.10/site-packages/google/api_core/retry/retry_unary.py", line 144, in retry_target
    result = target()
  File "/home/sst7260/airflow_projects/project1/env/lib/python3.10/site-packages/google/cloud/_http/__init__.py", line 482, in api_request
    response = self._make_request(
  File "/home/sst7260/airflow_projects/project1/env/lib/python3.10/site-packages/google/cloud/_http/__init__.py", line 341, in _make_request
    return self._do_request(
  File "/home/sst7260/airflow_projects/project1/env/lib/python3.10/site-packages/google/cloud/_http/__init__.py", line 379, in _do_request
    return self.http.request(
  File "/home/sst7260/airflow_projects/project1/env/lib/python3.10/site-packages/google/auth/transport/requests.py", line 574, in request
    self.credentials.refresh(auth_request)
  File "/home/sst7260/airflow_projects/project1/env/lib/python3.10/site-packages/google/auth/credentials.py", line 311, in refresh
    raise exceptions.InvalidOperation("Anonymous credentials cannot be refreshed.")

[2024-09-10T15:51:38.123+0530] {requests.py:558} INFO - Refreshing credentials due to a 401 response. Attempt 1/2.
[2024-09-10T15:51:38.123+0530] {retry.py:313} WARNING - Retry with exponential backoff: waiting for 9.744724542417565 seconds before retrying _gcs_object because we caught exception: google.auth.exceptions.InvalidOperation: Anonymous credentials cannot be refreshed.
 Traceback for above exception (most recent call last):
  File "/home/sst7260/airflow_projects/project1/env/lib/python3.10/site-packages/apache_beam/utils/retry.py", line 298, in wrapper
    return fun(*args, **kwargs)
  File "/home/sst7260/airflow_projects/project1/env/lib/python3.10/site-packages/apache_beam/io/gcp/gcsio.py", line 462, in _gcs_object
    blob = bucket.get_blob(blob_name)
  File "/usr/lib/python3.10/contextlib.py", line 79, in inner
    return func(*args, **kwds)
  File "/home/sst7260/airflow_projects/project1/env/lib/python3.10/site-packages/google/cloud/storage/bucket.py", line 1283, in get_blob
    blob.reload(
  File "/home/sst7260/airflow_projects/project1/env/lib/python3.10/site-packages/google/cloud/storage/_helpers.py", line 300, in reload
    api_response = client._get_resource(
  File "/home/sst7260/airflow_projects/project1/env/lib/python3.10/site-packages/google/cloud/storage/client.py", line 464, in _get_resource
    return self._connection.api_request(
  File "/home/sst7260/airflow_projects/project1/env/lib/python3.10/site-packages/google/cloud/storage/_http.py", line 90, in api_request
    return call()
  File "/home/sst7260/airflow_projects/project1/env/lib/python3.10/site-packages/google/api_core/retry/retry_unary.py", line 293, in retry_wrapped_func
    return retry_target(
  File "/home/sst7260/airflow_projects/project1/env/lib/python3.10/site-packages/google/api_core/retry/retry_unary.py", line 153, in retry_target
    _retry_error_helper(
  File "/home/sst7260/airflow_projects/project1/env/lib/python3.10/site-packages/google/api_core/retry/retry_base.py", line 212, in _retry_error_helper
    raise final_exc from source_exc
  File "/home/sst7260/airflow_projects/project1/env/lib/python3.10/site-packages/google/api_core/retry/retry_unary.py", line 144, in retry_target
    result = target()
  File "/home/sst7260/airflow_projects/project1/env/lib/python3.10/site-packages/google/cloud/_http/__init__.py", line 482, in api_request
    response = self._make_request(
  File "/home/sst7260/airflow_projects/project1/env/lib/python3.10/site-packages/google/cloud/_http/__init__.py", line 341, in _make_request
    return self._do_request(
  File "/home/sst7260/airflow_projects/project1/env/lib/python3.10/site-packages/google/cloud/_http/__init__.py", line 379, in _do_request
    return self.http.request(
  File "/home/sst7260/airflow_projects/project1/env/lib/python3.10/site-packages/google/auth/transport/requests.py", line 574, in request
    self.credentials.refresh(auth_request)
  File "/home/sst7260/airflow_projects/project1/env/lib/python3.10/site-packages/google/auth/credentials.py", line 311, in refresh
    raise exceptions.InvalidOperation("Anonymous credentials cannot be refreshed.")

[2024-09-10T15:51:48.263+0530] {requests.py:558} INFO - Refreshing credentials due to a 401 response. Attempt 1/2.
[2024-09-10T15:51:48.264+0530] {retry.py:313} WARNING - Retry with exponential backoff: waiting for 11.154831097892625 seconds before retrying _gcs_object because we caught exception: google.auth.exceptions.InvalidOperation: Anonymous credentials cannot be refreshed.
 Traceback for above exception (most recent call last):
  File "/home/sst7260/airflow_projects/project1/env/lib/python3.10/site-packages/apache_beam/utils/retry.py", line 298, in wrapper
    return fun(*args, **kwargs)
  File "/home/sst7260/airflow_projects/project1/env/lib/python3.10/site-packages/apache_beam/io/gcp/gcsio.py", line 462, in _gcs_object
    blob = bucket.get_blob(blob_name)
  File "/usr/lib/python3.10/contextlib.py", line 79, in inner
    return func(*args, **kwds)
  File "/home/sst7260/airflow_projects/project1/env/lib/python3.10/site-packages/google/cloud/storage/bucket.py", line 1283, in get_blob
    blob.reload(
  File "/home/sst7260/airflow_projects/project1/env/lib/python3.10/site-packages/google/cloud/storage/_helpers.py", line 300, in reload
    api_response = client._get_resource(
  File "/home/sst7260/airflow_projects/project1/env/lib/python3.10/site-packages/google/cloud/storage/client.py", line 464, in _get_resource
    return self._connection.api_request(
  File "/home/sst7260/airflow_projects/project1/env/lib/python3.10/site-packages/google/cloud/storage/_http.py", line 90, in api_request
    return call()
  File "/home/sst7260/airflow_projects/project1/env/lib/python3.10/site-packages/google/api_core/retry/retry_unary.py", line 293, in retry_wrapped_func
    return retry_target(
  File "/home/sst7260/airflow_projects/project1/env/lib/python3.10/site-packages/google/api_core/retry/retry_unary.py", line 153, in retry_target
    _retry_error_helper(
  File "/home/sst7260/airflow_projects/project1/env/lib/python3.10/site-packages/google/api_core/retry/retry_base.py", line 212, in _retry_error_helper
    raise final_exc from source_exc
  File "/home/sst7260/airflow_projects/project1/env/lib/python3.10/site-packages/google/api_core/retry/retry_unary.py", line 144, in retry_target
    result = target()
  File "/home/sst7260/airflow_projects/project1/env/lib/python3.10/site-packages/google/cloud/_http/__init__.py", line 482, in api_request
    response = self._make_request(
  File "/home/sst7260/airflow_projects/project1/env/lib/python3.10/site-packages/google/cloud/_http/__init__.py", line 341, in _make_request
    return self._do_request(
  File "/home/sst7260/airflow_projects/project1/env/lib/python3.10/site-packages/google/cloud/_http/__init__.py", line 379, in _do_request
    return self.http.request(
  File "/home/sst7260/airflow_projects/project1/env/lib/python3.10/site-packages/google/auth/transport/requests.py", line 574, in request
    self.credentials.refresh(auth_request)
  File "/home/sst7260/airflow_projects/project1/env/lib/python3.10/site-packages/google/auth/credentials.py", line 311, in refresh
    raise exceptions.InvalidOperation("Anonymous credentials cannot be refreshed.")

[2024-09-10T15:51:59.810+0530] {requests.py:558} INFO - Refreshing credentials due to a 401 response. Attempt 1/2.
[2024-09-10T15:51:59.811+0530] {retry.py:313} WARNING - Retry with exponential backoff: waiting for 38.282027032918094 seconds before retrying _gcs_object because we caught exception: google.auth.exceptions.InvalidOperation: Anonymous credentials cannot be refreshed.
 Traceback for above exception (most recent call last):
  File "/home/sst7260/airflow_projects/project1/env/lib/python3.10/site-packages/apache_beam/utils/retry.py", line 298, in wrapper
    return fun(*args, **kwargs)
  File "/home/sst7260/airflow_projects/project1/env/lib/python3.10/site-packages/apache_beam/io/gcp/gcsio.py", line 462, in _gcs_object
    blob = bucket.get_blob(blob_name)
  File "/usr/lib/python3.10/contextlib.py", line 79, in inner
    return func(*args, **kwds)
  File "/home/sst7260/airflow_projects/project1/env/lib/python3.10/site-packages/google/cloud/storage/bucket.py", line 1283, in get_blob
    blob.reload(
  File "/home/sst7260/airflow_projects/project1/env/lib/python3.10/site-packages/google/cloud/storage/_helpers.py", line 300, in reload
    api_response = client._get_resource(
  File "/home/sst7260/airflow_projects/project1/env/lib/python3.10/site-packages/google/cloud/storage/client.py", line 464, in _get_resource
    return self._connection.api_request(
  File "/home/sst7260/airflow_projects/project1/env/lib/python3.10/site-packages/google/cloud/storage/_http.py", line 90, in api_request
    return call()
  File "/home/sst7260/airflow_projects/project1/env/lib/python3.10/site-packages/google/api_core/retry/retry_unary.py", line 293, in retry_wrapped_func
    return retry_target(
  File "/home/sst7260/airflow_projects/project1/env/lib/python3.10/site-packages/google/api_core/retry/retry_unary.py", line 153, in retry_target
    _retry_error_helper(
  File "/home/sst7260/airflow_projects/project1/env/lib/python3.10/site-packages/google/api_core/retry/retry_base.py", line 212, in _retry_error_helper
    raise final_exc from source_exc
  File "/home/sst7260/airflow_projects/project1/env/lib/python3.10/site-packages/google/api_core/retry/retry_unary.py", line 144, in retry_target
    result = target()
  File "/home/sst7260/airflow_projects/project1/env/lib/python3.10/site-packages/google/cloud/_http/__init__.py", line 482, in api_request
    response = self._make_request(
  File "/home/sst7260/airflow_projects/project1/env/lib/python3.10/site-packages/google/cloud/_http/__init__.py", line 341, in _make_request
    return self._do_request(
  File "/home/sst7260/airflow_projects/project1/env/lib/python3.10/site-packages/google/cloud/_http/__init__.py", line 379, in _do_request
    return self.http.request(
  File "/home/sst7260/airflow_projects/project1/env/lib/python3.10/site-packages/google/auth/transport/requests.py", line 574, in request
    self.credentials.refresh(auth_request)
  File "/home/sst7260/airflow_projects/project1/env/lib/python3.10/site-packages/google/auth/credentials.py", line 311, in refresh
    raise exceptions.InvalidOperation("Anonymous credentials cannot be refreshed.")

[2024-09-10T15:52:38.518+0530] {requests.py:558} INFO - Refreshing credentials due to a 401 response. Attempt 1/2.
[2024-09-10T15:52:38.518+0530] {retry.py:313} WARNING - Retry with exponential backoff: waiting for 43.14893787358035 seconds before retrying _gcs_object because we caught exception: google.auth.exceptions.InvalidOperation: Anonymous credentials cannot be refreshed.
 Traceback for above exception (most recent call last):
  File "/home/sst7260/airflow_projects/project1/env/lib/python3.10/site-packages/apache_beam/utils/retry.py", line 298, in wrapper
    return fun(*args, **kwargs)
  File "/home/sst7260/airflow_projects/project1/env/lib/python3.10/site-packages/apache_beam/io/gcp/gcsio.py", line 462, in _gcs_object
    blob = bucket.get_blob(blob_name)
  File "/usr/lib/python3.10/contextlib.py", line 79, in inner
    return func(*args, **kwds)
  File "/home/sst7260/airflow_projects/project1/env/lib/python3.10/site-packages/google/cloud/storage/bucket.py", line 1283, in get_blob
    blob.reload(
  File "/home/sst7260/airflow_projects/project1/env/lib/python3.10/site-packages/google/cloud/storage/_helpers.py", line 300, in reload
    api_response = client._get_resource(
  File "/home/sst7260/airflow_projects/project1/env/lib/python3.10/site-packages/google/cloud/storage/client.py", line 464, in _get_resource
    return self._connection.api_request(
  File "/home/sst7260/airflow_projects/project1/env/lib/python3.10/site-packages/google/cloud/storage/_http.py", line 90, in api_request
    return call()
  File "/home/sst7260/airflow_projects/project1/env/lib/python3.10/site-packages/google/api_core/retry/retry_unary.py", line 293, in retry_wrapped_func
    return retry_target(
  File "/home/sst7260/airflow_projects/project1/env/lib/python3.10/site-packages/google/api_core/retry/retry_unary.py", line 153, in retry_target
    _retry_error_helper(
  File "/home/sst7260/airflow_projects/project1/env/lib/python3.10/site-packages/google/api_core/retry/retry_base.py", line 212, in _retry_error_helper
    raise final_exc from source_exc
  File "/home/sst7260/airflow_projects/project1/env/lib/python3.10/site-packages/google/api_core/retry/retry_unary.py", line 144, in retry_target
    result = target()
  File "/home/sst7260/airflow_projects/project1/env/lib/python3.10/site-packages/google/cloud/_http/__init__.py", line 482, in api_request
    response = self._make_request(
  File "/home/sst7260/airflow_projects/project1/env/lib/python3.10/site-packages/google/cloud/_http/__init__.py", line 341, in _make_request
    return self._do_request(
  File "/home/sst7260/airflow_projects/project1/env/lib/python3.10/site-packages/google/cloud/_http/__init__.py", line 379, in _do_request
    return self.http.request(
  File "/home/sst7260/airflow_projects/project1/env/lib/python3.10/site-packages/google/auth/transport/requests.py", line 574, in request
    self.credentials.refresh(auth_request)
  File "/home/sst7260/airflow_projects/project1/env/lib/python3.10/site-packages/google/auth/credentials.py", line 311, in refresh
    raise exceptions.InvalidOperation("Anonymous credentials cannot be refreshed.")

[2024-09-10T15:53:22.101+0530] {requests.py:558} INFO - Refreshing credentials due to a 401 response. Attempt 1/2.
[2024-09-10T15:53:22.102+0530] {retry.py:313} WARNING - Retry with exponential backoff: waiting for 104.3505244575244 seconds before retrying _gcs_object because we caught exception: google.auth.exceptions.InvalidOperation: Anonymous credentials cannot be refreshed.
 Traceback for above exception (most recent call last):
  File "/home/sst7260/airflow_projects/project1/env/lib/python3.10/site-packages/apache_beam/utils/retry.py", line 298, in wrapper
    return fun(*args, **kwargs)
  File "/home/sst7260/airflow_projects/project1/env/lib/python3.10/site-packages/apache_beam/io/gcp/gcsio.py", line 462, in _gcs_object
    blob = bucket.get_blob(blob_name)
  File "/usr/lib/python3.10/contextlib.py", line 79, in inner
    return func(*args, **kwds)
  File "/home/sst7260/airflow_projects/project1/env/lib/python3.10/site-packages/google/cloud/storage/bucket.py", line 1283, in get_blob
    blob.reload(
  File "/home/sst7260/airflow_projects/project1/env/lib/python3.10/site-packages/google/cloud/storage/_helpers.py", line 300, in reload
    api_response = client._get_resource(
  File "/home/sst7260/airflow_projects/project1/env/lib/python3.10/site-packages/google/cloud/storage/client.py", line 464, in _get_resource
    return self._connection.api_request(
  File "/home/sst7260/airflow_projects/project1/env/lib/python3.10/site-packages/google/cloud/storage/_http.py", line 90, in api_request
    return call()
  File "/home/sst7260/airflow_projects/project1/env/lib/python3.10/site-packages/google/api_core/retry/retry_unary.py", line 293, in retry_wrapped_func
    return retry_target(
  File "/home/sst7260/airflow_projects/project1/env/lib/python3.10/site-packages/google/api_core/retry/retry_unary.py", line 153, in retry_target
    _retry_error_helper(
  File "/home/sst7260/airflow_projects/project1/env/lib/python3.10/site-packages/google/api_core/retry/retry_base.py", line 212, in _retry_error_helper
    raise final_exc from source_exc
  File "/home/sst7260/airflow_projects/project1/env/lib/python3.10/site-packages/google/api_core/retry/retry_unary.py", line 144, in retry_target
    result = target()
  File "/home/sst7260/airflow_projects/project1/env/lib/python3.10/site-packages/google/cloud/_http/__init__.py", line 482, in api_request
    response = self._make_request(
  File "/home/sst7260/airflow_projects/project1/env/lib/python3.10/site-packages/google/cloud/_http/__init__.py", line 341, in _make_request
    return self._do_request(
  File "/home/sst7260/airflow_projects/project1/env/lib/python3.10/site-packages/google/cloud/_http/__init__.py", line 379, in _do_request
    return self.http.request(
  File "/home/sst7260/airflow_projects/project1/env/lib/python3.10/site-packages/google/auth/transport/requests.py", line 574, in request
    self.credentials.refresh(auth_request)
  File "/home/sst7260/airflow_projects/project1/env/lib/python3.10/site-packages/google/auth/credentials.py", line 311, in refresh
    raise exceptions.InvalidOperation("Anonymous credentials cannot be refreshed.")

[2024-09-10T15:55:06.971+0530] {requests.py:558} INFO - Refreshing credentials due to a 401 response. Attempt 1/2.
[2024-09-10T15:55:06.972+0530] {retry.py:313} WARNING - Retry with exponential backoff: waiting for 194.35359037798648 seconds before retrying _gcs_object because we caught exception: google.auth.exceptions.InvalidOperation: Anonymous credentials cannot be refreshed.
 Traceback for above exception (most recent call last):
  File "/home/sst7260/airflow_projects/project1/env/lib/python3.10/site-packages/apache_beam/utils/retry.py", line 298, in wrapper
    return fun(*args, **kwargs)
  File "/home/sst7260/airflow_projects/project1/env/lib/python3.10/site-packages/apache_beam/io/gcp/gcsio.py", line 462, in _gcs_object
    blob = bucket.get_blob(blob_name)
  File "/usr/lib/python3.10/contextlib.py", line 79, in inner
    return func(*args, **kwds)
  File "/home/sst7260/airflow_projects/project1/env/lib/python3.10/site-packages/google/cloud/storage/bucket.py", line 1283, in get_blob
    blob.reload(
  File "/home/sst7260/airflow_projects/project1/env/lib/python3.10/site-packages/google/cloud/storage/_helpers.py", line 300, in reload
    api_response = client._get_resource(
  File "/home/sst7260/airflow_projects/project1/env/lib/python3.10/site-packages/google/cloud/storage/client.py", line 464, in _get_resource
    return self._connection.api_request(
  File "/home/sst7260/airflow_projects/project1/env/lib/python3.10/site-packages/google/cloud/storage/_http.py", line 90, in api_request
    return call()
  File "/home/sst7260/airflow_projects/project1/env/lib/python3.10/site-packages/google/api_core/retry/retry_unary.py", line 293, in retry_wrapped_func
    return retry_target(
  File "/home/sst7260/airflow_projects/project1/env/lib/python3.10/site-packages/google/api_core/retry/retry_unary.py", line 153, in retry_target
    _retry_error_helper(
  File "/home/sst7260/airflow_projects/project1/env/lib/python3.10/site-packages/google/api_core/retry/retry_base.py", line 212, in _retry_error_helper
    raise final_exc from source_exc
  File "/home/sst7260/airflow_projects/project1/env/lib/python3.10/site-packages/google/api_core/retry/retry_unary.py", line 144, in retry_target
    result = target()
  File "/home/sst7260/airflow_projects/project1/env/lib/python3.10/site-packages/google/cloud/_http/__init__.py", line 482, in api_request
    response = self._make_request(
  File "/home/sst7260/airflow_projects/project1/env/lib/python3.10/site-packages/google/cloud/_http/__init__.py", line 341, in _make_request
    return self._do_request(
  File "/home/sst7260/airflow_projects/project1/env/lib/python3.10/site-packages/google/cloud/_http/__init__.py", line 379, in _do_request
    return self.http.request(
  File "/home/sst7260/airflow_projects/project1/env/lib/python3.10/site-packages/google/auth/transport/requests.py", line 574, in request
    self.credentials.refresh(auth_request)
  File "/home/sst7260/airflow_projects/project1/env/lib/python3.10/site-packages/google/auth/credentials.py", line 311, in refresh
    raise exceptions.InvalidOperation("Anonymous credentials cannot be refreshed.")

[2024-09-10T15:58:21.811+0530] {requests.py:558} INFO - Refreshing credentials due to a 401 response. Attempt 1/2.
[2024-09-10T15:58:21.814+0530] {taskinstance.py:3310} ERROR - Task failed with exception
Traceback (most recent call last):
  File "/home/sst7260/airflow_projects/project1/env/lib/python3.10/site-packages/airflow/models/taskinstance.py", line 767, in _execute_task
    result = _execute_callable(context=context, **execute_callable_kwargs)
  File "/home/sst7260/airflow_projects/project1/env/lib/python3.10/site-packages/airflow/models/taskinstance.py", line 733, in _execute_callable
    return ExecutionCallableRunner(
  File "/home/sst7260/airflow_projects/project1/env/lib/python3.10/site-packages/airflow/utils/operator_helpers.py", line 252, in run
    return self.func(*args, **kwargs)
  File "/home/sst7260/airflow_projects/project1/env/lib/python3.10/site-packages/airflow/models/baseoperator.py", line 406, in wrapper
    return func(self, *args, **kwargs)
  File "/home/sst7260/airflow_projects/project1/env/lib/python3.10/site-packages/airflow/operators/python.py", line 238, in execute
    return_value = self.execute_callable()
  File "/home/sst7260/airflow_projects/project1/env/lib/python3.10/site-packages/airflow/operators/python.py", line 256, in execute_callable
    return runner.run(*self.op_args, **self.op_kwargs)
  File "/home/sst7260/airflow_projects/project1/env/lib/python3.10/site-packages/airflow/utils/operator_helpers.py", line 252, in run
    return self.func(*args, **kwargs)
  File "/home/sst7260/airflow_projects/project1/dags/beam_etl_dag.py", line 51, in run_beam_pipeline
  File "/home/sst7260/airflow_projects/project1/env/lib/python3.10/site-packages/apache_beam/io/textio.py", line 781, in __init__
    self._source = self._source_class(
  File "/home/sst7260/airflow_projects/project1/env/lib/python3.10/site-packages/apache_beam/io/textio.py", line 140, in __init__
    super().__init__(
  File "/home/sst7260/airflow_projects/project1/env/lib/python3.10/site-packages/apache_beam/io/filebasedsource.py", line 127, in __init__
    self._validate()
  File "/home/sst7260/airflow_projects/project1/env/lib/python3.10/site-packages/apache_beam/options/value_provider.py", line 193, in _f
    return fnc(self, *args, **kwargs)
  File "/home/sst7260/airflow_projects/project1/env/lib/python3.10/site-packages/apache_beam/io/filebasedsource.py", line 188, in _validate
    match_result = FileSystems.match([pattern], limits=[1])[0]
  File "/home/sst7260/airflow_projects/project1/env/lib/python3.10/site-packages/apache_beam/io/filesystems.py", line 239, in match
    return filesystem.match(patterns, limits)
  File "/home/sst7260/airflow_projects/project1/env/lib/python3.10/site-packages/apache_beam/io/filesystem.py", line 804, in match
    raise BeamIOError("Match operation failed", exceptions)
apache_beam.io.filesystem.BeamIOError: Match operation failed with exceptions {'gs://sn_insights_test/input/OnlineRetail.csv': InvalidOperation('Anonymous credentials cannot be refreshed.')}
[2024-09-10T15:58:21.843+0530] {logging_mixin.py:190} INFO - Task instance in failure state
[2024-09-10T15:58:21.844+0530] {logging_mixin.py:190} INFO - Task start:2024-09-10 10:20:12.381135+00:00 end:2024-09-10 10:28:21.842058+00:00 duration:489.460923
[2024-09-10T15:58:21.844+0530] {logging_mixin.py:190} INFO - Task:<Task(PythonOperator): run_beam_pipeline> dag:<DAG: beam_etl_dag_with_credentials> dagrun:<DagRun beam_etl_dag_with_credentials @ 2024-09-10 10:04:53.865121+00:00: manual__2024-09-10T10:04:53.865121+00:00, state:running, queued_at: 2024-09-10 10:04:53.878805+00:00. externally triggered: True>
[2024-09-10T15:58:21.844+0530] {logging_mixin.py:190} INFO - Failure caused by Match operation failed with exceptions {'gs://sn_insights_test/input/OnlineRetail.csv': InvalidOperation('Anonymous credentials cannot be refreshed.')}
[2024-09-10T15:58:21.844+0530] {taskinstance.py:1225} INFO - Marking task as FAILED. dag_id=beam_etl_dag_with_credentials, task_id=run_beam_pipeline, run_id=manual__2024-09-10T10:04:53.865121+00:00, execution_date=20240910T100453, start_date=20240910T102012, end_date=20240910T102821
[2024-09-10T15:58:21.880+0530] {taskinstance.py:340} INFO - ::group::Post task execution logs
[2024-09-10T15:58:21.881+0530] {standard_task_runner.py:124} ERROR - Failed to execute job 73 for task run_beam_pipeline (Match operation failed with exceptions {'gs://sn_insights_test/input/OnlineRetail.csv': InvalidOperation('Anonymous credentials cannot be refreshed.')}; 194150)
Traceback (most recent call last):
  File "/home/sst7260/airflow_projects/project1/env/lib/python3.10/site-packages/airflow/task/task_runner/standard_task_runner.py", line 117, in _start_by_fork
    ret = args.func(args, dag=self.dag)
  File "/home/sst7260/airflow_projects/project1/env/lib/python3.10/site-packages/airflow/cli/cli_config.py", line 49, in command
    return func(*args, **kwargs)
  File "/home/sst7260/airflow_projects/project1/env/lib/python3.10/site-packages/airflow/utils/cli.py", line 115, in wrapper
    return f(*args, **kwargs)
  File "/home/sst7260/airflow_projects/project1/env/lib/python3.10/site-packages/airflow/cli/commands/task_command.py", line 483, in task_run
    task_return_code = _run_task_by_selected_method(args, _dag, ti)
  File "/home/sst7260/airflow_projects/project1/env/lib/python3.10/site-packages/airflow/cli/commands/task_command.py", line 256, in _run_task_by_selected_method
    return _run_raw_task(args, ti)
  File "/home/sst7260/airflow_projects/project1/env/lib/python3.10/site-packages/airflow/cli/commands/task_command.py", line 341, in _run_raw_task
    return ti._run_raw_task(
  File "/home/sst7260/airflow_projects/project1/env/lib/python3.10/site-packages/airflow/utils/session.py", line 97, in wrapper
    return func(*args, session=session, **kwargs)
  File "/home/sst7260/airflow_projects/project1/env/lib/python3.10/site-packages/airflow/models/taskinstance.py", line 3004, in _run_raw_task
    return _run_raw_task(
  File "/home/sst7260/airflow_projects/project1/env/lib/python3.10/site-packages/airflow/models/taskinstance.py", line 273, in _run_raw_task
    TaskInstance._execute_task_with_callbacks(
  File "/home/sst7260/airflow_projects/project1/env/lib/python3.10/site-packages/airflow/models/taskinstance.py", line 3158, in _execute_task_with_callbacks
    result = self._execute_task(context, task_orig)
  File "/home/sst7260/airflow_projects/project1/env/lib/python3.10/site-packages/airflow/models/taskinstance.py", line 3182, in _execute_task
    return _execute_task(self, context, task_orig)
  File "/home/sst7260/airflow_projects/project1/env/lib/python3.10/site-packages/airflow/models/taskinstance.py", line 767, in _execute_task
    result = _execute_callable(context=context, **execute_callable_kwargs)
  File "/home/sst7260/airflow_projects/project1/env/lib/python3.10/site-packages/airflow/models/taskinstance.py", line 733, in _execute_callable
    return ExecutionCallableRunner(
  File "/home/sst7260/airflow_projects/project1/env/lib/python3.10/site-packages/airflow/utils/operator_helpers.py", line 252, in run
    return self.func(*args, **kwargs)
  File "/home/sst7260/airflow_projects/project1/env/lib/python3.10/site-packages/airflow/models/baseoperator.py", line 406, in wrapper
    return func(self, *args, **kwargs)
  File "/home/sst7260/airflow_projects/project1/env/lib/python3.10/site-packages/airflow/operators/python.py", line 238, in execute
    return_value = self.execute_callable()
  File "/home/sst7260/airflow_projects/project1/env/lib/python3.10/site-packages/airflow/operators/python.py", line 256, in execute_callable
    return runner.run(*self.op_args, **self.op_kwargs)
  File "/home/sst7260/airflow_projects/project1/env/lib/python3.10/site-packages/airflow/utils/operator_helpers.py", line 252, in run
    return self.func(*args, **kwargs)
  File "/home/sst7260/airflow_projects/project1/dags/beam_etl_dag.py", line 51, in run_beam_pipeline
  File "/home/sst7260/airflow_projects/project1/env/lib/python3.10/site-packages/apache_beam/io/textio.py", line 781, in __init__
    self._source = self._source_class(
  File "/home/sst7260/airflow_projects/project1/env/lib/python3.10/site-packages/apache_beam/io/textio.py", line 140, in __init__
    super().__init__(
  File "/home/sst7260/airflow_projects/project1/env/lib/python3.10/site-packages/apache_beam/io/filebasedsource.py", line 127, in __init__
    self._validate()
  File "/home/sst7260/airflow_projects/project1/env/lib/python3.10/site-packages/apache_beam/options/value_provider.py", line 193, in _f
    return fnc(self, *args, **kwargs)
  File "/home/sst7260/airflow_projects/project1/env/lib/python3.10/site-packages/apache_beam/io/filebasedsource.py", line 188, in _validate
    match_result = FileSystems.match([pattern], limits=[1])[0]
  File "/home/sst7260/airflow_projects/project1/env/lib/python3.10/site-packages/apache_beam/io/filesystems.py", line 239, in match
    return filesystem.match(patterns, limits)
  File "/home/sst7260/airflow_projects/project1/env/lib/python3.10/site-packages/apache_beam/io/filesystem.py", line 804, in match
    raise BeamIOError("Match operation failed", exceptions)
apache_beam.io.filesystem.BeamIOError: Match operation failed with exceptions {'gs://sn_insights_test/input/OnlineRetail.csv': InvalidOperation('Anonymous credentials cannot be refreshed.')}
[2024-09-10T15:58:21.934+0530] {local_task_job_runner.py:266} INFO - Task exited with return code 1
[2024-09-10T15:58:21.955+0530] {taskinstance.py:3900} INFO - 0 downstream tasks scheduled from follow-on schedule check
[2024-09-10T15:58:21.955+0530] {local_task_job_runner.py:245} INFO - ::endgroup::
