[2024-09-10T12:01:00.463+0530] {local_task_job_runner.py:123} INFO - ::group::Pre task execution logs
[2024-09-10T12:01:00.493+0530] {taskinstance.py:2612} INFO - Dependencies all met for dep_context=non-requeueable deps ti=<TaskInstance: apache_beam_etl_pipeline.run_beam_pipeline2 manual__2024-09-10T06:25:53.429449+00:00 [queued]>
[2024-09-10T12:01:00.498+0530] {taskinstance.py:2612} INFO - Dependencies all met for dep_context=requeueable deps ti=<TaskInstance: apache_beam_etl_pipeline.run_beam_pipeline2 manual__2024-09-10T06:25:53.429449+00:00 [queued]>
[2024-09-10T12:01:00.498+0530] {taskinstance.py:2865} INFO - Starting attempt 2 of 2
[2024-09-10T12:01:00.542+0530] {taskinstance.py:2888} INFO - Executing <Task(BashOperator): run_beam_pipeline2> on 2024-09-10 06:25:53.429449+00:00
[2024-09-10T12:01:00.545+0530] {standard_task_runner.py:72} INFO - Started process 155379 to run task
[2024-09-10T12:01:00.548+0530] {standard_task_runner.py:104} INFO - Running: ['airflow', 'tasks', 'run', 'apache_beam_etl_pipeline', 'run_beam_pipeline2', 'manual__2024-09-10T06:25:53.429449+00:00', '--job-id', '46', '--raw', '--subdir', 'DAGS_FOLDER/aaz.py', '--cfg-path', '/tmp/tmp_w_eqgsn']
[2024-09-10T12:01:00.548+0530] {standard_task_runner.py:105} INFO - Job 46: Subtask run_beam_pipeline2
[2024-09-10T12:01:00.595+0530] {task_command.py:467} INFO - Running <TaskInstance: apache_beam_etl_pipeline.run_beam_pipeline2 manual__2024-09-10T06:25:53.429449+00:00 [running]> on host PG0392KD.springernature.com
[2024-09-10T12:01:00.659+0530] {taskinstance.py:3131} INFO - Exporting env vars: AIRFLOW_CTX_DAG_OWNER='airflow_SS' AIRFLOW_CTX_DAG_ID='apache_beam_etl_pipeline' AIRFLOW_CTX_TASK_ID='run_beam_pipeline2' AIRFLOW_CTX_EXECUTION_DATE='2024-09-10T06:25:53.429449+00:00' AIRFLOW_CTX_TRY_NUMBER='2' AIRFLOW_CTX_DAG_RUN_ID='manual__2024-09-10T06:25:53.429449+00:00'
[2024-09-10T12:01:00.660+0530] {logging_mixin.py:190} INFO - Task instance is in running state
[2024-09-10T12:01:00.660+0530] {logging_mixin.py:190} INFO -  Previous state of the Task instance: queued
[2024-09-10T12:01:00.660+0530] {logging_mixin.py:190} INFO - Current task name:run_beam_pipeline2 state:running start_date:2024-09-10 06:31:00.493423+00:00
[2024-09-10T12:01:00.661+0530] {logging_mixin.py:190} INFO - Dag name:apache_beam_etl_pipeline and current dag run status:running
[2024-09-10T12:01:00.661+0530] {taskinstance.py:731} INFO - ::endgroup::
[2024-09-10T12:01:00.661+0530] {subprocess.py:63} INFO - Tmp dir root location: /tmp
[2024-09-10T12:01:00.662+0530] {subprocess.py:75} INFO - Running command: ['/usr/bin/bash', '-c', 'python3 ~/airflow_projects/project1/beam_scripts/etl_pipe_1.py']
[2024-09-10T12:01:00.668+0530] {subprocess.py:86} INFO - Output:
[2024-09-10T12:01:01.178+0530] {subprocess.py:93} INFO - Failed to import GCSFileSystem; loading of this filesystem will be skipped. Error details: cannot import name 'storage' from 'google.cloud' (unknown location)
[2024-09-10T12:01:01.314+0530] {subprocess.py:93} INFO - Traceback (most recent call last):
[2024-09-10T12:01:01.314+0530] {subprocess.py:93} INFO -   File "/home/sst7260/airflow_projects/project1/beam_scripts/etl_pipe_1.py", line 53, in <module>
[2024-09-10T12:01:01.314+0530] {subprocess.py:93} INFO -     transform_load()
[2024-09-10T12:01:01.314+0530] {subprocess.py:93} INFO -   File "/home/sst7260/airflow_projects/project1/beam_scripts/etl_pipe_1.py", line 37, in transform_load
[2024-09-10T12:01:01.314+0530] {subprocess.py:93} INFO -     | 'ReadFromText' >> ReadFromText(raw_data_bucket,
[2024-09-10T12:01:01.315+0530] {subprocess.py:93} INFO -   File "/home/sst7260/airflow_projects/project1/env/lib/python3.10/site-packages/apache_beam/io/textio.py", line 781, in __init__
[2024-09-10T12:01:01.315+0530] {subprocess.py:93} INFO -     self._source = self._source_class(
[2024-09-10T12:01:01.315+0530] {subprocess.py:93} INFO -   File "/home/sst7260/airflow_projects/project1/env/lib/python3.10/site-packages/apache_beam/io/textio.py", line 140, in __init__
[2024-09-10T12:01:01.315+0530] {subprocess.py:93} INFO -     super().__init__(
[2024-09-10T12:01:01.315+0530] {subprocess.py:93} INFO -   File "/home/sst7260/airflow_projects/project1/env/lib/python3.10/site-packages/apache_beam/io/filebasedsource.py", line 127, in __init__
[2024-09-10T12:01:01.315+0530] {subprocess.py:93} INFO -     self._validate()
[2024-09-10T12:01:01.315+0530] {subprocess.py:93} INFO -   File "/home/sst7260/airflow_projects/project1/env/lib/python3.10/site-packages/apache_beam/options/value_provider.py", line 193, in _f
[2024-09-10T12:01:01.315+0530] {subprocess.py:93} INFO -     return fnc(self, *args, **kwargs)
[2024-09-10T12:01:01.315+0530] {subprocess.py:93} INFO -   File "/home/sst7260/airflow_projects/project1/env/lib/python3.10/site-packages/apache_beam/io/filebasedsource.py", line 188, in _validate
[2024-09-10T12:01:01.315+0530] {subprocess.py:93} INFO -     match_result = FileSystems.match([pattern], limits=[1])[0]
[2024-09-10T12:01:01.315+0530] {subprocess.py:93} INFO -   File "/home/sst7260/airflow_projects/project1/env/lib/python3.10/site-packages/apache_beam/io/filesystems.py", line 238, in match
[2024-09-10T12:01:01.315+0530] {subprocess.py:93} INFO -     filesystem = FileSystems.get_filesystem(patterns[0])
[2024-09-10T12:01:01.316+0530] {subprocess.py:93} INFO -   File "/home/sst7260/airflow_projects/project1/env/lib/python3.10/site-packages/apache_beam/io/filesystems.py", line 138, in get_filesystem
[2024-09-10T12:01:01.316+0530] {subprocess.py:93} INFO -     raise ValueError(
[2024-09-10T12:01:01.316+0530] {subprocess.py:93} INFO - ValueError: Unable to get filesystem from specified path, please use the correct path or ensure the required dependency is installed, e.g., pip install apache-beam[gcp]. Path specified: gs://sn_insights_test/input/OnlineRetail.csv
[2024-09-10T12:01:01.415+0530] {subprocess.py:97} INFO - Command exited with return code 1
[2024-09-10T12:01:01.421+0530] {taskinstance.py:3310} ERROR - Task failed with exception
Traceback (most recent call last):
  File "/home/sst7260/airflow_projects/project1/env/lib/python3.10/site-packages/airflow/models/taskinstance.py", line 767, in _execute_task
    result = _execute_callable(context=context, **execute_callable_kwargs)
  File "/home/sst7260/airflow_projects/project1/env/lib/python3.10/site-packages/airflow/models/taskinstance.py", line 733, in _execute_callable
    return ExecutionCallableRunner(
  File "/home/sst7260/airflow_projects/project1/env/lib/python3.10/site-packages/airflow/utils/operator_helpers.py", line 252, in run
    return self.func(*args, **kwargs)
  File "/home/sst7260/airflow_projects/project1/env/lib/python3.10/site-packages/airflow/models/baseoperator.py", line 406, in wrapper
    return func(self, *args, **kwargs)
  File "/home/sst7260/airflow_projects/project1/env/lib/python3.10/site-packages/airflow/operators/bash.py", line 249, in execute
    raise AirflowException(
airflow.exceptions.AirflowException: Bash command failed. The command returned a non-zero exit code 1.
[2024-09-10T12:01:01.424+0530] {logging_mixin.py:190} INFO - Task instance in failure state
[2024-09-10T12:01:01.425+0530] {logging_mixin.py:190} INFO - Task start:2024-09-10 06:31:00.493423+00:00 end:2024-09-10 06:31:01.423887+00:00 duration:0.930464
[2024-09-10T12:01:01.425+0530] {logging_mixin.py:190} INFO - Task:<Task(BashOperator): run_beam_pipeline2> dag:<DAG: apache_beam_etl_pipeline> dagrun:<DagRun apache_beam_etl_pipeline @ 2024-09-10 06:25:53.429449+00:00: manual__2024-09-10T06:25:53.429449+00:00, state:running, queued_at: 2024-09-10 06:25:53.441589+00:00. externally triggered: True>
[2024-09-10T12:01:01.425+0530] {logging_mixin.py:190} INFO - Failure caused by Bash command failed. The command returned a non-zero exit code 1.
[2024-09-10T12:01:01.425+0530] {taskinstance.py:1225} INFO - Marking task as FAILED. dag_id=apache_beam_etl_pipeline, task_id=run_beam_pipeline2, run_id=manual__2024-09-10T06:25:53.429449+00:00, execution_date=20240910T062553, start_date=20240910T063100, end_date=20240910T063101
[2024-09-10T12:01:01.448+0530] {taskinstance.py:340} INFO - ::group::Post task execution logs
[2024-09-10T12:01:01.449+0530] {standard_task_runner.py:124} ERROR - Failed to execute job 46 for task run_beam_pipeline2 (Bash command failed. The command returned a non-zero exit code 1.; 155379)
Traceback (most recent call last):
  File "/home/sst7260/airflow_projects/project1/env/lib/python3.10/site-packages/airflow/task/task_runner/standard_task_runner.py", line 117, in _start_by_fork
    ret = args.func(args, dag=self.dag)
  File "/home/sst7260/airflow_projects/project1/env/lib/python3.10/site-packages/airflow/cli/cli_config.py", line 49, in command
    return func(*args, **kwargs)
  File "/home/sst7260/airflow_projects/project1/env/lib/python3.10/site-packages/airflow/utils/cli.py", line 115, in wrapper
    return f(*args, **kwargs)
  File "/home/sst7260/airflow_projects/project1/env/lib/python3.10/site-packages/airflow/cli/commands/task_command.py", line 483, in task_run
    task_return_code = _run_task_by_selected_method(args, _dag, ti)
  File "/home/sst7260/airflow_projects/project1/env/lib/python3.10/site-packages/airflow/cli/commands/task_command.py", line 256, in _run_task_by_selected_method
    return _run_raw_task(args, ti)
  File "/home/sst7260/airflow_projects/project1/env/lib/python3.10/site-packages/airflow/cli/commands/task_command.py", line 341, in _run_raw_task
    return ti._run_raw_task(
  File "/home/sst7260/airflow_projects/project1/env/lib/python3.10/site-packages/airflow/utils/session.py", line 97, in wrapper
    return func(*args, session=session, **kwargs)
  File "/home/sst7260/airflow_projects/project1/env/lib/python3.10/site-packages/airflow/models/taskinstance.py", line 3004, in _run_raw_task
    return _run_raw_task(
  File "/home/sst7260/airflow_projects/project1/env/lib/python3.10/site-packages/airflow/models/taskinstance.py", line 273, in _run_raw_task
    TaskInstance._execute_task_with_callbacks(
  File "/home/sst7260/airflow_projects/project1/env/lib/python3.10/site-packages/airflow/models/taskinstance.py", line 3158, in _execute_task_with_callbacks
    result = self._execute_task(context, task_orig)
  File "/home/sst7260/airflow_projects/project1/env/lib/python3.10/site-packages/airflow/models/taskinstance.py", line 3182, in _execute_task
    return _execute_task(self, context, task_orig)
  File "/home/sst7260/airflow_projects/project1/env/lib/python3.10/site-packages/airflow/models/taskinstance.py", line 767, in _execute_task
    result = _execute_callable(context=context, **execute_callable_kwargs)
  File "/home/sst7260/airflow_projects/project1/env/lib/python3.10/site-packages/airflow/models/taskinstance.py", line 733, in _execute_callable
    return ExecutionCallableRunner(
  File "/home/sst7260/airflow_projects/project1/env/lib/python3.10/site-packages/airflow/utils/operator_helpers.py", line 252, in run
    return self.func(*args, **kwargs)
  File "/home/sst7260/airflow_projects/project1/env/lib/python3.10/site-packages/airflow/models/baseoperator.py", line 406, in wrapper
    return func(self, *args, **kwargs)
  File "/home/sst7260/airflow_projects/project1/env/lib/python3.10/site-packages/airflow/operators/bash.py", line 249, in execute
    raise AirflowException(
airflow.exceptions.AirflowException: Bash command failed. The command returned a non-zero exit code 1.
[2024-09-10T12:01:01.486+0530] {local_task_job_runner.py:266} INFO - Task exited with return code 1
[2024-09-10T12:01:01.501+0530] {taskinstance.py:3900} INFO - 0 downstream tasks scheduled from follow-on schedule check
[2024-09-10T12:01:01.502+0530] {local_task_job_runner.py:245} INFO - ::endgroup::
