[2024-09-10T14:27:16.449+0530] {local_task_job_runner.py:123} INFO - ::group::Pre task execution logs
[2024-09-10T14:27:16.463+0530] {taskinstance.py:2612} INFO - Dependencies all met for dep_context=non-requeueable deps ti=<TaskInstance: beam_etl_dag.run_beam_pipeline manual__2024-09-10T08:54:43.145293+00:00 [queued]>
[2024-09-10T14:27:16.471+0530] {taskinstance.py:2612} INFO - Dependencies all met for dep_context=requeueable deps ti=<TaskInstance: beam_etl_dag.run_beam_pipeline manual__2024-09-10T08:54:43.145293+00:00 [queued]>
[2024-09-10T14:27:16.472+0530] {taskinstance.py:2865} INFO - Starting attempt 2 of 2
[2024-09-10T14:27:16.508+0530] {taskinstance.py:2888} INFO - Executing <Task(PythonOperator): run_beam_pipeline> on 2024-09-10 08:54:43.145293+00:00
[2024-09-10T14:27:16.516+0530] {standard_task_runner.py:72} INFO - Started process 179171 to run task
[2024-09-10T14:27:16.521+0530] {standard_task_runner.py:104} INFO - Running: ['airflow', 'tasks', 'run', 'beam_etl_dag', 'run_beam_pipeline', 'manual__2024-09-10T08:54:43.145293+00:00', '--job-id', '60', '--raw', '--subdir', 'DAGS_FOLDER/beam_etl_dag.py', '--cfg-path', '/tmp/tmpqmuqx17u']
[2024-09-10T14:27:16.522+0530] {standard_task_runner.py:105} INFO - Job 60: Subtask run_beam_pipeline
[2024-09-10T14:27:16.616+0530] {task_command.py:467} INFO - Running <TaskInstance: beam_etl_dag.run_beam_pipeline manual__2024-09-10T08:54:43.145293+00:00 [running]> on host PG0392KD.springernature.com
[2024-09-10T14:27:16.715+0530] {taskinstance.py:3131} INFO - Exporting env vars: AIRFLOW_CTX_DAG_OWNER='airflow_SS' AIRFLOW_CTX_DAG_ID='beam_etl_dag' AIRFLOW_CTX_TASK_ID='run_beam_pipeline' AIRFLOW_CTX_EXECUTION_DATE='2024-09-10T08:54:43.145293+00:00' AIRFLOW_CTX_TRY_NUMBER='2' AIRFLOW_CTX_DAG_RUN_ID='manual__2024-09-10T08:54:43.145293+00:00'
[2024-09-10T14:27:16.717+0530] {logging_mixin.py:190} INFO - Task instance is in running state
[2024-09-10T14:27:16.717+0530] {logging_mixin.py:190} INFO -  Previous state of the Task instance: queued
[2024-09-10T14:27:16.717+0530] {logging_mixin.py:190} INFO - Current task name:run_beam_pipeline state:running start_date:2024-09-10 08:57:16.464025+00:00
[2024-09-10T14:27:16.718+0530] {logging_mixin.py:190} INFO - Dag name:beam_etl_dag and current dag run status:running
[2024-09-10T14:27:16.718+0530] {taskinstance.py:731} INFO - ::endgroup::
[2024-09-10T14:27:16.724+0530] {pipeline.py:197} INFO - Missing pipeline option (runner). Executing pipeline using the default runner: DirectRunner.
[2024-09-10T14:27:19.750+0530] {_metadata.py:142} WARNING - Compute Engine Metadata server unavailable on attempt 1 of 3. Reason: timed out
[2024-09-10T14:27:23.685+0530] {_metadata.py:142} WARNING - Compute Engine Metadata server unavailable on attempt 2 of 3. Reason: timed out
[2024-09-10T14:27:28.752+0530] {_metadata.py:142} WARNING - Compute Engine Metadata server unavailable on attempt 3 of 3. Reason: timed out
[2024-09-10T14:27:28.753+0530] {_default.py:338} WARNING - Authentication failed using Compute Engine authentication due to unavailable metadata server.
[2024-09-10T14:27:28.754+0530] {retry.py:313} WARNING - Retry with exponential backoff: waiting for 1.989130433322722 seconds before retrying _get_credentials_with_retrys because we caught exception: google.auth.exceptions.DefaultCredentialsError: Your default credentials were not found. To set up Application Default Credentials, see https://cloud.google.com/docs/authentication/external/set-up-adc for more information.
 Traceback for above exception (most recent call last):
  File "/home/sst7260/airflow_projects/project1/env/lib/python3.10/site-packages/apache_beam/utils/retry.py", line 298, in wrapper
    return fun(*args, **kwargs)
  File "/home/sst7260/airflow_projects/project1/env/lib/python3.10/site-packages/apache_beam/internal/gcp/auth.py", line 175, in _get_credentials_with_retrys
    credentials, _ = google.auth.default(
  File "/home/sst7260/airflow_projects/project1/env/lib/python3.10/site-packages/google/auth/_default.py", line 691, in default
    raise exceptions.DefaultCredentialsError(_CLOUD_SDK_MISSING_CREDENTIALS)

[2024-09-10T14:27:33.750+0530] {_metadata.py:142} WARNING - Compute Engine Metadata server unavailable on attempt 1 of 3. Reason: timed out
[2024-09-10T14:27:37.676+0530] {_metadata.py:142} WARNING - Compute Engine Metadata server unavailable on attempt 2 of 3. Reason: timed out
[2024-09-10T14:27:42.698+0530] {_metadata.py:142} WARNING - Compute Engine Metadata server unavailable on attempt 3 of 3. Reason: timed out
[2024-09-10T14:27:42.699+0530] {_default.py:338} WARNING - Authentication failed using Compute Engine authentication due to unavailable metadata server.
[2024-09-10T14:27:42.699+0530] {retry.py:313} WARNING - Retry with exponential backoff: waiting for 3.4169721845182974 seconds before retrying _get_credentials_with_retrys because we caught exception: google.auth.exceptions.DefaultCredentialsError: Your default credentials were not found. To set up Application Default Credentials, see https://cloud.google.com/docs/authentication/external/set-up-adc for more information.
 Traceback for above exception (most recent call last):
  File "/home/sst7260/airflow_projects/project1/env/lib/python3.10/site-packages/apache_beam/utils/retry.py", line 298, in wrapper
    return fun(*args, **kwargs)
  File "/home/sst7260/airflow_projects/project1/env/lib/python3.10/site-packages/apache_beam/internal/gcp/auth.py", line 175, in _get_credentials_with_retrys
    credentials, _ = google.auth.default(
  File "/home/sst7260/airflow_projects/project1/env/lib/python3.10/site-packages/google/auth/_default.py", line 691, in default
    raise exceptions.DefaultCredentialsError(_CLOUD_SDK_MISSING_CREDENTIALS)

[2024-09-10T14:27:49.127+0530] {_metadata.py:142} WARNING - Compute Engine Metadata server unavailable on attempt 1 of 3. Reason: timed out
[2024-09-10T14:27:53.064+0530] {_metadata.py:142} WARNING - Compute Engine Metadata server unavailable on attempt 2 of 3. Reason: timed out
[2024-09-10T14:27:58.148+0530] {_metadata.py:142} WARNING - Compute Engine Metadata server unavailable on attempt 3 of 3. Reason: timed out
[2024-09-10T14:27:58.148+0530] {_default.py:338} WARNING - Authentication failed using Compute Engine authentication due to unavailable metadata server.
[2024-09-10T14:27:58.149+0530] {retry.py:313} WARNING - Retry with exponential backoff: waiting for 5.17037582361431 seconds before retrying _get_credentials_with_retrys because we caught exception: google.auth.exceptions.DefaultCredentialsError: Your default credentials were not found. To set up Application Default Credentials, see https://cloud.google.com/docs/authentication/external/set-up-adc for more information.
 Traceback for above exception (most recent call last):
  File "/home/sst7260/airflow_projects/project1/env/lib/python3.10/site-packages/apache_beam/utils/retry.py", line 298, in wrapper
    return fun(*args, **kwargs)
  File "/home/sst7260/airflow_projects/project1/env/lib/python3.10/site-packages/apache_beam/internal/gcp/auth.py", line 175, in _get_credentials_with_retrys
    credentials, _ = google.auth.default(
  File "/home/sst7260/airflow_projects/project1/env/lib/python3.10/site-packages/google/auth/_default.py", line 691, in default
    raise exceptions.DefaultCredentialsError(_CLOUD_SDK_MISSING_CREDENTIALS)

[2024-09-10T14:28:06.331+0530] {_metadata.py:142} WARNING - Compute Engine Metadata server unavailable on attempt 1 of 3. Reason: timed out
[2024-09-10T14:28:10.336+0530] {_metadata.py:142} WARNING - Compute Engine Metadata server unavailable on attempt 2 of 3. Reason: timed out
[2024-09-10T14:28:15.491+0530] {_metadata.py:142} WARNING - Compute Engine Metadata server unavailable on attempt 3 of 3. Reason: timed out
[2024-09-10T14:28:15.492+0530] {_default.py:338} WARNING - Authentication failed using Compute Engine authentication due to unavailable metadata server.
[2024-09-10T14:28:15.492+0530] {retry.py:313} WARNING - Retry with exponential backoff: waiting for 9.168349782492108 seconds before retrying _get_credentials_with_retrys because we caught exception: google.auth.exceptions.DefaultCredentialsError: Your default credentials were not found. To set up Application Default Credentials, see https://cloud.google.com/docs/authentication/external/set-up-adc for more information.
 Traceback for above exception (most recent call last):
  File "/home/sst7260/airflow_projects/project1/env/lib/python3.10/site-packages/apache_beam/utils/retry.py", line 298, in wrapper
    return fun(*args, **kwargs)
  File "/home/sst7260/airflow_projects/project1/env/lib/python3.10/site-packages/apache_beam/internal/gcp/auth.py", line 175, in _get_credentials_with_retrys
    credentials, _ = google.auth.default(
  File "/home/sst7260/airflow_projects/project1/env/lib/python3.10/site-packages/google/auth/_default.py", line 691, in default
    raise exceptions.DefaultCredentialsError(_CLOUD_SDK_MISSING_CREDENTIALS)

[2024-09-10T14:28:27.676+0530] {_metadata.py:142} WARNING - Compute Engine Metadata server unavailable on attempt 1 of 3. Reason: timed out
[2024-09-10T14:28:31.770+0530] {_metadata.py:142} WARNING - Compute Engine Metadata server unavailable on attempt 2 of 3. Reason: timed out
[2024-09-10T14:28:36.880+0530] {_metadata.py:142} WARNING - Compute Engine Metadata server unavailable on attempt 3 of 3. Reason: timed out
[2024-09-10T14:28:36.880+0530] {_default.py:338} WARNING - Authentication failed using Compute Engine authentication due to unavailable metadata server.
[2024-09-10T14:28:36.880+0530] {auth.py:165} WARNING - Unable to find default credentials to use: Your default credentials were not found. To set up Application Default Credentials, see https://cloud.google.com/docs/authentication/external/set-up-adc for more information.
Connecting anonymously. This is expected if no credentials are needed to access GCP resources.
[2024-09-10T14:28:37.426+0530] {requests.py:558} INFO - Refreshing credentials due to a 401 response. Attempt 1/2.
[2024-09-10T14:28:37.429+0530] {retry.py:313} WARNING - Retry with exponential backoff: waiting for 4.203900426820425 seconds before retrying _gcs_object because we caught exception: google.auth.exceptions.InvalidOperation: Anonymous credentials cannot be refreshed.
 Traceback for above exception (most recent call last):
  File "/home/sst7260/airflow_projects/project1/env/lib/python3.10/site-packages/apache_beam/utils/retry.py", line 298, in wrapper
    return fun(*args, **kwargs)
  File "/home/sst7260/airflow_projects/project1/env/lib/python3.10/site-packages/apache_beam/io/gcp/gcsio.py", line 462, in _gcs_object
    blob = bucket.get_blob(blob_name)
  File "/usr/lib/python3.10/contextlib.py", line 79, in inner
    return func(*args, **kwds)
  File "/home/sst7260/airflow_projects/project1/env/lib/python3.10/site-packages/google/cloud/storage/bucket.py", line 1283, in get_blob
    blob.reload(
  File "/home/sst7260/airflow_projects/project1/env/lib/python3.10/site-packages/google/cloud/storage/_helpers.py", line 300, in reload
    api_response = client._get_resource(
  File "/home/sst7260/airflow_projects/project1/env/lib/python3.10/site-packages/google/cloud/storage/client.py", line 464, in _get_resource
    return self._connection.api_request(
  File "/home/sst7260/airflow_projects/project1/env/lib/python3.10/site-packages/google/cloud/storage/_http.py", line 90, in api_request
    return call()
  File "/home/sst7260/airflow_projects/project1/env/lib/python3.10/site-packages/google/api_core/retry/retry_unary.py", line 293, in retry_wrapped_func
    return retry_target(
  File "/home/sst7260/airflow_projects/project1/env/lib/python3.10/site-packages/google/api_core/retry/retry_unary.py", line 153, in retry_target
    _retry_error_helper(
  File "/home/sst7260/airflow_projects/project1/env/lib/python3.10/site-packages/google/api_core/retry/retry_base.py", line 212, in _retry_error_helper
    raise final_exc from source_exc
  File "/home/sst7260/airflow_projects/project1/env/lib/python3.10/site-packages/google/api_core/retry/retry_unary.py", line 144, in retry_target
    result = target()
  File "/home/sst7260/airflow_projects/project1/env/lib/python3.10/site-packages/google/cloud/_http/__init__.py", line 482, in api_request
    response = self._make_request(
  File "/home/sst7260/airflow_projects/project1/env/lib/python3.10/site-packages/google/cloud/_http/__init__.py", line 341, in _make_request
    return self._do_request(
  File "/home/sst7260/airflow_projects/project1/env/lib/python3.10/site-packages/google/cloud/_http/__init__.py", line 379, in _do_request
    return self.http.request(
  File "/home/sst7260/airflow_projects/project1/env/lib/python3.10/site-packages/google/auth/transport/requests.py", line 574, in request
    self.credentials.refresh(auth_request)
  File "/home/sst7260/airflow_projects/project1/env/lib/python3.10/site-packages/google/auth/credentials.py", line 311, in refresh
    raise exceptions.InvalidOperation("Anonymous credentials cannot be refreshed.")

[2024-09-10T14:28:42.074+0530] {requests.py:558} INFO - Refreshing credentials due to a 401 response. Attempt 1/2.
[2024-09-10T14:28:42.075+0530] {retry.py:313} WARNING - Retry with exponential backoff: waiting for 9.327288095016883 seconds before retrying _gcs_object because we caught exception: google.auth.exceptions.InvalidOperation: Anonymous credentials cannot be refreshed.
 Traceback for above exception (most recent call last):
  File "/home/sst7260/airflow_projects/project1/env/lib/python3.10/site-packages/apache_beam/utils/retry.py", line 298, in wrapper
    return fun(*args, **kwargs)
  File "/home/sst7260/airflow_projects/project1/env/lib/python3.10/site-packages/apache_beam/io/gcp/gcsio.py", line 462, in _gcs_object
    blob = bucket.get_blob(blob_name)
  File "/usr/lib/python3.10/contextlib.py", line 79, in inner
    return func(*args, **kwds)
  File "/home/sst7260/airflow_projects/project1/env/lib/python3.10/site-packages/google/cloud/storage/bucket.py", line 1283, in get_blob
    blob.reload(
  File "/home/sst7260/airflow_projects/project1/env/lib/python3.10/site-packages/google/cloud/storage/_helpers.py", line 300, in reload
    api_response = client._get_resource(
  File "/home/sst7260/airflow_projects/project1/env/lib/python3.10/site-packages/google/cloud/storage/client.py", line 464, in _get_resource
    return self._connection.api_request(
  File "/home/sst7260/airflow_projects/project1/env/lib/python3.10/site-packages/google/cloud/storage/_http.py", line 90, in api_request
    return call()
  File "/home/sst7260/airflow_projects/project1/env/lib/python3.10/site-packages/google/api_core/retry/retry_unary.py", line 293, in retry_wrapped_func
    return retry_target(
  File "/home/sst7260/airflow_projects/project1/env/lib/python3.10/site-packages/google/api_core/retry/retry_unary.py", line 153, in retry_target
    _retry_error_helper(
  File "/home/sst7260/airflow_projects/project1/env/lib/python3.10/site-packages/google/api_core/retry/retry_base.py", line 212, in _retry_error_helper
    raise final_exc from source_exc
  File "/home/sst7260/airflow_projects/project1/env/lib/python3.10/site-packages/google/api_core/retry/retry_unary.py", line 144, in retry_target
    result = target()
  File "/home/sst7260/airflow_projects/project1/env/lib/python3.10/site-packages/google/cloud/_http/__init__.py", line 482, in api_request
    response = self._make_request(
  File "/home/sst7260/airflow_projects/project1/env/lib/python3.10/site-packages/google/cloud/_http/__init__.py", line 341, in _make_request
    return self._do_request(
  File "/home/sst7260/airflow_projects/project1/env/lib/python3.10/site-packages/google/cloud/_http/__init__.py", line 379, in _do_request
    return self.http.request(
  File "/home/sst7260/airflow_projects/project1/env/lib/python3.10/site-packages/google/auth/transport/requests.py", line 574, in request
    self.credentials.refresh(auth_request)
  File "/home/sst7260/airflow_projects/project1/env/lib/python3.10/site-packages/google/auth/credentials.py", line 311, in refresh
    raise exceptions.InvalidOperation("Anonymous credentials cannot be refreshed.")

[2024-09-10T14:28:51.797+0530] {requests.py:558} INFO - Refreshing credentials due to a 401 response. Attempt 1/2.
[2024-09-10T14:28:51.797+0530] {retry.py:313} WARNING - Retry with exponential backoff: waiting for 18.810020135197924 seconds before retrying _gcs_object because we caught exception: google.auth.exceptions.InvalidOperation: Anonymous credentials cannot be refreshed.
 Traceback for above exception (most recent call last):
  File "/home/sst7260/airflow_projects/project1/env/lib/python3.10/site-packages/apache_beam/utils/retry.py", line 298, in wrapper
    return fun(*args, **kwargs)
  File "/home/sst7260/airflow_projects/project1/env/lib/python3.10/site-packages/apache_beam/io/gcp/gcsio.py", line 462, in _gcs_object
    blob = bucket.get_blob(blob_name)
  File "/usr/lib/python3.10/contextlib.py", line 79, in inner
    return func(*args, **kwds)
  File "/home/sst7260/airflow_projects/project1/env/lib/python3.10/site-packages/google/cloud/storage/bucket.py", line 1283, in get_blob
    blob.reload(
  File "/home/sst7260/airflow_projects/project1/env/lib/python3.10/site-packages/google/cloud/storage/_helpers.py", line 300, in reload
    api_response = client._get_resource(
  File "/home/sst7260/airflow_projects/project1/env/lib/python3.10/site-packages/google/cloud/storage/client.py", line 464, in _get_resource
    return self._connection.api_request(
  File "/home/sst7260/airflow_projects/project1/env/lib/python3.10/site-packages/google/cloud/storage/_http.py", line 90, in api_request
    return call()
  File "/home/sst7260/airflow_projects/project1/env/lib/python3.10/site-packages/google/api_core/retry/retry_unary.py", line 293, in retry_wrapped_func
    return retry_target(
  File "/home/sst7260/airflow_projects/project1/env/lib/python3.10/site-packages/google/api_core/retry/retry_unary.py", line 153, in retry_target
    _retry_error_helper(
  File "/home/sst7260/airflow_projects/project1/env/lib/python3.10/site-packages/google/api_core/retry/retry_base.py", line 212, in _retry_error_helper
    raise final_exc from source_exc
  File "/home/sst7260/airflow_projects/project1/env/lib/python3.10/site-packages/google/api_core/retry/retry_unary.py", line 144, in retry_target
    result = target()
  File "/home/sst7260/airflow_projects/project1/env/lib/python3.10/site-packages/google/cloud/_http/__init__.py", line 482, in api_request
    response = self._make_request(
  File "/home/sst7260/airflow_projects/project1/env/lib/python3.10/site-packages/google/cloud/_http/__init__.py", line 341, in _make_request
    return self._do_request(
  File "/home/sst7260/airflow_projects/project1/env/lib/python3.10/site-packages/google/cloud/_http/__init__.py", line 379, in _do_request
    return self.http.request(
  File "/home/sst7260/airflow_projects/project1/env/lib/python3.10/site-packages/google/auth/transport/requests.py", line 574, in request
    self.credentials.refresh(auth_request)
  File "/home/sst7260/airflow_projects/project1/env/lib/python3.10/site-packages/google/auth/credentials.py", line 311, in refresh
    raise exceptions.InvalidOperation("Anonymous credentials cannot be refreshed.")

[2024-09-10T14:29:11.022+0530] {requests.py:558} INFO - Refreshing credentials due to a 401 response. Attempt 1/2.
[2024-09-10T14:29:11.023+0530] {retry.py:313} WARNING - Retry with exponential backoff: waiting for 20.429143949755755 seconds before retrying _gcs_object because we caught exception: google.auth.exceptions.InvalidOperation: Anonymous credentials cannot be refreshed.
 Traceback for above exception (most recent call last):
  File "/home/sst7260/airflow_projects/project1/env/lib/python3.10/site-packages/apache_beam/utils/retry.py", line 298, in wrapper
    return fun(*args, **kwargs)
  File "/home/sst7260/airflow_projects/project1/env/lib/python3.10/site-packages/apache_beam/io/gcp/gcsio.py", line 462, in _gcs_object
    blob = bucket.get_blob(blob_name)
  File "/usr/lib/python3.10/contextlib.py", line 79, in inner
    return func(*args, **kwds)
  File "/home/sst7260/airflow_projects/project1/env/lib/python3.10/site-packages/google/cloud/storage/bucket.py", line 1283, in get_blob
    blob.reload(
  File "/home/sst7260/airflow_projects/project1/env/lib/python3.10/site-packages/google/cloud/storage/_helpers.py", line 300, in reload
    api_response = client._get_resource(
  File "/home/sst7260/airflow_projects/project1/env/lib/python3.10/site-packages/google/cloud/storage/client.py", line 464, in _get_resource
    return self._connection.api_request(
  File "/home/sst7260/airflow_projects/project1/env/lib/python3.10/site-packages/google/cloud/storage/_http.py", line 90, in api_request
    return call()
  File "/home/sst7260/airflow_projects/project1/env/lib/python3.10/site-packages/google/api_core/retry/retry_unary.py", line 293, in retry_wrapped_func
    return retry_target(
  File "/home/sst7260/airflow_projects/project1/env/lib/python3.10/site-packages/google/api_core/retry/retry_unary.py", line 153, in retry_target
    _retry_error_helper(
  File "/home/sst7260/airflow_projects/project1/env/lib/python3.10/site-packages/google/api_core/retry/retry_base.py", line 212, in _retry_error_helper
    raise final_exc from source_exc
  File "/home/sst7260/airflow_projects/project1/env/lib/python3.10/site-packages/google/api_core/retry/retry_unary.py", line 144, in retry_target
    result = target()
  File "/home/sst7260/airflow_projects/project1/env/lib/python3.10/site-packages/google/cloud/_http/__init__.py", line 482, in api_request
    response = self._make_request(
  File "/home/sst7260/airflow_projects/project1/env/lib/python3.10/site-packages/google/cloud/_http/__init__.py", line 341, in _make_request
    return self._do_request(
  File "/home/sst7260/airflow_projects/project1/env/lib/python3.10/site-packages/google/cloud/_http/__init__.py", line 379, in _do_request
    return self.http.request(
  File "/home/sst7260/airflow_projects/project1/env/lib/python3.10/site-packages/google/auth/transport/requests.py", line 574, in request
    self.credentials.refresh(auth_request)
  File "/home/sst7260/airflow_projects/project1/env/lib/python3.10/site-packages/google/auth/credentials.py", line 311, in refresh
    raise exceptions.InvalidOperation("Anonymous credentials cannot be refreshed.")

[2024-09-10T14:29:31.871+0530] {requests.py:558} INFO - Refreshing credentials due to a 401 response. Attempt 1/2.
[2024-09-10T14:29:31.872+0530] {retry.py:313} WARNING - Retry with exponential backoff: waiting for 42.89391208668407 seconds before retrying _gcs_object because we caught exception: google.auth.exceptions.InvalidOperation: Anonymous credentials cannot be refreshed.
 Traceback for above exception (most recent call last):
  File "/home/sst7260/airflow_projects/project1/env/lib/python3.10/site-packages/apache_beam/utils/retry.py", line 298, in wrapper
    return fun(*args, **kwargs)
  File "/home/sst7260/airflow_projects/project1/env/lib/python3.10/site-packages/apache_beam/io/gcp/gcsio.py", line 462, in _gcs_object
    blob = bucket.get_blob(blob_name)
  File "/usr/lib/python3.10/contextlib.py", line 79, in inner
    return func(*args, **kwds)
  File "/home/sst7260/airflow_projects/project1/env/lib/python3.10/site-packages/google/cloud/storage/bucket.py", line 1283, in get_blob
    blob.reload(
  File "/home/sst7260/airflow_projects/project1/env/lib/python3.10/site-packages/google/cloud/storage/_helpers.py", line 300, in reload
    api_response = client._get_resource(
  File "/home/sst7260/airflow_projects/project1/env/lib/python3.10/site-packages/google/cloud/storage/client.py", line 464, in _get_resource
    return self._connection.api_request(
  File "/home/sst7260/airflow_projects/project1/env/lib/python3.10/site-packages/google/cloud/storage/_http.py", line 90, in api_request
    return call()
  File "/home/sst7260/airflow_projects/project1/env/lib/python3.10/site-packages/google/api_core/retry/retry_unary.py", line 293, in retry_wrapped_func
    return retry_target(
  File "/home/sst7260/airflow_projects/project1/env/lib/python3.10/site-packages/google/api_core/retry/retry_unary.py", line 153, in retry_target
    _retry_error_helper(
  File "/home/sst7260/airflow_projects/project1/env/lib/python3.10/site-packages/google/api_core/retry/retry_base.py", line 212, in _retry_error_helper
    raise final_exc from source_exc
  File "/home/sst7260/airflow_projects/project1/env/lib/python3.10/site-packages/google/api_core/retry/retry_unary.py", line 144, in retry_target
    result = target()
  File "/home/sst7260/airflow_projects/project1/env/lib/python3.10/site-packages/google/cloud/_http/__init__.py", line 482, in api_request
    response = self._make_request(
  File "/home/sst7260/airflow_projects/project1/env/lib/python3.10/site-packages/google/cloud/_http/__init__.py", line 341, in _make_request
    return self._do_request(
  File "/home/sst7260/airflow_projects/project1/env/lib/python3.10/site-packages/google/cloud/_http/__init__.py", line 379, in _do_request
    return self.http.request(
  File "/home/sst7260/airflow_projects/project1/env/lib/python3.10/site-packages/google/auth/transport/requests.py", line 574, in request
    self.credentials.refresh(auth_request)
  File "/home/sst7260/airflow_projects/project1/env/lib/python3.10/site-packages/google/auth/credentials.py", line 311, in refresh
    raise exceptions.InvalidOperation("Anonymous credentials cannot be refreshed.")

[2024-09-10T14:30:15.193+0530] {requests.py:558} INFO - Refreshing credentials due to a 401 response. Attempt 1/2.
[2024-09-10T14:30:15.194+0530] {retry.py:313} WARNING - Retry with exponential backoff: waiting for 97.03886692674622 seconds before retrying _gcs_object because we caught exception: google.auth.exceptions.InvalidOperation: Anonymous credentials cannot be refreshed.
 Traceback for above exception (most recent call last):
  File "/home/sst7260/airflow_projects/project1/env/lib/python3.10/site-packages/apache_beam/utils/retry.py", line 298, in wrapper
    return fun(*args, **kwargs)
  File "/home/sst7260/airflow_projects/project1/env/lib/python3.10/site-packages/apache_beam/io/gcp/gcsio.py", line 462, in _gcs_object
    blob = bucket.get_blob(blob_name)
  File "/usr/lib/python3.10/contextlib.py", line 79, in inner
    return func(*args, **kwds)
  File "/home/sst7260/airflow_projects/project1/env/lib/python3.10/site-packages/google/cloud/storage/bucket.py", line 1283, in get_blob
    blob.reload(
  File "/home/sst7260/airflow_projects/project1/env/lib/python3.10/site-packages/google/cloud/storage/_helpers.py", line 300, in reload
    api_response = client._get_resource(
  File "/home/sst7260/airflow_projects/project1/env/lib/python3.10/site-packages/google/cloud/storage/client.py", line 464, in _get_resource
    return self._connection.api_request(
  File "/home/sst7260/airflow_projects/project1/env/lib/python3.10/site-packages/google/cloud/storage/_http.py", line 90, in api_request
    return call()
  File "/home/sst7260/airflow_projects/project1/env/lib/python3.10/site-packages/google/api_core/retry/retry_unary.py", line 293, in retry_wrapped_func
    return retry_target(
  File "/home/sst7260/airflow_projects/project1/env/lib/python3.10/site-packages/google/api_core/retry/retry_unary.py", line 153, in retry_target
    _retry_error_helper(
  File "/home/sst7260/airflow_projects/project1/env/lib/python3.10/site-packages/google/api_core/retry/retry_base.py", line 212, in _retry_error_helper
    raise final_exc from source_exc
  File "/home/sst7260/airflow_projects/project1/env/lib/python3.10/site-packages/google/api_core/retry/retry_unary.py", line 144, in retry_target
    result = target()
  File "/home/sst7260/airflow_projects/project1/env/lib/python3.10/site-packages/google/cloud/_http/__init__.py", line 482, in api_request
    response = self._make_request(
  File "/home/sst7260/airflow_projects/project1/env/lib/python3.10/site-packages/google/cloud/_http/__init__.py", line 341, in _make_request
    return self._do_request(
  File "/home/sst7260/airflow_projects/project1/env/lib/python3.10/site-packages/google/cloud/_http/__init__.py", line 379, in _do_request
    return self.http.request(
  File "/home/sst7260/airflow_projects/project1/env/lib/python3.10/site-packages/google/auth/transport/requests.py", line 574, in request
    self.credentials.refresh(auth_request)
  File "/home/sst7260/airflow_projects/project1/env/lib/python3.10/site-packages/google/auth/credentials.py", line 311, in refresh
    raise exceptions.InvalidOperation("Anonymous credentials cannot be refreshed.")

[2024-09-10T14:31:52.659+0530] {requests.py:558} INFO - Refreshing credentials due to a 401 response. Attempt 1/2.
[2024-09-10T14:31:52.660+0530] {retry.py:313} WARNING - Retry with exponential backoff: waiting for 206.77108696625396 seconds before retrying _gcs_object because we caught exception: google.auth.exceptions.InvalidOperation: Anonymous credentials cannot be refreshed.
 Traceback for above exception (most recent call last):
  File "/home/sst7260/airflow_projects/project1/env/lib/python3.10/site-packages/apache_beam/utils/retry.py", line 298, in wrapper
    return fun(*args, **kwargs)
  File "/home/sst7260/airflow_projects/project1/env/lib/python3.10/site-packages/apache_beam/io/gcp/gcsio.py", line 462, in _gcs_object
    blob = bucket.get_blob(blob_name)
  File "/usr/lib/python3.10/contextlib.py", line 79, in inner
    return func(*args, **kwds)
  File "/home/sst7260/airflow_projects/project1/env/lib/python3.10/site-packages/google/cloud/storage/bucket.py", line 1283, in get_blob
    blob.reload(
  File "/home/sst7260/airflow_projects/project1/env/lib/python3.10/site-packages/google/cloud/storage/_helpers.py", line 300, in reload
    api_response = client._get_resource(
  File "/home/sst7260/airflow_projects/project1/env/lib/python3.10/site-packages/google/cloud/storage/client.py", line 464, in _get_resource
    return self._connection.api_request(
  File "/home/sst7260/airflow_projects/project1/env/lib/python3.10/site-packages/google/cloud/storage/_http.py", line 90, in api_request
    return call()
  File "/home/sst7260/airflow_projects/project1/env/lib/python3.10/site-packages/google/api_core/retry/retry_unary.py", line 293, in retry_wrapped_func
    return retry_target(
  File "/home/sst7260/airflow_projects/project1/env/lib/python3.10/site-packages/google/api_core/retry/retry_unary.py", line 153, in retry_target
    _retry_error_helper(
  File "/home/sst7260/airflow_projects/project1/env/lib/python3.10/site-packages/google/api_core/retry/retry_base.py", line 212, in _retry_error_helper
    raise final_exc from source_exc
  File "/home/sst7260/airflow_projects/project1/env/lib/python3.10/site-packages/google/api_core/retry/retry_unary.py", line 144, in retry_target
    result = target()
  File "/home/sst7260/airflow_projects/project1/env/lib/python3.10/site-packages/google/cloud/_http/__init__.py", line 482, in api_request
    response = self._make_request(
  File "/home/sst7260/airflow_projects/project1/env/lib/python3.10/site-packages/google/cloud/_http/__init__.py", line 341, in _make_request
    return self._do_request(
  File "/home/sst7260/airflow_projects/project1/env/lib/python3.10/site-packages/google/cloud/_http/__init__.py", line 379, in _do_request
    return self.http.request(
  File "/home/sst7260/airflow_projects/project1/env/lib/python3.10/site-packages/google/auth/transport/requests.py", line 574, in request
    self.credentials.refresh(auth_request)
  File "/home/sst7260/airflow_projects/project1/env/lib/python3.10/site-packages/google/auth/credentials.py", line 311, in refresh
    raise exceptions.InvalidOperation("Anonymous credentials cannot be refreshed.")

[2024-09-10T14:33:44.444+0530] {local_task_job_runner.py:346} WARNING - State of this instance has been externally set to failed. Terminating instance.
[2024-09-10T14:33:44.445+0530] {local_task_job_runner.py:245} INFO - ::endgroup::
[2024-09-10T14:33:44.447+0530] {process_utils.py:132} INFO - Sending Signals.SIGTERM to group 179171. PIDs of all processes in the group: [179171]
[2024-09-10T14:33:44.448+0530] {process_utils.py:87} INFO - Sending the signal Signals.SIGTERM to group 179171
[2024-09-10T14:33:44.448+0530] {taskinstance.py:3092} ERROR - Received SIGTERM. Terminating subprocesses.
[2024-09-10T14:33:44.479+0530] {taskinstance.py:340} INFO - ::group::Post task execution logs
[2024-09-10T14:33:44.501+0530] {process_utils.py:80} INFO - Process psutil.Process(pid=179171, status='terminated', exitcode=0, started='14:27:15') (179171) terminated with exit code 0
