[2024-09-10T14:38:48.787+0530] {local_task_job_runner.py:123} INFO - ::group::Pre task execution logs
[2024-09-10T14:38:48.799+0530] {taskinstance.py:2612} INFO - Dependencies all met for dep_context=non-requeueable deps ti=<TaskInstance: beam_etl_dag.run_beam_pipeline manual__2024-09-10T09:07:55.155593+00:00 [queued]>
[2024-09-10T14:38:48.803+0530] {taskinstance.py:2612} INFO - Dependencies all met for dep_context=requeueable deps ti=<TaskInstance: beam_etl_dag.run_beam_pipeline manual__2024-09-10T09:07:55.155593+00:00 [queued]>
[2024-09-10T14:38:48.803+0530] {taskinstance.py:2865} INFO - Starting attempt 2 of 2
[2024-09-10T14:38:48.830+0530] {taskinstance.py:2888} INFO - Executing <Task(PythonOperator): run_beam_pipeline> on 2024-09-10 09:07:55.155593+00:00
[2024-09-10T14:38:48.834+0530] {standard_task_runner.py:72} INFO - Started process 180440 to run task
[2024-09-10T14:38:48.840+0530] {standard_task_runner.py:104} INFO - Running: ['airflow', 'tasks', 'run', 'beam_etl_dag', 'run_beam_pipeline', 'manual__2024-09-10T09:07:55.155593+00:00', '--job-id', '62', '--raw', '--subdir', 'DAGS_FOLDER/beam_etl_dag.py', '--cfg-path', '/tmp/tmp4i98gzw9']
[2024-09-10T14:38:48.841+0530] {standard_task_runner.py:105} INFO - Job 62: Subtask run_beam_pipeline
[2024-09-10T14:38:48.906+0530] {task_command.py:467} INFO - Running <TaskInstance: beam_etl_dag.run_beam_pipeline manual__2024-09-10T09:07:55.155593+00:00 [running]> on host PG0392KD.springernature.com
[2024-09-10T14:38:48.962+0530] {taskinstance.py:3131} INFO - Exporting env vars: AIRFLOW_CTX_DAG_OWNER='airflow_SS' AIRFLOW_CTX_DAG_ID='beam_etl_dag' AIRFLOW_CTX_TASK_ID='run_beam_pipeline' AIRFLOW_CTX_EXECUTION_DATE='2024-09-10T09:07:55.155593+00:00' AIRFLOW_CTX_TRY_NUMBER='2' AIRFLOW_CTX_DAG_RUN_ID='manual__2024-09-10T09:07:55.155593+00:00'
[2024-09-10T14:38:48.964+0530] {logging_mixin.py:190} INFO - Task instance is in running state
[2024-09-10T14:38:48.964+0530] {logging_mixin.py:190} INFO -  Previous state of the Task instance: queued
[2024-09-10T14:38:48.964+0530] {logging_mixin.py:190} INFO - Current task name:run_beam_pipeline state:running start_date:2024-09-10 09:08:48.799610+00:00
[2024-09-10T14:38:48.964+0530] {logging_mixin.py:190} INFO - Dag name:beam_etl_dag and current dag run status:running
[2024-09-10T14:38:48.964+0530] {taskinstance.py:731} INFO - ::endgroup::
[2024-09-10T14:38:48.969+0530] {pipeline.py:197} INFO - Missing pipeline option (runner). Executing pipeline using the default runner: DirectRunner.
[2024-09-10T14:38:51.987+0530] {_metadata.py:142} WARNING - Compute Engine Metadata server unavailable on attempt 1 of 3. Reason: timed out
[2024-09-10T14:38:56.081+0530] {_metadata.py:142} WARNING - Compute Engine Metadata server unavailable on attempt 2 of 3. Reason: timed out
[2024-09-10T14:39:01.106+0530] {_metadata.py:142} WARNING - Compute Engine Metadata server unavailable on attempt 3 of 3. Reason: timed out
[2024-09-10T14:39:01.106+0530] {_default.py:338} WARNING - Authentication failed using Compute Engine authentication due to unavailable metadata server.
[2024-09-10T14:39:01.107+0530] {retry.py:313} WARNING - Retry with exponential backoff: waiting for 1.1323423067698957 seconds before retrying _get_credentials_with_retrys because we caught exception: google.auth.exceptions.DefaultCredentialsError: Your default credentials were not found. To set up Application Default Credentials, see https://cloud.google.com/docs/authentication/external/set-up-adc for more information.
 Traceback for above exception (most recent call last):
  File "/home/sst7260/airflow_projects/project1/env/lib/python3.10/site-packages/apache_beam/utils/retry.py", line 298, in wrapper
    return fun(*args, **kwargs)
  File "/home/sst7260/airflow_projects/project1/env/lib/python3.10/site-packages/apache_beam/internal/gcp/auth.py", line 175, in _get_credentials_with_retrys
    credentials, _ = google.auth.default(
  File "/home/sst7260/airflow_projects/project1/env/lib/python3.10/site-packages/google/auth/_default.py", line 691, in default
    raise exceptions.DefaultCredentialsError(_CLOUD_SDK_MISSING_CREDENTIALS)

[2024-09-10T14:39:05.246+0530] {_metadata.py:142} WARNING - Compute Engine Metadata server unavailable on attempt 1 of 3. Reason: timed out
[2024-09-10T14:39:09.341+0530] {_metadata.py:142} WARNING - Compute Engine Metadata server unavailable on attempt 2 of 3. Reason: timed out
[2024-09-10T14:39:14.420+0530] {_metadata.py:142} WARNING - Compute Engine Metadata server unavailable on attempt 3 of 3. Reason: timed out
[2024-09-10T14:39:14.421+0530] {_default.py:338} WARNING - Authentication failed using Compute Engine authentication due to unavailable metadata server.
[2024-09-10T14:39:14.421+0530] {retry.py:313} WARNING - Retry with exponential backoff: waiting for 2.2695938577093977 seconds before retrying _get_credentials_with_retrys because we caught exception: google.auth.exceptions.DefaultCredentialsError: Your default credentials were not found. To set up Application Default Credentials, see https://cloud.google.com/docs/authentication/external/set-up-adc for more information.
 Traceback for above exception (most recent call last):
  File "/home/sst7260/airflow_projects/project1/env/lib/python3.10/site-packages/apache_beam/utils/retry.py", line 298, in wrapper
    return fun(*args, **kwargs)
  File "/home/sst7260/airflow_projects/project1/env/lib/python3.10/site-packages/apache_beam/internal/gcp/auth.py", line 175, in _get_credentials_with_retrys
    credentials, _ = google.auth.default(
  File "/home/sst7260/airflow_projects/project1/env/lib/python3.10/site-packages/google/auth/_default.py", line 691, in default
    raise exceptions.DefaultCredentialsError(_CLOUD_SDK_MISSING_CREDENTIALS)

[2024-09-10T14:39:19.697+0530] {_metadata.py:142} WARNING - Compute Engine Metadata server unavailable on attempt 1 of 3. Reason: timed out
[2024-09-10T14:39:23.740+0530] {_metadata.py:142} WARNING - Compute Engine Metadata server unavailable on attempt 2 of 3. Reason: timed out
[2024-09-10T14:39:28.577+0530] {_metadata.py:142} WARNING - Compute Engine Metadata server unavailable on attempt 3 of 3. Reason: timed out
[2024-09-10T14:39:28.578+0530] {_default.py:338} WARNING - Authentication failed using Compute Engine authentication due to unavailable metadata server.
[2024-09-10T14:39:28.578+0530] {retry.py:313} WARNING - Retry with exponential backoff: waiting for 5.595319109915604 seconds before retrying _get_credentials_with_retrys because we caught exception: google.auth.exceptions.DefaultCredentialsError: Your default credentials were not found. To set up Application Default Credentials, see https://cloud.google.com/docs/authentication/external/set-up-adc for more information.
 Traceback for above exception (most recent call last):
  File "/home/sst7260/airflow_projects/project1/env/lib/python3.10/site-packages/apache_beam/utils/retry.py", line 298, in wrapper
    return fun(*args, **kwargs)
  File "/home/sst7260/airflow_projects/project1/env/lib/python3.10/site-packages/apache_beam/internal/gcp/auth.py", line 175, in _get_credentials_with_retrys
    credentials, _ = google.auth.default(
  File "/home/sst7260/airflow_projects/project1/env/lib/python3.10/site-packages/google/auth/_default.py", line 691, in default
    raise exceptions.DefaultCredentialsError(_CLOUD_SDK_MISSING_CREDENTIALS)

[2024-09-10T14:39:37.184+0530] {_metadata.py:142} WARNING - Compute Engine Metadata server unavailable on attempt 1 of 3. Reason: timed out
[2024-09-10T14:39:41.170+0530] {_metadata.py:142} WARNING - Compute Engine Metadata server unavailable on attempt 2 of 3. Reason: timed out
[2024-09-10T14:39:46.337+0530] {_metadata.py:142} WARNING - Compute Engine Metadata server unavailable on attempt 3 of 3. Reason: timed out
[2024-09-10T14:39:46.337+0530] {_default.py:338} WARNING - Authentication failed using Compute Engine authentication due to unavailable metadata server.
[2024-09-10T14:39:46.338+0530] {retry.py:313} WARNING - Retry with exponential backoff: waiting for 8.041412274165046 seconds before retrying _get_credentials_with_retrys because we caught exception: google.auth.exceptions.DefaultCredentialsError: Your default credentials were not found. To set up Application Default Credentials, see https://cloud.google.com/docs/authentication/external/set-up-adc for more information.
 Traceback for above exception (most recent call last):
  File "/home/sst7260/airflow_projects/project1/env/lib/python3.10/site-packages/apache_beam/utils/retry.py", line 298, in wrapper
    return fun(*args, **kwargs)
  File "/home/sst7260/airflow_projects/project1/env/lib/python3.10/site-packages/apache_beam/internal/gcp/auth.py", line 175, in _get_credentials_with_retrys
    credentials, _ = google.auth.default(
  File "/home/sst7260/airflow_projects/project1/env/lib/python3.10/site-packages/google/auth/_default.py", line 691, in default
    raise exceptions.DefaultCredentialsError(_CLOUD_SDK_MISSING_CREDENTIALS)

[2024-09-10T14:39:57.392+0530] {_metadata.py:142} WARNING - Compute Engine Metadata server unavailable on attempt 1 of 3. Reason: timed out
[2024-09-10T14:40:01.394+0530] {_metadata.py:142} WARNING - Compute Engine Metadata server unavailable on attempt 2 of 3. Reason: timed out
[2024-09-10T14:40:06.327+0530] {_metadata.py:142} WARNING - Compute Engine Metadata server unavailable on attempt 3 of 3. Reason: timed out
[2024-09-10T14:40:06.328+0530] {_default.py:338} WARNING - Authentication failed using Compute Engine authentication due to unavailable metadata server.
[2024-09-10T14:40:06.328+0530] {auth.py:165} WARNING - Unable to find default credentials to use: Your default credentials were not found. To set up Application Default Credentials, see https://cloud.google.com/docs/authentication/external/set-up-adc for more information.
Connecting anonymously. This is expected if no credentials are needed to access GCP resources.
[2024-09-10T14:40:08.628+0530] {requests.py:558} INFO - Refreshing credentials due to a 401 response. Attempt 1/2.
[2024-09-10T14:40:08.630+0530] {retry.py:313} WARNING - Retry with exponential backoff: waiting for 3.4516850333793867 seconds before retrying _gcs_object because we caught exception: google.auth.exceptions.InvalidOperation: Anonymous credentials cannot be refreshed.
 Traceback for above exception (most recent call last):
  File "/home/sst7260/airflow_projects/project1/env/lib/python3.10/site-packages/apache_beam/utils/retry.py", line 298, in wrapper
    return fun(*args, **kwargs)
  File "/home/sst7260/airflow_projects/project1/env/lib/python3.10/site-packages/apache_beam/io/gcp/gcsio.py", line 462, in _gcs_object
    blob = bucket.get_blob(blob_name)
  File "/usr/lib/python3.10/contextlib.py", line 79, in inner
    return func(*args, **kwds)
  File "/home/sst7260/airflow_projects/project1/env/lib/python3.10/site-packages/google/cloud/storage/bucket.py", line 1283, in get_blob
    blob.reload(
  File "/home/sst7260/airflow_projects/project1/env/lib/python3.10/site-packages/google/cloud/storage/_helpers.py", line 300, in reload
    api_response = client._get_resource(
  File "/home/sst7260/airflow_projects/project1/env/lib/python3.10/site-packages/google/cloud/storage/client.py", line 464, in _get_resource
    return self._connection.api_request(
  File "/home/sst7260/airflow_projects/project1/env/lib/python3.10/site-packages/google/cloud/storage/_http.py", line 90, in api_request
    return call()
  File "/home/sst7260/airflow_projects/project1/env/lib/python3.10/site-packages/google/api_core/retry/retry_unary.py", line 293, in retry_wrapped_func
    return retry_target(
  File "/home/sst7260/airflow_projects/project1/env/lib/python3.10/site-packages/google/api_core/retry/retry_unary.py", line 153, in retry_target
    _retry_error_helper(
  File "/home/sst7260/airflow_projects/project1/env/lib/python3.10/site-packages/google/api_core/retry/retry_base.py", line 212, in _retry_error_helper
    raise final_exc from source_exc
  File "/home/sst7260/airflow_projects/project1/env/lib/python3.10/site-packages/google/api_core/retry/retry_unary.py", line 144, in retry_target
    result = target()
  File "/home/sst7260/airflow_projects/project1/env/lib/python3.10/site-packages/google/cloud/_http/__init__.py", line 482, in api_request
    response = self._make_request(
  File "/home/sst7260/airflow_projects/project1/env/lib/python3.10/site-packages/google/cloud/_http/__init__.py", line 341, in _make_request
    return self._do_request(
  File "/home/sst7260/airflow_projects/project1/env/lib/python3.10/site-packages/google/cloud/_http/__init__.py", line 379, in _do_request
    return self.http.request(
  File "/home/sst7260/airflow_projects/project1/env/lib/python3.10/site-packages/google/auth/transport/requests.py", line 574, in request
    self.credentials.refresh(auth_request)
  File "/home/sst7260/airflow_projects/project1/env/lib/python3.10/site-packages/google/auth/credentials.py", line 311, in refresh
    raise exceptions.InvalidOperation("Anonymous credentials cannot be refreshed.")

[2024-09-10T14:40:12.477+0530] {requests.py:558} INFO - Refreshing credentials due to a 401 response. Attempt 1/2.
[2024-09-10T14:40:12.477+0530] {retry.py:313} WARNING - Retry with exponential backoff: waiting for 9.05106539483316 seconds before retrying _gcs_object because we caught exception: google.auth.exceptions.InvalidOperation: Anonymous credentials cannot be refreshed.
 Traceback for above exception (most recent call last):
  File "/home/sst7260/airflow_projects/project1/env/lib/python3.10/site-packages/apache_beam/utils/retry.py", line 298, in wrapper
    return fun(*args, **kwargs)
  File "/home/sst7260/airflow_projects/project1/env/lib/python3.10/site-packages/apache_beam/io/gcp/gcsio.py", line 462, in _gcs_object
    blob = bucket.get_blob(blob_name)
  File "/usr/lib/python3.10/contextlib.py", line 79, in inner
    return func(*args, **kwds)
  File "/home/sst7260/airflow_projects/project1/env/lib/python3.10/site-packages/google/cloud/storage/bucket.py", line 1283, in get_blob
    blob.reload(
  File "/home/sst7260/airflow_projects/project1/env/lib/python3.10/site-packages/google/cloud/storage/_helpers.py", line 300, in reload
    api_response = client._get_resource(
  File "/home/sst7260/airflow_projects/project1/env/lib/python3.10/site-packages/google/cloud/storage/client.py", line 464, in _get_resource
    return self._connection.api_request(
  File "/home/sst7260/airflow_projects/project1/env/lib/python3.10/site-packages/google/cloud/storage/_http.py", line 90, in api_request
    return call()
  File "/home/sst7260/airflow_projects/project1/env/lib/python3.10/site-packages/google/api_core/retry/retry_unary.py", line 293, in retry_wrapped_func
    return retry_target(
  File "/home/sst7260/airflow_projects/project1/env/lib/python3.10/site-packages/google/api_core/retry/retry_unary.py", line 153, in retry_target
    _retry_error_helper(
  File "/home/sst7260/airflow_projects/project1/env/lib/python3.10/site-packages/google/api_core/retry/retry_base.py", line 212, in _retry_error_helper
    raise final_exc from source_exc
  File "/home/sst7260/airflow_projects/project1/env/lib/python3.10/site-packages/google/api_core/retry/retry_unary.py", line 144, in retry_target
    result = target()
  File "/home/sst7260/airflow_projects/project1/env/lib/python3.10/site-packages/google/cloud/_http/__init__.py", line 482, in api_request
    response = self._make_request(
  File "/home/sst7260/airflow_projects/project1/env/lib/python3.10/site-packages/google/cloud/_http/__init__.py", line 341, in _make_request
    return self._do_request(
  File "/home/sst7260/airflow_projects/project1/env/lib/python3.10/site-packages/google/cloud/_http/__init__.py", line 379, in _do_request
    return self.http.request(
  File "/home/sst7260/airflow_projects/project1/env/lib/python3.10/site-packages/google/auth/transport/requests.py", line 574, in request
    self.credentials.refresh(auth_request)
  File "/home/sst7260/airflow_projects/project1/env/lib/python3.10/site-packages/google/auth/credentials.py", line 311, in refresh
    raise exceptions.InvalidOperation("Anonymous credentials cannot be refreshed.")

[2024-09-10T14:40:21.929+0530] {requests.py:558} INFO - Refreshing credentials due to a 401 response. Attempt 1/2.
[2024-09-10T14:40:21.930+0530] {retry.py:313} WARNING - Retry with exponential backoff: waiting for 19.443703253850114 seconds before retrying _gcs_object because we caught exception: google.auth.exceptions.InvalidOperation: Anonymous credentials cannot be refreshed.
 Traceback for above exception (most recent call last):
  File "/home/sst7260/airflow_projects/project1/env/lib/python3.10/site-packages/apache_beam/utils/retry.py", line 298, in wrapper
    return fun(*args, **kwargs)
  File "/home/sst7260/airflow_projects/project1/env/lib/python3.10/site-packages/apache_beam/io/gcp/gcsio.py", line 462, in _gcs_object
    blob = bucket.get_blob(blob_name)
  File "/usr/lib/python3.10/contextlib.py", line 79, in inner
    return func(*args, **kwds)
  File "/home/sst7260/airflow_projects/project1/env/lib/python3.10/site-packages/google/cloud/storage/bucket.py", line 1283, in get_blob
    blob.reload(
  File "/home/sst7260/airflow_projects/project1/env/lib/python3.10/site-packages/google/cloud/storage/_helpers.py", line 300, in reload
    api_response = client._get_resource(
  File "/home/sst7260/airflow_projects/project1/env/lib/python3.10/site-packages/google/cloud/storage/client.py", line 464, in _get_resource
    return self._connection.api_request(
  File "/home/sst7260/airflow_projects/project1/env/lib/python3.10/site-packages/google/cloud/storage/_http.py", line 90, in api_request
    return call()
  File "/home/sst7260/airflow_projects/project1/env/lib/python3.10/site-packages/google/api_core/retry/retry_unary.py", line 293, in retry_wrapped_func
    return retry_target(
  File "/home/sst7260/airflow_projects/project1/env/lib/python3.10/site-packages/google/api_core/retry/retry_unary.py", line 153, in retry_target
    _retry_error_helper(
  File "/home/sst7260/airflow_projects/project1/env/lib/python3.10/site-packages/google/api_core/retry/retry_base.py", line 212, in _retry_error_helper
    raise final_exc from source_exc
  File "/home/sst7260/airflow_projects/project1/env/lib/python3.10/site-packages/google/api_core/retry/retry_unary.py", line 144, in retry_target
    result = target()
  File "/home/sst7260/airflow_projects/project1/env/lib/python3.10/site-packages/google/cloud/_http/__init__.py", line 482, in api_request
    response = self._make_request(
  File "/home/sst7260/airflow_projects/project1/env/lib/python3.10/site-packages/google/cloud/_http/__init__.py", line 341, in _make_request
    return self._do_request(
  File "/home/sst7260/airflow_projects/project1/env/lib/python3.10/site-packages/google/cloud/_http/__init__.py", line 379, in _do_request
    return self.http.request(
  File "/home/sst7260/airflow_projects/project1/env/lib/python3.10/site-packages/google/auth/transport/requests.py", line 574, in request
    self.credentials.refresh(auth_request)
  File "/home/sst7260/airflow_projects/project1/env/lib/python3.10/site-packages/google/auth/credentials.py", line 311, in refresh
    raise exceptions.InvalidOperation("Anonymous credentials cannot be refreshed.")

[2024-09-10T14:40:41.786+0530] {requests.py:558} INFO - Refreshing credentials due to a 401 response. Attempt 1/2.
[2024-09-10T14:40:41.786+0530] {retry.py:313} WARNING - Retry with exponential backoff: waiting for 27.980113300326337 seconds before retrying _gcs_object because we caught exception: google.auth.exceptions.InvalidOperation: Anonymous credentials cannot be refreshed.
 Traceback for above exception (most recent call last):
  File "/home/sst7260/airflow_projects/project1/env/lib/python3.10/site-packages/apache_beam/utils/retry.py", line 298, in wrapper
    return fun(*args, **kwargs)
  File "/home/sst7260/airflow_projects/project1/env/lib/python3.10/site-packages/apache_beam/io/gcp/gcsio.py", line 462, in _gcs_object
    blob = bucket.get_blob(blob_name)
  File "/usr/lib/python3.10/contextlib.py", line 79, in inner
    return func(*args, **kwds)
  File "/home/sst7260/airflow_projects/project1/env/lib/python3.10/site-packages/google/cloud/storage/bucket.py", line 1283, in get_blob
    blob.reload(
  File "/home/sst7260/airflow_projects/project1/env/lib/python3.10/site-packages/google/cloud/storage/_helpers.py", line 300, in reload
    api_response = client._get_resource(
  File "/home/sst7260/airflow_projects/project1/env/lib/python3.10/site-packages/google/cloud/storage/client.py", line 464, in _get_resource
    return self._connection.api_request(
  File "/home/sst7260/airflow_projects/project1/env/lib/python3.10/site-packages/google/cloud/storage/_http.py", line 90, in api_request
    return call()
  File "/home/sst7260/airflow_projects/project1/env/lib/python3.10/site-packages/google/api_core/retry/retry_unary.py", line 293, in retry_wrapped_func
    return retry_target(
  File "/home/sst7260/airflow_projects/project1/env/lib/python3.10/site-packages/google/api_core/retry/retry_unary.py", line 153, in retry_target
    _retry_error_helper(
  File "/home/sst7260/airflow_projects/project1/env/lib/python3.10/site-packages/google/api_core/retry/retry_base.py", line 212, in _retry_error_helper
    raise final_exc from source_exc
  File "/home/sst7260/airflow_projects/project1/env/lib/python3.10/site-packages/google/api_core/retry/retry_unary.py", line 144, in retry_target
    result = target()
  File "/home/sst7260/airflow_projects/project1/env/lib/python3.10/site-packages/google/cloud/_http/__init__.py", line 482, in api_request
    response = self._make_request(
  File "/home/sst7260/airflow_projects/project1/env/lib/python3.10/site-packages/google/cloud/_http/__init__.py", line 341, in _make_request
    return self._do_request(
  File "/home/sst7260/airflow_projects/project1/env/lib/python3.10/site-packages/google/cloud/_http/__init__.py", line 379, in _do_request
    return self.http.request(
  File "/home/sst7260/airflow_projects/project1/env/lib/python3.10/site-packages/google/auth/transport/requests.py", line 574, in request
    self.credentials.refresh(auth_request)
  File "/home/sst7260/airflow_projects/project1/env/lib/python3.10/site-packages/google/auth/credentials.py", line 311, in refresh
    raise exceptions.InvalidOperation("Anonymous credentials cannot be refreshed.")

[2024-09-10T14:41:10.182+0530] {requests.py:558} INFO - Refreshing credentials due to a 401 response. Attempt 1/2.
[2024-09-10T14:41:10.182+0530] {retry.py:313} WARNING - Retry with exponential backoff: waiting for 54.9447320385171 seconds before retrying _gcs_object because we caught exception: google.auth.exceptions.InvalidOperation: Anonymous credentials cannot be refreshed.
 Traceback for above exception (most recent call last):
  File "/home/sst7260/airflow_projects/project1/env/lib/python3.10/site-packages/apache_beam/utils/retry.py", line 298, in wrapper
    return fun(*args, **kwargs)
  File "/home/sst7260/airflow_projects/project1/env/lib/python3.10/site-packages/apache_beam/io/gcp/gcsio.py", line 462, in _gcs_object
    blob = bucket.get_blob(blob_name)
  File "/usr/lib/python3.10/contextlib.py", line 79, in inner
    return func(*args, **kwds)
  File "/home/sst7260/airflow_projects/project1/env/lib/python3.10/site-packages/google/cloud/storage/bucket.py", line 1283, in get_blob
    blob.reload(
  File "/home/sst7260/airflow_projects/project1/env/lib/python3.10/site-packages/google/cloud/storage/_helpers.py", line 300, in reload
    api_response = client._get_resource(
  File "/home/sst7260/airflow_projects/project1/env/lib/python3.10/site-packages/google/cloud/storage/client.py", line 464, in _get_resource
    return self._connection.api_request(
  File "/home/sst7260/airflow_projects/project1/env/lib/python3.10/site-packages/google/cloud/storage/_http.py", line 90, in api_request
    return call()
  File "/home/sst7260/airflow_projects/project1/env/lib/python3.10/site-packages/google/api_core/retry/retry_unary.py", line 293, in retry_wrapped_func
    return retry_target(
  File "/home/sst7260/airflow_projects/project1/env/lib/python3.10/site-packages/google/api_core/retry/retry_unary.py", line 153, in retry_target
    _retry_error_helper(
  File "/home/sst7260/airflow_projects/project1/env/lib/python3.10/site-packages/google/api_core/retry/retry_base.py", line 212, in _retry_error_helper
    raise final_exc from source_exc
  File "/home/sst7260/airflow_projects/project1/env/lib/python3.10/site-packages/google/api_core/retry/retry_unary.py", line 144, in retry_target
    result = target()
  File "/home/sst7260/airflow_projects/project1/env/lib/python3.10/site-packages/google/cloud/_http/__init__.py", line 482, in api_request
    response = self._make_request(
  File "/home/sst7260/airflow_projects/project1/env/lib/python3.10/site-packages/google/cloud/_http/__init__.py", line 341, in _make_request
    return self._do_request(
  File "/home/sst7260/airflow_projects/project1/env/lib/python3.10/site-packages/google/cloud/_http/__init__.py", line 379, in _do_request
    return self.http.request(
  File "/home/sst7260/airflow_projects/project1/env/lib/python3.10/site-packages/google/auth/transport/requests.py", line 574, in request
    self.credentials.refresh(auth_request)
  File "/home/sst7260/airflow_projects/project1/env/lib/python3.10/site-packages/google/auth/credentials.py", line 311, in refresh
    raise exceptions.InvalidOperation("Anonymous credentials cannot be refreshed.")

[2024-09-10T14:42:05.587+0530] {requests.py:558} INFO - Refreshing credentials due to a 401 response. Attempt 1/2.
[2024-09-10T14:42:05.587+0530] {retry.py:313} WARNING - Retry with exponential backoff: waiting for 122.06098045890293 seconds before retrying _gcs_object because we caught exception: google.auth.exceptions.InvalidOperation: Anonymous credentials cannot be refreshed.
 Traceback for above exception (most recent call last):
  File "/home/sst7260/airflow_projects/project1/env/lib/python3.10/site-packages/apache_beam/utils/retry.py", line 298, in wrapper
    return fun(*args, **kwargs)
  File "/home/sst7260/airflow_projects/project1/env/lib/python3.10/site-packages/apache_beam/io/gcp/gcsio.py", line 462, in _gcs_object
    blob = bucket.get_blob(blob_name)
  File "/usr/lib/python3.10/contextlib.py", line 79, in inner
    return func(*args, **kwds)
  File "/home/sst7260/airflow_projects/project1/env/lib/python3.10/site-packages/google/cloud/storage/bucket.py", line 1283, in get_blob
    blob.reload(
  File "/home/sst7260/airflow_projects/project1/env/lib/python3.10/site-packages/google/cloud/storage/_helpers.py", line 300, in reload
    api_response = client._get_resource(
  File "/home/sst7260/airflow_projects/project1/env/lib/python3.10/site-packages/google/cloud/storage/client.py", line 464, in _get_resource
    return self._connection.api_request(
  File "/home/sst7260/airflow_projects/project1/env/lib/python3.10/site-packages/google/cloud/storage/_http.py", line 90, in api_request
    return call()
  File "/home/sst7260/airflow_projects/project1/env/lib/python3.10/site-packages/google/api_core/retry/retry_unary.py", line 293, in retry_wrapped_func
    return retry_target(
  File "/home/sst7260/airflow_projects/project1/env/lib/python3.10/site-packages/google/api_core/retry/retry_unary.py", line 153, in retry_target
    _retry_error_helper(
  File "/home/sst7260/airflow_projects/project1/env/lib/python3.10/site-packages/google/api_core/retry/retry_base.py", line 212, in _retry_error_helper
    raise final_exc from source_exc
  File "/home/sst7260/airflow_projects/project1/env/lib/python3.10/site-packages/google/api_core/retry/retry_unary.py", line 144, in retry_target
    result = target()
  File "/home/sst7260/airflow_projects/project1/env/lib/python3.10/site-packages/google/cloud/_http/__init__.py", line 482, in api_request
    response = self._make_request(
  File "/home/sst7260/airflow_projects/project1/env/lib/python3.10/site-packages/google/cloud/_http/__init__.py", line 341, in _make_request
    return self._do_request(
  File "/home/sst7260/airflow_projects/project1/env/lib/python3.10/site-packages/google/cloud/_http/__init__.py", line 379, in _do_request
    return self.http.request(
  File "/home/sst7260/airflow_projects/project1/env/lib/python3.10/site-packages/google/auth/transport/requests.py", line 574, in request
    self.credentials.refresh(auth_request)
  File "/home/sst7260/airflow_projects/project1/env/lib/python3.10/site-packages/google/auth/credentials.py", line 311, in refresh
    raise exceptions.InvalidOperation("Anonymous credentials cannot be refreshed.")

[2024-09-10T14:44:08.148+0530] {requests.py:558} INFO - Refreshing credentials due to a 401 response. Attempt 1/2.
[2024-09-10T14:44:08.149+0530] {retry.py:313} WARNING - Retry with exponential backoff: waiting for 246.1745771131844 seconds before retrying _gcs_object because we caught exception: google.auth.exceptions.InvalidOperation: Anonymous credentials cannot be refreshed.
 Traceback for above exception (most recent call last):
  File "/home/sst7260/airflow_projects/project1/env/lib/python3.10/site-packages/apache_beam/utils/retry.py", line 298, in wrapper
    return fun(*args, **kwargs)
  File "/home/sst7260/airflow_projects/project1/env/lib/python3.10/site-packages/apache_beam/io/gcp/gcsio.py", line 462, in _gcs_object
    blob = bucket.get_blob(blob_name)
  File "/usr/lib/python3.10/contextlib.py", line 79, in inner
    return func(*args, **kwds)
  File "/home/sst7260/airflow_projects/project1/env/lib/python3.10/site-packages/google/cloud/storage/bucket.py", line 1283, in get_blob
    blob.reload(
  File "/home/sst7260/airflow_projects/project1/env/lib/python3.10/site-packages/google/cloud/storage/_helpers.py", line 300, in reload
    api_response = client._get_resource(
  File "/home/sst7260/airflow_projects/project1/env/lib/python3.10/site-packages/google/cloud/storage/client.py", line 464, in _get_resource
    return self._connection.api_request(
  File "/home/sst7260/airflow_projects/project1/env/lib/python3.10/site-packages/google/cloud/storage/_http.py", line 90, in api_request
    return call()
  File "/home/sst7260/airflow_projects/project1/env/lib/python3.10/site-packages/google/api_core/retry/retry_unary.py", line 293, in retry_wrapped_func
    return retry_target(
  File "/home/sst7260/airflow_projects/project1/env/lib/python3.10/site-packages/google/api_core/retry/retry_unary.py", line 153, in retry_target
    _retry_error_helper(
  File "/home/sst7260/airflow_projects/project1/env/lib/python3.10/site-packages/google/api_core/retry/retry_base.py", line 212, in _retry_error_helper
    raise final_exc from source_exc
  File "/home/sst7260/airflow_projects/project1/env/lib/python3.10/site-packages/google/api_core/retry/retry_unary.py", line 144, in retry_target
    result = target()
  File "/home/sst7260/airflow_projects/project1/env/lib/python3.10/site-packages/google/cloud/_http/__init__.py", line 482, in api_request
    response = self._make_request(
  File "/home/sst7260/airflow_projects/project1/env/lib/python3.10/site-packages/google/cloud/_http/__init__.py", line 341, in _make_request
    return self._do_request(
  File "/home/sst7260/airflow_projects/project1/env/lib/python3.10/site-packages/google/cloud/_http/__init__.py", line 379, in _do_request
    return self.http.request(
  File "/home/sst7260/airflow_projects/project1/env/lib/python3.10/site-packages/google/auth/transport/requests.py", line 574, in request
    self.credentials.refresh(auth_request)
  File "/home/sst7260/airflow_projects/project1/env/lib/python3.10/site-packages/google/auth/credentials.py", line 311, in refresh
    raise exceptions.InvalidOperation("Anonymous credentials cannot be refreshed.")

[2024-09-10T14:46:21.773+0530] {local_task_job_runner.py:346} WARNING - State of this instance has been externally set to failed. Terminating instance.
[2024-09-10T14:46:21.774+0530] {local_task_job_runner.py:245} INFO - ::endgroup::
[2024-09-10T14:46:21.775+0530] {process_utils.py:132} INFO - Sending Signals.SIGTERM to group 180440. PIDs of all processes in the group: [180440]
[2024-09-10T14:46:21.775+0530] {process_utils.py:87} INFO - Sending the signal Signals.SIGTERM to group 180440
[2024-09-10T14:46:21.776+0530] {taskinstance.py:3092} ERROR - Received SIGTERM. Terminating subprocesses.
[2024-09-10T14:46:21.805+0530] {taskinstance.py:340} INFO - ::group::Post task execution logs
[2024-09-10T14:46:21.828+0530] {process_utils.py:80} INFO - Process psutil.Process(pid=180440, status='terminated', exitcode=0, started='14:38:47') (180440) terminated with exit code 0
