[2024-09-10T15:13:07.529+0530] {local_task_job_runner.py:123} INFO - ::group::Pre task execution logs
[2024-09-10T15:13:07.537+0530] {taskinstance.py:2612} INFO - Dependencies all met for dep_context=non-requeueable deps ti=<TaskInstance: beam_etl_dag_with_credentials.run_beam_pipeline manual__2024-09-10T09:43:00.310170+00:00 [queued]>
[2024-09-10T15:13:07.545+0530] {taskinstance.py:2612} INFO - Dependencies all met for dep_context=requeueable deps ti=<TaskInstance: beam_etl_dag_with_credentials.run_beam_pipeline manual__2024-09-10T09:43:00.310170+00:00 [queued]>
[2024-09-10T15:13:07.545+0530] {taskinstance.py:2865} INFO - Starting attempt 1 of 2
[2024-09-10T15:13:07.580+0530] {taskinstance.py:2888} INFO - Executing <Task(PythonOperator): run_beam_pipeline> on 2024-09-10 09:43:00.310170+00:00
[2024-09-10T15:13:07.589+0530] {standard_task_runner.py:72} INFO - Started process 186775 to run task
[2024-09-10T15:13:07.594+0530] {standard_task_runner.py:104} INFO - Running: ['airflow', 'tasks', 'run', 'beam_etl_dag_with_credentials', 'run_beam_pipeline', 'manual__2024-09-10T09:43:00.310170+00:00', '--job-id', '64', '--raw', '--subdir', 'DAGS_FOLDER/beam_etl_dag.py', '--cfg-path', '/tmp/tmp1epmcvps']
[2024-09-10T15:13:07.595+0530] {standard_task_runner.py:105} INFO - Job 64: Subtask run_beam_pipeline
[2024-09-10T15:13:07.670+0530] {task_command.py:467} INFO - Running <TaskInstance: beam_etl_dag_with_credentials.run_beam_pipeline manual__2024-09-10T09:43:00.310170+00:00 [running]> on host PG0392KD.springernature.com
[2024-09-10T15:13:07.756+0530] {taskinstance.py:3131} INFO - Exporting env vars: AIRFLOW_CTX_DAG_OWNER='airflow' AIRFLOW_CTX_DAG_ID='beam_etl_dag_with_credentials' AIRFLOW_CTX_TASK_ID='run_beam_pipeline' AIRFLOW_CTX_EXECUTION_DATE='2024-09-10T09:43:00.310170+00:00' AIRFLOW_CTX_TRY_NUMBER='1' AIRFLOW_CTX_DAG_RUN_ID='manual__2024-09-10T09:43:00.310170+00:00'
[2024-09-10T15:13:07.759+0530] {logging_mixin.py:190} INFO - Task instance is in running state
[2024-09-10T15:13:07.759+0530] {logging_mixin.py:190} INFO -  Previous state of the Task instance: queued
[2024-09-10T15:13:07.759+0530] {logging_mixin.py:190} INFO - Current task name:run_beam_pipeline state:running start_date:2024-09-10 09:43:07.537996+00:00
[2024-09-10T15:13:07.760+0530] {logging_mixin.py:190} INFO - Dag name:beam_etl_dag_with_credentials and current dag run status:running
[2024-09-10T15:13:07.760+0530] {taskinstance.py:731} INFO - ::endgroup::
[2024-09-10T15:13:07.763+0530] {pipeline.py:197} INFO - Missing pipeline option (runner). Executing pipeline using the default runner: DirectRunner.
[2024-09-10T15:13:10.784+0530] {_metadata.py:142} WARNING - Compute Engine Metadata server unavailable on attempt 1 of 3. Reason: timed out
[2024-09-10T15:13:14.815+0530] {_metadata.py:142} WARNING - Compute Engine Metadata server unavailable on attempt 2 of 3. Reason: timed out
[2024-09-10T15:13:19.768+0530] {_metadata.py:142} WARNING - Compute Engine Metadata server unavailable on attempt 3 of 3. Reason: timed out
[2024-09-10T15:13:19.768+0530] {_default.py:338} WARNING - Authentication failed using Compute Engine authentication due to unavailable metadata server.
[2024-09-10T15:13:19.771+0530] {retry.py:313} WARNING - Retry with exponential backoff: waiting for 1.359304573721987 seconds before retrying _get_credentials_with_retrys because we caught exception: google.auth.exceptions.DefaultCredentialsError: Your default credentials were not found. To set up Application Default Credentials, see https://cloud.google.com/docs/authentication/external/set-up-adc for more information.
 Traceback for above exception (most recent call last):
  File "/home/sst7260/airflow_projects/project1/env/lib/python3.10/site-packages/apache_beam/utils/retry.py", line 298, in wrapper
    return fun(*args, **kwargs)
  File "/home/sst7260/airflow_projects/project1/env/lib/python3.10/site-packages/apache_beam/internal/gcp/auth.py", line 175, in _get_credentials_with_retrys
    credentials, _ = google.auth.default(
  File "/home/sst7260/airflow_projects/project1/env/lib/python3.10/site-packages/google/auth/_default.py", line 691, in default
    raise exceptions.DefaultCredentialsError(_CLOUD_SDK_MISSING_CREDENTIALS)

[2024-09-10T15:13:24.137+0530] {_metadata.py:142} WARNING - Compute Engine Metadata server unavailable on attempt 1 of 3. Reason: timed out
[2024-09-10T15:13:28.217+0530] {_metadata.py:142} WARNING - Compute Engine Metadata server unavailable on attempt 2 of 3. Reason: timed out
[2024-09-10T15:13:33.377+0530] {_metadata.py:142} WARNING - Compute Engine Metadata server unavailable on attempt 3 of 3. Reason: timed out
[2024-09-10T15:13:33.378+0530] {_default.py:338} WARNING - Authentication failed using Compute Engine authentication due to unavailable metadata server.
[2024-09-10T15:13:33.378+0530] {retry.py:313} WARNING - Retry with exponential backoff: waiting for 3.806170235565127 seconds before retrying _get_credentials_with_retrys because we caught exception: google.auth.exceptions.DefaultCredentialsError: Your default credentials were not found. To set up Application Default Credentials, see https://cloud.google.com/docs/authentication/external/set-up-adc for more information.
 Traceback for above exception (most recent call last):
  File "/home/sst7260/airflow_projects/project1/env/lib/python3.10/site-packages/apache_beam/utils/retry.py", line 298, in wrapper
    return fun(*args, **kwargs)
  File "/home/sst7260/airflow_projects/project1/env/lib/python3.10/site-packages/apache_beam/internal/gcp/auth.py", line 175, in _get_credentials_with_retrys
    credentials, _ = google.auth.default(
  File "/home/sst7260/airflow_projects/project1/env/lib/python3.10/site-packages/google/auth/_default.py", line 691, in default
    raise exceptions.DefaultCredentialsError(_CLOUD_SDK_MISSING_CREDENTIALS)

[2024-09-10T15:13:40.193+0530] {_metadata.py:142} WARNING - Compute Engine Metadata server unavailable on attempt 1 of 3. Reason: timed out
[2024-09-10T15:13:44.250+0530] {_metadata.py:142} WARNING - Compute Engine Metadata server unavailable on attempt 2 of 3. Reason: timed out
[2024-09-10T15:13:49.368+0530] {_metadata.py:142} WARNING - Compute Engine Metadata server unavailable on attempt 3 of 3. Reason: timed out
[2024-09-10T15:13:49.368+0530] {_default.py:338} WARNING - Authentication failed using Compute Engine authentication due to unavailable metadata server.
[2024-09-10T15:13:49.368+0530] {retry.py:313} WARNING - Retry with exponential backoff: waiting for 5.479869898667948 seconds before retrying _get_credentials_with_retrys because we caught exception: google.auth.exceptions.DefaultCredentialsError: Your default credentials were not found. To set up Application Default Credentials, see https://cloud.google.com/docs/authentication/external/set-up-adc for more information.
 Traceback for above exception (most recent call last):
  File "/home/sst7260/airflow_projects/project1/env/lib/python3.10/site-packages/apache_beam/utils/retry.py", line 298, in wrapper
    return fun(*args, **kwargs)
  File "/home/sst7260/airflow_projects/project1/env/lib/python3.10/site-packages/apache_beam/internal/gcp/auth.py", line 175, in _get_credentials_with_retrys
    credentials, _ = google.auth.default(
  File "/home/sst7260/airflow_projects/project1/env/lib/python3.10/site-packages/google/auth/_default.py", line 691, in default
    raise exceptions.DefaultCredentialsError(_CLOUD_SDK_MISSING_CREDENTIALS)

[2024-09-10T15:13:57.858+0530] {_metadata.py:142} WARNING - Compute Engine Metadata server unavailable on attempt 1 of 3. Reason: timed out
[2024-09-10T15:14:01.796+0530] {_metadata.py:142} WARNING - Compute Engine Metadata server unavailable on attempt 2 of 3. Reason: timed out
[2024-09-10T15:14:06.716+0530] {_metadata.py:142} WARNING - Compute Engine Metadata server unavailable on attempt 3 of 3. Reason: timed out
[2024-09-10T15:14:06.716+0530] {_default.py:338} WARNING - Authentication failed using Compute Engine authentication due to unavailable metadata server.
[2024-09-10T15:14:06.717+0530] {retry.py:313} WARNING - Retry with exponential backoff: waiting for 8.624563674567781 seconds before retrying _get_credentials_with_retrys because we caught exception: google.auth.exceptions.DefaultCredentialsError: Your default credentials were not found. To set up Application Default Credentials, see https://cloud.google.com/docs/authentication/external/set-up-adc for more information.
 Traceback for above exception (most recent call last):
  File "/home/sst7260/airflow_projects/project1/env/lib/python3.10/site-packages/apache_beam/utils/retry.py", line 298, in wrapper
    return fun(*args, **kwargs)
  File "/home/sst7260/airflow_projects/project1/env/lib/python3.10/site-packages/apache_beam/internal/gcp/auth.py", line 175, in _get_credentials_with_retrys
    credentials, _ = google.auth.default(
  File "/home/sst7260/airflow_projects/project1/env/lib/python3.10/site-packages/google/auth/_default.py", line 691, in default
    raise exceptions.DefaultCredentialsError(_CLOUD_SDK_MISSING_CREDENTIALS)

[2024-09-10T15:14:18.355+0530] {_metadata.py:142} WARNING - Compute Engine Metadata server unavailable on attempt 1 of 3. Reason: timed out
[2024-09-10T15:14:22.406+0530] {_metadata.py:142} WARNING - Compute Engine Metadata server unavailable on attempt 2 of 3. Reason: timed out
[2024-09-10T15:14:27.609+0530] {_metadata.py:142} WARNING - Compute Engine Metadata server unavailable on attempt 3 of 3. Reason: timed out
[2024-09-10T15:14:27.610+0530] {_default.py:338} WARNING - Authentication failed using Compute Engine authentication due to unavailable metadata server.
[2024-09-10T15:14:27.610+0530] {auth.py:165} WARNING - Unable to find default credentials to use: Your default credentials were not found. To set up Application Default Credentials, see https://cloud.google.com/docs/authentication/external/set-up-adc for more information.
Connecting anonymously. This is expected if no credentials are needed to access GCP resources.
[2024-09-10T15:14:28.308+0530] {requests.py:558} INFO - Refreshing credentials due to a 401 response. Attempt 1/2.
[2024-09-10T15:14:28.317+0530] {retry.py:313} WARNING - Retry with exponential backoff: waiting for 2.7459492255611737 seconds before retrying _gcs_object because we caught exception: google.auth.exceptions.InvalidOperation: Anonymous credentials cannot be refreshed.
 Traceback for above exception (most recent call last):
  File "/home/sst7260/airflow_projects/project1/env/lib/python3.10/site-packages/apache_beam/utils/retry.py", line 298, in wrapper
    return fun(*args, **kwargs)
  File "/home/sst7260/airflow_projects/project1/env/lib/python3.10/site-packages/apache_beam/io/gcp/gcsio.py", line 462, in _gcs_object
    blob = bucket.get_blob(blob_name)
  File "/usr/lib/python3.10/contextlib.py", line 79, in inner
    return func(*args, **kwds)
  File "/home/sst7260/airflow_projects/project1/env/lib/python3.10/site-packages/google/cloud/storage/bucket.py", line 1283, in get_blob
    blob.reload(
  File "/home/sst7260/airflow_projects/project1/env/lib/python3.10/site-packages/google/cloud/storage/_helpers.py", line 300, in reload
    api_response = client._get_resource(
  File "/home/sst7260/airflow_projects/project1/env/lib/python3.10/site-packages/google/cloud/storage/client.py", line 464, in _get_resource
    return self._connection.api_request(
  File "/home/sst7260/airflow_projects/project1/env/lib/python3.10/site-packages/google/cloud/storage/_http.py", line 90, in api_request
    return call()
  File "/home/sst7260/airflow_projects/project1/env/lib/python3.10/site-packages/google/api_core/retry/retry_unary.py", line 293, in retry_wrapped_func
    return retry_target(
  File "/home/sst7260/airflow_projects/project1/env/lib/python3.10/site-packages/google/api_core/retry/retry_unary.py", line 153, in retry_target
    _retry_error_helper(
  File "/home/sst7260/airflow_projects/project1/env/lib/python3.10/site-packages/google/api_core/retry/retry_base.py", line 212, in _retry_error_helper
    raise final_exc from source_exc
  File "/home/sst7260/airflow_projects/project1/env/lib/python3.10/site-packages/google/api_core/retry/retry_unary.py", line 144, in retry_target
    result = target()
  File "/home/sst7260/airflow_projects/project1/env/lib/python3.10/site-packages/google/cloud/_http/__init__.py", line 482, in api_request
    response = self._make_request(
  File "/home/sst7260/airflow_projects/project1/env/lib/python3.10/site-packages/google/cloud/_http/__init__.py", line 341, in _make_request
    return self._do_request(
  File "/home/sst7260/airflow_projects/project1/env/lib/python3.10/site-packages/google/cloud/_http/__init__.py", line 379, in _do_request
    return self.http.request(
  File "/home/sst7260/airflow_projects/project1/env/lib/python3.10/site-packages/google/auth/transport/requests.py", line 574, in request
    self.credentials.refresh(auth_request)
  File "/home/sst7260/airflow_projects/project1/env/lib/python3.10/site-packages/google/auth/credentials.py", line 311, in refresh
    raise exceptions.InvalidOperation("Anonymous credentials cannot be refreshed.")

[2024-09-10T15:14:31.448+0530] {requests.py:558} INFO - Refreshing credentials due to a 401 response. Attempt 1/2.
[2024-09-10T15:14:31.448+0530] {retry.py:313} WARNING - Retry with exponential backoff: waiting for 7.696334806837286 seconds before retrying _gcs_object because we caught exception: google.auth.exceptions.InvalidOperation: Anonymous credentials cannot be refreshed.
 Traceback for above exception (most recent call last):
  File "/home/sst7260/airflow_projects/project1/env/lib/python3.10/site-packages/apache_beam/utils/retry.py", line 298, in wrapper
    return fun(*args, **kwargs)
  File "/home/sst7260/airflow_projects/project1/env/lib/python3.10/site-packages/apache_beam/io/gcp/gcsio.py", line 462, in _gcs_object
    blob = bucket.get_blob(blob_name)
  File "/usr/lib/python3.10/contextlib.py", line 79, in inner
    return func(*args, **kwds)
  File "/home/sst7260/airflow_projects/project1/env/lib/python3.10/site-packages/google/cloud/storage/bucket.py", line 1283, in get_blob
    blob.reload(
  File "/home/sst7260/airflow_projects/project1/env/lib/python3.10/site-packages/google/cloud/storage/_helpers.py", line 300, in reload
    api_response = client._get_resource(
  File "/home/sst7260/airflow_projects/project1/env/lib/python3.10/site-packages/google/cloud/storage/client.py", line 464, in _get_resource
    return self._connection.api_request(
  File "/home/sst7260/airflow_projects/project1/env/lib/python3.10/site-packages/google/cloud/storage/_http.py", line 90, in api_request
    return call()
  File "/home/sst7260/airflow_projects/project1/env/lib/python3.10/site-packages/google/api_core/retry/retry_unary.py", line 293, in retry_wrapped_func
    return retry_target(
  File "/home/sst7260/airflow_projects/project1/env/lib/python3.10/site-packages/google/api_core/retry/retry_unary.py", line 153, in retry_target
    _retry_error_helper(
  File "/home/sst7260/airflow_projects/project1/env/lib/python3.10/site-packages/google/api_core/retry/retry_base.py", line 212, in _retry_error_helper
    raise final_exc from source_exc
  File "/home/sst7260/airflow_projects/project1/env/lib/python3.10/site-packages/google/api_core/retry/retry_unary.py", line 144, in retry_target
    result = target()
  File "/home/sst7260/airflow_projects/project1/env/lib/python3.10/site-packages/google/cloud/_http/__init__.py", line 482, in api_request
    response = self._make_request(
  File "/home/sst7260/airflow_projects/project1/env/lib/python3.10/site-packages/google/cloud/_http/__init__.py", line 341, in _make_request
    return self._do_request(
  File "/home/sst7260/airflow_projects/project1/env/lib/python3.10/site-packages/google/cloud/_http/__init__.py", line 379, in _do_request
    return self.http.request(
  File "/home/sst7260/airflow_projects/project1/env/lib/python3.10/site-packages/google/auth/transport/requests.py", line 574, in request
    self.credentials.refresh(auth_request)
  File "/home/sst7260/airflow_projects/project1/env/lib/python3.10/site-packages/google/auth/credentials.py", line 311, in refresh
    raise exceptions.InvalidOperation("Anonymous credentials cannot be refreshed.")

[2024-09-10T15:14:39.538+0530] {requests.py:558} INFO - Refreshing credentials due to a 401 response. Attempt 1/2.
[2024-09-10T15:14:39.539+0530] {retry.py:313} WARNING - Retry with exponential backoff: waiting for 12.722269234005964 seconds before retrying _gcs_object because we caught exception: google.auth.exceptions.InvalidOperation: Anonymous credentials cannot be refreshed.
 Traceback for above exception (most recent call last):
  File "/home/sst7260/airflow_projects/project1/env/lib/python3.10/site-packages/apache_beam/utils/retry.py", line 298, in wrapper
    return fun(*args, **kwargs)
  File "/home/sst7260/airflow_projects/project1/env/lib/python3.10/site-packages/apache_beam/io/gcp/gcsio.py", line 462, in _gcs_object
    blob = bucket.get_blob(blob_name)
  File "/usr/lib/python3.10/contextlib.py", line 79, in inner
    return func(*args, **kwds)
  File "/home/sst7260/airflow_projects/project1/env/lib/python3.10/site-packages/google/cloud/storage/bucket.py", line 1283, in get_blob
    blob.reload(
  File "/home/sst7260/airflow_projects/project1/env/lib/python3.10/site-packages/google/cloud/storage/_helpers.py", line 300, in reload
    api_response = client._get_resource(
  File "/home/sst7260/airflow_projects/project1/env/lib/python3.10/site-packages/google/cloud/storage/client.py", line 464, in _get_resource
    return self._connection.api_request(
  File "/home/sst7260/airflow_projects/project1/env/lib/python3.10/site-packages/google/cloud/storage/_http.py", line 90, in api_request
    return call()
  File "/home/sst7260/airflow_projects/project1/env/lib/python3.10/site-packages/google/api_core/retry/retry_unary.py", line 293, in retry_wrapped_func
    return retry_target(
  File "/home/sst7260/airflow_projects/project1/env/lib/python3.10/site-packages/google/api_core/retry/retry_unary.py", line 153, in retry_target
    _retry_error_helper(
  File "/home/sst7260/airflow_projects/project1/env/lib/python3.10/site-packages/google/api_core/retry/retry_base.py", line 212, in _retry_error_helper
    raise final_exc from source_exc
  File "/home/sst7260/airflow_projects/project1/env/lib/python3.10/site-packages/google/api_core/retry/retry_unary.py", line 144, in retry_target
    result = target()
  File "/home/sst7260/airflow_projects/project1/env/lib/python3.10/site-packages/google/cloud/_http/__init__.py", line 482, in api_request
    response = self._make_request(
  File "/home/sst7260/airflow_projects/project1/env/lib/python3.10/site-packages/google/cloud/_http/__init__.py", line 341, in _make_request
    return self._do_request(
  File "/home/sst7260/airflow_projects/project1/env/lib/python3.10/site-packages/google/cloud/_http/__init__.py", line 379, in _do_request
    return self.http.request(
  File "/home/sst7260/airflow_projects/project1/env/lib/python3.10/site-packages/google/auth/transport/requests.py", line 574, in request
    self.credentials.refresh(auth_request)
  File "/home/sst7260/airflow_projects/project1/env/lib/python3.10/site-packages/google/auth/credentials.py", line 311, in refresh
    raise exceptions.InvalidOperation("Anonymous credentials cannot be refreshed.")

[2024-09-10T15:14:52.663+0530] {requests.py:558} INFO - Refreshing credentials due to a 401 response. Attempt 1/2.
[2024-09-10T15:14:52.663+0530] {retry.py:313} WARNING - Retry with exponential backoff: waiting for 36.71366483457744 seconds before retrying _gcs_object because we caught exception: google.auth.exceptions.InvalidOperation: Anonymous credentials cannot be refreshed.
 Traceback for above exception (most recent call last):
  File "/home/sst7260/airflow_projects/project1/env/lib/python3.10/site-packages/apache_beam/utils/retry.py", line 298, in wrapper
    return fun(*args, **kwargs)
  File "/home/sst7260/airflow_projects/project1/env/lib/python3.10/site-packages/apache_beam/io/gcp/gcsio.py", line 462, in _gcs_object
    blob = bucket.get_blob(blob_name)
  File "/usr/lib/python3.10/contextlib.py", line 79, in inner
    return func(*args, **kwds)
  File "/home/sst7260/airflow_projects/project1/env/lib/python3.10/site-packages/google/cloud/storage/bucket.py", line 1283, in get_blob
    blob.reload(
  File "/home/sst7260/airflow_projects/project1/env/lib/python3.10/site-packages/google/cloud/storage/_helpers.py", line 300, in reload
    api_response = client._get_resource(
  File "/home/sst7260/airflow_projects/project1/env/lib/python3.10/site-packages/google/cloud/storage/client.py", line 464, in _get_resource
    return self._connection.api_request(
  File "/home/sst7260/airflow_projects/project1/env/lib/python3.10/site-packages/google/cloud/storage/_http.py", line 90, in api_request
    return call()
  File "/home/sst7260/airflow_projects/project1/env/lib/python3.10/site-packages/google/api_core/retry/retry_unary.py", line 293, in retry_wrapped_func
    return retry_target(
  File "/home/sst7260/airflow_projects/project1/env/lib/python3.10/site-packages/google/api_core/retry/retry_unary.py", line 153, in retry_target
    _retry_error_helper(
  File "/home/sst7260/airflow_projects/project1/env/lib/python3.10/site-packages/google/api_core/retry/retry_base.py", line 212, in _retry_error_helper
    raise final_exc from source_exc
  File "/home/sst7260/airflow_projects/project1/env/lib/python3.10/site-packages/google/api_core/retry/retry_unary.py", line 144, in retry_target
    result = target()
  File "/home/sst7260/airflow_projects/project1/env/lib/python3.10/site-packages/google/cloud/_http/__init__.py", line 482, in api_request
    response = self._make_request(
  File "/home/sst7260/airflow_projects/project1/env/lib/python3.10/site-packages/google/cloud/_http/__init__.py", line 341, in _make_request
    return self._do_request(
  File "/home/sst7260/airflow_projects/project1/env/lib/python3.10/site-packages/google/cloud/_http/__init__.py", line 379, in _do_request
    return self.http.request(
  File "/home/sst7260/airflow_projects/project1/env/lib/python3.10/site-packages/google/auth/transport/requests.py", line 574, in request
    self.credentials.refresh(auth_request)
  File "/home/sst7260/airflow_projects/project1/env/lib/python3.10/site-packages/google/auth/credentials.py", line 311, in refresh
    raise exceptions.InvalidOperation("Anonymous credentials cannot be refreshed.")

[2024-09-10T15:15:29.798+0530] {requests.py:558} INFO - Refreshing credentials due to a 401 response. Attempt 1/2.
[2024-09-10T15:15:29.799+0530] {retry.py:313} WARNING - Retry with exponential backoff: waiting for 66.81281958572174 seconds before retrying _gcs_object because we caught exception: google.auth.exceptions.InvalidOperation: Anonymous credentials cannot be refreshed.
 Traceback for above exception (most recent call last):
  File "/home/sst7260/airflow_projects/project1/env/lib/python3.10/site-packages/apache_beam/utils/retry.py", line 298, in wrapper
    return fun(*args, **kwargs)
  File "/home/sst7260/airflow_projects/project1/env/lib/python3.10/site-packages/apache_beam/io/gcp/gcsio.py", line 462, in _gcs_object
    blob = bucket.get_blob(blob_name)
  File "/usr/lib/python3.10/contextlib.py", line 79, in inner
    return func(*args, **kwds)
  File "/home/sst7260/airflow_projects/project1/env/lib/python3.10/site-packages/google/cloud/storage/bucket.py", line 1283, in get_blob
    blob.reload(
  File "/home/sst7260/airflow_projects/project1/env/lib/python3.10/site-packages/google/cloud/storage/_helpers.py", line 300, in reload
    api_response = client._get_resource(
  File "/home/sst7260/airflow_projects/project1/env/lib/python3.10/site-packages/google/cloud/storage/client.py", line 464, in _get_resource
    return self._connection.api_request(
  File "/home/sst7260/airflow_projects/project1/env/lib/python3.10/site-packages/google/cloud/storage/_http.py", line 90, in api_request
    return call()
  File "/home/sst7260/airflow_projects/project1/env/lib/python3.10/site-packages/google/api_core/retry/retry_unary.py", line 293, in retry_wrapped_func
    return retry_target(
  File "/home/sst7260/airflow_projects/project1/env/lib/python3.10/site-packages/google/api_core/retry/retry_unary.py", line 153, in retry_target
    _retry_error_helper(
  File "/home/sst7260/airflow_projects/project1/env/lib/python3.10/site-packages/google/api_core/retry/retry_base.py", line 212, in _retry_error_helper
    raise final_exc from source_exc
  File "/home/sst7260/airflow_projects/project1/env/lib/python3.10/site-packages/google/api_core/retry/retry_unary.py", line 144, in retry_target
    result = target()
  File "/home/sst7260/airflow_projects/project1/env/lib/python3.10/site-packages/google/cloud/_http/__init__.py", line 482, in api_request
    response = self._make_request(
  File "/home/sst7260/airflow_projects/project1/env/lib/python3.10/site-packages/google/cloud/_http/__init__.py", line 341, in _make_request
    return self._do_request(
  File "/home/sst7260/airflow_projects/project1/env/lib/python3.10/site-packages/google/cloud/_http/__init__.py", line 379, in _do_request
    return self.http.request(
  File "/home/sst7260/airflow_projects/project1/env/lib/python3.10/site-packages/google/auth/transport/requests.py", line 574, in request
    self.credentials.refresh(auth_request)
  File "/home/sst7260/airflow_projects/project1/env/lib/python3.10/site-packages/google/auth/credentials.py", line 311, in refresh
    raise exceptions.InvalidOperation("Anonymous credentials cannot be refreshed.")

[2024-09-10T15:16:29.078+0530] {local_task_job_runner.py:318} WARNING - Recorded pid 187946 does not match the current pid 186775
[2024-09-10T15:16:29.079+0530] {local_task_job_runner.py:218} WARNING - Heartbeat failed with Exception: PID of job runner does not match
[2024-09-10T15:16:34.113+0530] {local_task_job_runner.py:318} WARNING - Recorded pid 187946 does not match the current pid 186775
[2024-09-10T15:16:34.113+0530] {local_task_job_runner.py:218} WARNING - Heartbeat failed with Exception: PID of job runner does not match
[2024-09-10T15:16:37.067+0530] {requests.py:558} INFO - Refreshing credentials due to a 401 response. Attempt 1/2.
[2024-09-10T15:16:37.071+0530] {retry.py:313} WARNING - Retry with exponential backoff: waiting for 107.35741307796812 seconds before retrying _gcs_object because we caught exception: google.auth.exceptions.InvalidOperation: Anonymous credentials cannot be refreshed.
 Traceback for above exception (most recent call last):
  File "/home/sst7260/airflow_projects/project1/env/lib/python3.10/site-packages/apache_beam/utils/retry.py", line 298, in wrapper
    return fun(*args, **kwargs)
  File "/home/sst7260/airflow_projects/project1/env/lib/python3.10/site-packages/apache_beam/io/gcp/gcsio.py", line 462, in _gcs_object
    blob = bucket.get_blob(blob_name)
  File "/usr/lib/python3.10/contextlib.py", line 79, in inner
    return func(*args, **kwds)
  File "/home/sst7260/airflow_projects/project1/env/lib/python3.10/site-packages/google/cloud/storage/bucket.py", line 1283, in get_blob
    blob.reload(
  File "/home/sst7260/airflow_projects/project1/env/lib/python3.10/site-packages/google/cloud/storage/_helpers.py", line 300, in reload
    api_response = client._get_resource(
  File "/home/sst7260/airflow_projects/project1/env/lib/python3.10/site-packages/google/cloud/storage/client.py", line 464, in _get_resource
    return self._connection.api_request(
  File "/home/sst7260/airflow_projects/project1/env/lib/python3.10/site-packages/google/cloud/storage/_http.py", line 90, in api_request
    return call()
  File "/home/sst7260/airflow_projects/project1/env/lib/python3.10/site-packages/google/api_core/retry/retry_unary.py", line 293, in retry_wrapped_func
    return retry_target(
  File "/home/sst7260/airflow_projects/project1/env/lib/python3.10/site-packages/google/api_core/retry/retry_unary.py", line 153, in retry_target
    _retry_error_helper(
  File "/home/sst7260/airflow_projects/project1/env/lib/python3.10/site-packages/google/api_core/retry/retry_base.py", line 212, in _retry_error_helper
    raise final_exc from source_exc
  File "/home/sst7260/airflow_projects/project1/env/lib/python3.10/site-packages/google/api_core/retry/retry_unary.py", line 144, in retry_target
    result = target()
  File "/home/sst7260/airflow_projects/project1/env/lib/python3.10/site-packages/google/cloud/_http/__init__.py", line 482, in api_request
    response = self._make_request(
  File "/home/sst7260/airflow_projects/project1/env/lib/python3.10/site-packages/google/cloud/_http/__init__.py", line 341, in _make_request
    return self._do_request(
  File "/home/sst7260/airflow_projects/project1/env/lib/python3.10/site-packages/google/cloud/_http/__init__.py", line 379, in _do_request
    return self.http.request(
  File "/home/sst7260/airflow_projects/project1/env/lib/python3.10/site-packages/google/auth/transport/requests.py", line 574, in request
    self.credentials.refresh(auth_request)
  File "/home/sst7260/airflow_projects/project1/env/lib/python3.10/site-packages/google/auth/credentials.py", line 311, in refresh
    raise exceptions.InvalidOperation("Anonymous credentials cannot be refreshed.")

[2024-09-10T15:16:39.146+0530] {local_task_job_runner.py:318} WARNING - Recorded pid 187946 does not match the current pid 186775
[2024-09-10T15:16:39.146+0530] {local_task_job_runner.py:218} WARNING - Heartbeat failed with Exception: PID of job runner does not match
[2024-09-10T15:16:44.184+0530] {local_task_job_runner.py:318} WARNING - Recorded pid 187946 does not match the current pid 186775
[2024-09-10T15:16:44.185+0530] {local_task_job_runner.py:218} WARNING - Heartbeat failed with Exception: PID of job runner does not match
[2024-09-10T15:16:49.213+0530] {local_task_job_runner.py:318} WARNING - Recorded pid 187946 does not match the current pid 186775
[2024-09-10T15:16:49.213+0530] {local_task_job_runner.py:218} WARNING - Heartbeat failed with Exception: PID of job runner does not match
[2024-09-10T15:16:54.248+0530] {local_task_job_runner.py:318} WARNING - Recorded pid 187946 does not match the current pid 186775
[2024-09-10T15:16:54.248+0530] {local_task_job_runner.py:218} WARNING - Heartbeat failed with Exception: PID of job runner does not match
[2024-09-10T15:16:59.283+0530] {local_task_job_runner.py:318} WARNING - Recorded pid 187946 does not match the current pid 186775
[2024-09-10T15:16:59.283+0530] {local_task_job_runner.py:218} WARNING - Heartbeat failed with Exception: PID of job runner does not match
[2024-09-10T15:17:04.311+0530] {local_task_job_runner.py:318} WARNING - Recorded pid 187946 does not match the current pid 186775
[2024-09-10T15:17:04.311+0530] {local_task_job_runner.py:218} WARNING - Heartbeat failed with Exception: PID of job runner does not match
[2024-09-10T15:17:09.341+0530] {local_task_job_runner.py:318} WARNING - Recorded pid 187946 does not match the current pid 186775
[2024-09-10T15:17:09.341+0530] {local_task_job_runner.py:218} WARNING - Heartbeat failed with Exception: PID of job runner does not match
[2024-09-10T15:17:14.378+0530] {local_task_job_runner.py:318} WARNING - Recorded pid 187946 does not match the current pid 186775
[2024-09-10T15:17:14.378+0530] {local_task_job_runner.py:218} WARNING - Heartbeat failed with Exception: PID of job runner does not match
[2024-09-10T15:17:19.414+0530] {local_task_job_runner.py:318} WARNING - Recorded pid 187946 does not match the current pid 186775
[2024-09-10T15:17:19.414+0530] {local_task_job_runner.py:218} WARNING - Heartbeat failed with Exception: PID of job runner does not match
[2024-09-10T15:17:24.443+0530] {local_task_job_runner.py:318} WARNING - Recorded pid 187946 does not match the current pid 186775
[2024-09-10T15:17:24.443+0530] {local_task_job_runner.py:218} WARNING - Heartbeat failed with Exception: PID of job runner does not match
[2024-09-10T15:17:29.471+0530] {local_task_job_runner.py:318} WARNING - Recorded pid 187946 does not match the current pid 186775
[2024-09-10T15:17:29.472+0530] {local_task_job_runner.py:218} WARNING - Heartbeat failed with Exception: PID of job runner does not match
[2024-09-10T15:17:34.503+0530] {local_task_job_runner.py:318} WARNING - Recorded pid 187946 does not match the current pid 186775
[2024-09-10T15:17:34.504+0530] {local_task_job_runner.py:218} WARNING - Heartbeat failed with Exception: PID of job runner does not match
[2024-09-10T15:17:39.537+0530] {local_task_job_runner.py:318} WARNING - Recorded pid 187946 does not match the current pid 186775
[2024-09-10T15:17:39.538+0530] {local_task_job_runner.py:218} WARNING - Heartbeat failed with Exception: PID of job runner does not match
[2024-09-10T15:17:44.573+0530] {local_task_job_runner.py:318} WARNING - Recorded pid 187946 does not match the current pid 186775
[2024-09-10T15:17:44.574+0530] {local_task_job_runner.py:218} WARNING - Heartbeat failed with Exception: PID of job runner does not match
[2024-09-10T15:17:49.613+0530] {local_task_job_runner.py:318} WARNING - Recorded pid 187946 does not match the current pid 186775
[2024-09-10T15:17:49.614+0530] {local_task_job_runner.py:218} WARNING - Heartbeat failed with Exception: PID of job runner does not match
[2024-09-10T15:17:54.673+0530] {local_task_job_runner.py:318} WARNING - Recorded pid 187946 does not match the current pid 186775
[2024-09-10T15:17:54.674+0530] {local_task_job_runner.py:218} WARNING - Heartbeat failed with Exception: PID of job runner does not match
[2024-09-10T15:17:59.704+0530] {local_task_job_runner.py:318} WARNING - Recorded pid 187946 does not match the current pid 186775
[2024-09-10T15:17:59.705+0530] {local_task_job_runner.py:218} WARNING - Heartbeat failed with Exception: PID of job runner does not match
[2024-09-10T15:18:04.744+0530] {local_task_job_runner.py:318} WARNING - Recorded pid 187946 does not match the current pid 186775
[2024-09-10T15:18:04.744+0530] {local_task_job_runner.py:218} WARNING - Heartbeat failed with Exception: PID of job runner does not match
[2024-09-10T15:18:09.770+0530] {local_task_job_runner.py:318} WARNING - Recorded pid 187946 does not match the current pid 186775
[2024-09-10T15:18:09.770+0530] {local_task_job_runner.py:218} WARNING - Heartbeat failed with Exception: PID of job runner does not match
[2024-09-10T15:18:14.796+0530] {local_task_job_runner.py:318} WARNING - Recorded pid 187946 does not match the current pid 186775
[2024-09-10T15:18:14.796+0530] {local_task_job_runner.py:218} WARNING - Heartbeat failed with Exception: PID of job runner does not match
[2024-09-10T15:18:19.828+0530] {local_task_job_runner.py:318} WARNING - Recorded pid 187946 does not match the current pid 186775
[2024-09-10T15:18:19.828+0530] {local_task_job_runner.py:218} WARNING - Heartbeat failed with Exception: PID of job runner does not match
[2024-09-10T15:18:24.855+0530] {local_task_job_runner.py:318} WARNING - Recorded pid 187946 does not match the current pid 186775
[2024-09-10T15:18:24.855+0530] {local_task_job_runner.py:218} WARNING - Heartbeat failed with Exception: PID of job runner does not match
[2024-09-10T15:18:24.932+0530] {requests.py:558} INFO - Refreshing credentials due to a 401 response. Attempt 1/2.
[2024-09-10T15:18:24.932+0530] {retry.py:313} WARNING - Retry with exponential backoff: waiting for 272.9374175754605 seconds before retrying _gcs_object because we caught exception: google.auth.exceptions.InvalidOperation: Anonymous credentials cannot be refreshed.
 Traceback for above exception (most recent call last):
  File "/home/sst7260/airflow_projects/project1/env/lib/python3.10/site-packages/apache_beam/utils/retry.py", line 298, in wrapper
    return fun(*args, **kwargs)
  File "/home/sst7260/airflow_projects/project1/env/lib/python3.10/site-packages/apache_beam/io/gcp/gcsio.py", line 462, in _gcs_object
    blob = bucket.get_blob(blob_name)
  File "/usr/lib/python3.10/contextlib.py", line 79, in inner
    return func(*args, **kwds)
  File "/home/sst7260/airflow_projects/project1/env/lib/python3.10/site-packages/google/cloud/storage/bucket.py", line 1283, in get_blob
    blob.reload(
  File "/home/sst7260/airflow_projects/project1/env/lib/python3.10/site-packages/google/cloud/storage/_helpers.py", line 300, in reload
    api_response = client._get_resource(
  File "/home/sst7260/airflow_projects/project1/env/lib/python3.10/site-packages/google/cloud/storage/client.py", line 464, in _get_resource
    return self._connection.api_request(
  File "/home/sst7260/airflow_projects/project1/env/lib/python3.10/site-packages/google/cloud/storage/_http.py", line 90, in api_request
    return call()
  File "/home/sst7260/airflow_projects/project1/env/lib/python3.10/site-packages/google/api_core/retry/retry_unary.py", line 293, in retry_wrapped_func
    return retry_target(
  File "/home/sst7260/airflow_projects/project1/env/lib/python3.10/site-packages/google/api_core/retry/retry_unary.py", line 153, in retry_target
    _retry_error_helper(
  File "/home/sst7260/airflow_projects/project1/env/lib/python3.10/site-packages/google/api_core/retry/retry_base.py", line 212, in _retry_error_helper
    raise final_exc from source_exc
  File "/home/sst7260/airflow_projects/project1/env/lib/python3.10/site-packages/google/api_core/retry/retry_unary.py", line 144, in retry_target
    result = target()
  File "/home/sst7260/airflow_projects/project1/env/lib/python3.10/site-packages/google/cloud/_http/__init__.py", line 482, in api_request
    response = self._make_request(
  File "/home/sst7260/airflow_projects/project1/env/lib/python3.10/site-packages/google/cloud/_http/__init__.py", line 341, in _make_request
    return self._do_request(
  File "/home/sst7260/airflow_projects/project1/env/lib/python3.10/site-packages/google/cloud/_http/__init__.py", line 379, in _do_request
    return self.http.request(
  File "/home/sst7260/airflow_projects/project1/env/lib/python3.10/site-packages/google/auth/transport/requests.py", line 574, in request
    self.credentials.refresh(auth_request)
  File "/home/sst7260/airflow_projects/project1/env/lib/python3.10/site-packages/google/auth/credentials.py", line 311, in refresh
    raise exceptions.InvalidOperation("Anonymous credentials cannot be refreshed.")

[2024-09-10T15:18:29.884+0530] {local_task_job_runner.py:318} WARNING - Recorded pid 187946 does not match the current pid 186775
[2024-09-10T15:18:29.885+0530] {local_task_job_runner.py:218} WARNING - Heartbeat failed with Exception: PID of job runner does not match
[2024-09-10T15:18:34.912+0530] {local_task_job_runner.py:318} WARNING - Recorded pid 187946 does not match the current pid 186775
[2024-09-10T15:18:34.912+0530] {local_task_job_runner.py:218} WARNING - Heartbeat failed with Exception: PID of job runner does not match
[2024-09-10T15:18:39.956+0530] {local_task_job_runner.py:318} WARNING - Recorded pid 187946 does not match the current pid 186775
[2024-09-10T15:18:39.956+0530] {local_task_job_runner.py:218} WARNING - Heartbeat failed with Exception: PID of job runner does not match
[2024-09-10T15:18:44.977+0530] {local_task_job_runner.py:318} WARNING - Recorded pid 187946 does not match the current pid 186775
[2024-09-10T15:18:44.978+0530] {local_task_job_runner.py:218} WARNING - Heartbeat failed with Exception: PID of job runner does not match
[2024-09-10T15:18:50.005+0530] {local_task_job_runner.py:318} WARNING - Recorded pid 187946 does not match the current pid 186775
[2024-09-10T15:18:50.006+0530] {local_task_job_runner.py:218} WARNING - Heartbeat failed with Exception: PID of job runner does not match
[2024-09-10T15:18:55.066+0530] {local_task_job_runner.py:318} WARNING - Recorded pid 187946 does not match the current pid 186775
[2024-09-10T15:18:55.066+0530] {local_task_job_runner.py:218} WARNING - Heartbeat failed with Exception: PID of job runner does not match
[2024-09-10T15:19:00.127+0530] {local_task_job_runner.py:318} WARNING - Recorded pid 187946 does not match the current pid 186775
[2024-09-10T15:19:00.128+0530] {local_task_job_runner.py:218} WARNING - Heartbeat failed with Exception: PID of job runner does not match
[2024-09-10T15:19:05.150+0530] {local_task_job_runner.py:318} WARNING - Recorded pid 187946 does not match the current pid 186775
[2024-09-10T15:19:05.151+0530] {local_task_job_runner.py:218} WARNING - Heartbeat failed with Exception: PID of job runner does not match
[2024-09-10T15:19:10.181+0530] {local_task_job_runner.py:318} WARNING - Recorded pid 187946 does not match the current pid 186775
[2024-09-10T15:19:10.181+0530] {local_task_job_runner.py:218} WARNING - Heartbeat failed with Exception: PID of job runner does not match
[2024-09-10T15:19:15.205+0530] {local_task_job_runner.py:318} WARNING - Recorded pid 187946 does not match the current pid 186775
[2024-09-10T15:19:15.206+0530] {local_task_job_runner.py:218} WARNING - Heartbeat failed with Exception: PID of job runner does not match
[2024-09-10T15:19:20.230+0530] {local_task_job_runner.py:318} WARNING - Recorded pid 187946 does not match the current pid 186775
[2024-09-10T15:19:20.230+0530] {local_task_job_runner.py:218} WARNING - Heartbeat failed with Exception: PID of job runner does not match
[2024-09-10T15:19:25.295+0530] {local_task_job_runner.py:318} WARNING - Recorded pid 187946 does not match the current pid 186775
[2024-09-10T15:19:25.295+0530] {local_task_job_runner.py:218} WARNING - Heartbeat failed with Exception: PID of job runner does not match
[2024-09-10T15:19:30.355+0530] {local_task_job_runner.py:318} WARNING - Recorded pid 187946 does not match the current pid 186775
[2024-09-10T15:19:30.356+0530] {local_task_job_runner.py:218} WARNING - Heartbeat failed with Exception: PID of job runner does not match
[2024-09-10T15:19:35.380+0530] {local_task_job_runner.py:318} WARNING - Recorded pid 187946 does not match the current pid 186775
[2024-09-10T15:19:35.380+0530] {local_task_job_runner.py:218} WARNING - Heartbeat failed with Exception: PID of job runner does not match
[2024-09-10T15:19:40.403+0530] {local_task_job_runner.py:318} WARNING - Recorded pid 187946 does not match the current pid 186775
[2024-09-10T15:19:40.404+0530] {local_task_job_runner.py:218} WARNING - Heartbeat failed with Exception: PID of job runner does not match
[2024-09-10T15:19:45.432+0530] {local_task_job_runner.py:318} WARNING - Recorded pid 187946 does not match the current pid 186775
[2024-09-10T15:19:45.433+0530] {local_task_job_runner.py:218} WARNING - Heartbeat failed with Exception: PID of job runner does not match
[2024-09-10T15:19:50.462+0530] {local_task_job_runner.py:318} WARNING - Recorded pid 187946 does not match the current pid 186775
[2024-09-10T15:19:50.462+0530] {local_task_job_runner.py:218} WARNING - Heartbeat failed with Exception: PID of job runner does not match
[2024-09-10T15:19:55.489+0530] {local_task_job_runner.py:318} WARNING - Recorded pid 187946 does not match the current pid 186775
[2024-09-10T15:19:55.489+0530] {local_task_job_runner.py:218} WARNING - Heartbeat failed with Exception: PID of job runner does not match
[2024-09-10T15:20:00.513+0530] {local_task_job_runner.py:318} WARNING - Recorded pid 187946 does not match the current pid 186775
[2024-09-10T15:20:00.514+0530] {local_task_job_runner.py:218} WARNING - Heartbeat failed with Exception: PID of job runner does not match
[2024-09-10T15:20:05.541+0530] {local_task_job_runner.py:318} WARNING - Recorded pid 187946 does not match the current pid 186775
[2024-09-10T15:20:05.541+0530] {local_task_job_runner.py:218} WARNING - Heartbeat failed with Exception: PID of job runner does not match
[2024-09-10T15:20:10.562+0530] {local_task_job_runner.py:318} WARNING - Recorded pid 187946 does not match the current pid 186775
[2024-09-10T15:20:10.562+0530] {local_task_job_runner.py:218} WARNING - Heartbeat failed with Exception: PID of job runner does not match
[2024-09-10T15:20:15.588+0530] {local_task_job_runner.py:318} WARNING - Recorded pid 187946 does not match the current pid 186775
[2024-09-10T15:20:15.588+0530] {local_task_job_runner.py:218} WARNING - Heartbeat failed with Exception: PID of job runner does not match
[2024-09-10T15:20:20.619+0530] {local_task_job_runner.py:318} WARNING - Recorded pid 187946 does not match the current pid 186775
[2024-09-10T15:20:20.620+0530] {local_task_job_runner.py:218} WARNING - Heartbeat failed with Exception: PID of job runner does not match
[2024-09-10T15:20:25.651+0530] {local_task_job_runner.py:318} WARNING - Recorded pid 187946 does not match the current pid 186775
[2024-09-10T15:20:25.651+0530] {local_task_job_runner.py:218} WARNING - Heartbeat failed with Exception: PID of job runner does not match
[2024-09-10T15:20:30.716+0530] {local_task_job_runner.py:318} WARNING - Recorded pid 187946 does not match the current pid 186775
[2024-09-10T15:20:30.716+0530] {local_task_job_runner.py:218} WARNING - Heartbeat failed with Exception: PID of job runner does not match
[2024-09-10T15:20:35.740+0530] {local_task_job_runner.py:318} WARNING - Recorded pid 187946 does not match the current pid 186775
[2024-09-10T15:20:35.741+0530] {local_task_job_runner.py:218} WARNING - Heartbeat failed with Exception: PID of job runner does not match
[2024-09-10T15:20:40.801+0530] {local_task_job_runner.py:318} WARNING - Recorded pid 187946 does not match the current pid 186775
[2024-09-10T15:20:40.801+0530] {local_task_job_runner.py:218} WARNING - Heartbeat failed with Exception: PID of job runner does not match
[2024-09-10T15:20:45.825+0530] {local_task_job_runner.py:318} WARNING - Recorded pid 187946 does not match the current pid 186775
[2024-09-10T15:20:45.826+0530] {local_task_job_runner.py:218} WARNING - Heartbeat failed with Exception: PID of job runner does not match
[2024-09-10T15:20:50.860+0530] {local_task_job_runner.py:318} WARNING - Recorded pid 187946 does not match the current pid 186775
[2024-09-10T15:20:50.861+0530] {local_task_job_runner.py:218} WARNING - Heartbeat failed with Exception: PID of job runner does not match
[2024-09-10T15:20:55.892+0530] {local_task_job_runner.py:318} WARNING - Recorded pid 187946 does not match the current pid 186775
[2024-09-10T15:20:55.892+0530] {local_task_job_runner.py:218} WARNING - Heartbeat failed with Exception: PID of job runner does not match
[2024-09-10T15:21:00.919+0530] {local_task_job_runner.py:318} WARNING - Recorded pid 187946 does not match the current pid 186775
[2024-09-10T15:21:00.919+0530] {local_task_job_runner.py:218} WARNING - Heartbeat failed with Exception: PID of job runner does not match
[2024-09-10T15:21:06.004+0530] {local_task_job_runner.py:318} WARNING - Recorded pid 187946 does not match the current pid 186775
[2024-09-10T15:21:06.005+0530] {local_task_job_runner.py:218} WARNING - Heartbeat failed with Exception: PID of job runner does not match
[2024-09-10T15:21:11.067+0530] {local_task_job_runner.py:318} WARNING - Recorded pid 187946 does not match the current pid 186775
[2024-09-10T15:21:11.068+0530] {local_task_job_runner.py:218} WARNING - Heartbeat failed with Exception: PID of job runner does not match
[2024-09-10T15:21:16.096+0530] {local_task_job_runner.py:318} WARNING - Recorded pid 187946 does not match the current pid 186775
[2024-09-10T15:21:16.096+0530] {local_task_job_runner.py:218} WARNING - Heartbeat failed with Exception: PID of job runner does not match
[2024-09-10T15:21:21.124+0530] {local_task_job_runner.py:318} WARNING - Recorded pid 187946 does not match the current pid 186775
[2024-09-10T15:21:21.125+0530] {local_task_job_runner.py:218} WARNING - Heartbeat failed with Exception: PID of job runner does not match
[2024-09-10T15:21:26.151+0530] {local_task_job_runner.py:318} WARNING - Recorded pid 187946 does not match the current pid 186775
[2024-09-10T15:21:26.151+0530] {local_task_job_runner.py:218} WARNING - Heartbeat failed with Exception: PID of job runner does not match
[2024-09-10T15:21:31.181+0530] {local_task_job_runner.py:318} WARNING - Recorded pid 187946 does not match the current pid 186775
[2024-09-10T15:21:31.181+0530] {local_task_job_runner.py:218} WARNING - Heartbeat failed with Exception: PID of job runner does not match
[2024-09-10T15:21:36.208+0530] {local_task_job_runner.py:318} WARNING - Recorded pid 187946 does not match the current pid 186775
[2024-09-10T15:21:36.208+0530] {local_task_job_runner.py:218} WARNING - Heartbeat failed with Exception: PID of job runner does not match
[2024-09-10T15:21:41.233+0530] {local_task_job_runner.py:318} WARNING - Recorded pid 187946 does not match the current pid 186775
[2024-09-10T15:21:41.233+0530] {local_task_job_runner.py:218} WARNING - Heartbeat failed with Exception: PID of job runner does not match
[2024-09-10T15:21:46.258+0530] {local_task_job_runner.py:318} WARNING - Recorded pid 187946 does not match the current pid 186775
[2024-09-10T15:21:46.258+0530] {local_task_job_runner.py:218} WARNING - Heartbeat failed with Exception: PID of job runner does not match
[2024-09-10T15:21:51.283+0530] {local_task_job_runner.py:318} WARNING - Recorded pid 187946 does not match the current pid 186775
[2024-09-10T15:21:51.284+0530] {local_task_job_runner.py:218} WARNING - Heartbeat failed with Exception: PID of job runner does not match
[2024-09-10T15:21:56.314+0530] {local_task_job_runner.py:318} WARNING - Recorded pid 187946 does not match the current pid 186775
[2024-09-10T15:21:56.314+0530] {local_task_job_runner.py:218} WARNING - Heartbeat failed with Exception: PID of job runner does not match
[2024-09-10T15:22:01.342+0530] {local_task_job_runner.py:318} WARNING - Recorded pid 187946 does not match the current pid 186775
[2024-09-10T15:22:01.342+0530] {local_task_job_runner.py:218} WARNING - Heartbeat failed with Exception: PID of job runner does not match
[2024-09-10T15:22:06.370+0530] {local_task_job_runner.py:318} WARNING - Recorded pid 187946 does not match the current pid 186775
[2024-09-10T15:22:06.370+0530] {local_task_job_runner.py:218} WARNING - Heartbeat failed with Exception: PID of job runner does not match
[2024-09-10T15:22:11.395+0530] {local_task_job_runner.py:318} WARNING - Recorded pid 187946 does not match the current pid 186775
[2024-09-10T15:22:11.395+0530] {local_task_job_runner.py:218} WARNING - Heartbeat failed with Exception: PID of job runner does not match
[2024-09-10T15:22:16.423+0530] {local_task_job_runner.py:318} WARNING - Recorded pid 187946 does not match the current pid 186775
[2024-09-10T15:22:16.424+0530] {local_task_job_runner.py:218} WARNING - Heartbeat failed with Exception: PID of job runner does not match
[2024-09-10T15:22:21.448+0530] {local_task_job_runner.py:318} WARNING - Recorded pid 187946 does not match the current pid 186775
[2024-09-10T15:22:21.448+0530] {local_task_job_runner.py:218} WARNING - Heartbeat failed with Exception: PID of job runner does not match
[2024-09-10T15:22:26.477+0530] {local_task_job_runner.py:318} WARNING - Recorded pid 187946 does not match the current pid 186775
[2024-09-10T15:22:26.478+0530] {local_task_job_runner.py:218} WARNING - Heartbeat failed with Exception: PID of job runner does not match
[2024-09-10T15:22:31.501+0530] {local_task_job_runner.py:318} WARNING - Recorded pid 187946 does not match the current pid 186775
[2024-09-10T15:22:31.501+0530] {local_task_job_runner.py:218} WARNING - Heartbeat failed with Exception: PID of job runner does not match
[2024-09-10T15:22:36.533+0530] {local_task_job_runner.py:318} WARNING - Recorded pid 187946 does not match the current pid 186775
[2024-09-10T15:22:36.533+0530] {local_task_job_runner.py:218} WARNING - Heartbeat failed with Exception: PID of job runner does not match
[2024-09-10T15:22:41.561+0530] {local_task_job_runner.py:318} WARNING - Recorded pid 187946 does not match the current pid 186775
[2024-09-10T15:22:41.562+0530] {local_task_job_runner.py:218} WARNING - Heartbeat failed with Exception: PID of job runner does not match
[2024-09-10T15:22:46.590+0530] {local_task_job_runner.py:318} WARNING - Recorded pid 187946 does not match the current pid 186775
[2024-09-10T15:22:46.591+0530] {local_task_job_runner.py:218} WARNING - Heartbeat failed with Exception: PID of job runner does not match
[2024-09-10T15:22:51.622+0530] {local_task_job_runner.py:318} WARNING - Recorded pid 187946 does not match the current pid 186775
[2024-09-10T15:22:51.622+0530] {local_task_job_runner.py:218} WARNING - Heartbeat failed with Exception: PID of job runner does not match
[2024-09-10T15:22:56.654+0530] {local_task_job_runner.py:318} WARNING - Recorded pid 187946 does not match the current pid 186775
[2024-09-10T15:22:56.655+0530] {local_task_job_runner.py:218} WARNING - Heartbeat failed with Exception: PID of job runner does not match
[2024-09-10T15:23:00.461+0530] {requests.py:558} INFO - Refreshing credentials due to a 401 response. Attempt 1/2.
[2024-09-10T15:23:00.501+0530] {taskinstance.py:3310} ERROR - Task failed with exception
Traceback (most recent call last):
  File "/home/sst7260/airflow_projects/project1/env/lib/python3.10/site-packages/airflow/models/taskinstance.py", line 767, in _execute_task
    result = _execute_callable(context=context, **execute_callable_kwargs)
  File "/home/sst7260/airflow_projects/project1/env/lib/python3.10/site-packages/airflow/models/taskinstance.py", line 733, in _execute_callable
    return ExecutionCallableRunner(
  File "/home/sst7260/airflow_projects/project1/env/lib/python3.10/site-packages/airflow/utils/operator_helpers.py", line 252, in run
    return self.func(*args, **kwargs)
  File "/home/sst7260/airflow_projects/project1/env/lib/python3.10/site-packages/airflow/models/baseoperator.py", line 406, in wrapper
    return func(self, *args, **kwargs)
  File "/home/sst7260/airflow_projects/project1/env/lib/python3.10/site-packages/airflow/operators/python.py", line 238, in execute
    return_value = self.execute_callable()
  File "/home/sst7260/airflow_projects/project1/env/lib/python3.10/site-packages/airflow/operators/python.py", line 256, in execute_callable
    return runner.run(*self.op_args, **self.op_kwargs)
  File "/home/sst7260/airflow_projects/project1/env/lib/python3.10/site-packages/airflow/utils/operator_helpers.py", line 252, in run
    return self.func(*args, **kwargs)
  File "/home/sst7260/airflow_projects/project1/dags/beam_etl_dag.py", line 60, in run_beam_pipeline
    | 'ReadFromText' >> ReadFromText(raw_data_bucket,
  File "/home/sst7260/airflow_projects/project1/env/lib/python3.10/site-packages/apache_beam/io/textio.py", line 781, in __init__
    self._source = self._source_class(
  File "/home/sst7260/airflow_projects/project1/env/lib/python3.10/site-packages/apache_beam/io/textio.py", line 140, in __init__
    super().__init__(
  File "/home/sst7260/airflow_projects/project1/env/lib/python3.10/site-packages/apache_beam/io/filebasedsource.py", line 127, in __init__
    self._validate()
  File "/home/sst7260/airflow_projects/project1/env/lib/python3.10/site-packages/apache_beam/options/value_provider.py", line 193, in _f
    return fnc(self, *args, **kwargs)
  File "/home/sst7260/airflow_projects/project1/env/lib/python3.10/site-packages/apache_beam/io/filebasedsource.py", line 188, in _validate
    match_result = FileSystems.match([pattern], limits=[1])[0]
  File "/home/sst7260/airflow_projects/project1/env/lib/python3.10/site-packages/apache_beam/io/filesystems.py", line 239, in match
    return filesystem.match(patterns, limits)
  File "/home/sst7260/airflow_projects/project1/env/lib/python3.10/site-packages/apache_beam/io/filesystem.py", line 804, in match
    raise BeamIOError("Match operation failed", exceptions)
apache_beam.io.filesystem.BeamIOError: Match operation failed with exceptions {'gs://sn_insights_test/input/OnlineRetail.csv': InvalidOperation('Anonymous credentials cannot be refreshed.')}
[2024-09-10T15:23:00.633+0530] {logging_mixin.py:190} INFO - Task instance in failure state
[2024-09-10T15:23:00.634+0530] {logging_mixin.py:190} INFO - Task start:2024-09-10 09:46:25.912405+00:00 end:2024-09-10 09:53:00.616871+00:00 duration:394.704466
[2024-09-10T15:23:00.636+0530] {logging_mixin.py:190} INFO - Task:<Task(PythonOperator): run_beam_pipeline> dag:<DAG: beam_etl_dag_with_credentials> dagrun:<DagRun beam_etl_dag_with_credentials @ 2024-09-10 09:43:00.310170+00:00: manual__2024-09-10T09:43:00.310170+00:00, state:running, queued_at: 2024-09-10 09:43:00.353896+00:00. externally triggered: True>
[2024-09-10T15:23:00.636+0530] {logging_mixin.py:190} INFO - Failure caused by Match operation failed with exceptions {'gs://sn_insights_test/input/OnlineRetail.csv': InvalidOperation('Anonymous credentials cannot be refreshed.')}
[2024-09-10T15:23:00.637+0530] {taskinstance.py:1225} INFO - Marking task as FAILED. dag_id=beam_etl_dag_with_credentials, task_id=run_beam_pipeline, run_id=manual__2024-09-10T09:43:00.310170+00:00, execution_date=20240910T094300, start_date=20240910T094625, end_date=20240910T095300
[2024-09-10T15:23:00.738+0530] {taskinstance.py:340} INFO - ::group::Post task execution logs
[2024-09-10T15:23:00.743+0530] {standard_task_runner.py:124} ERROR - Failed to execute job 64 for task run_beam_pipeline (Match operation failed with exceptions {'gs://sn_insights_test/input/OnlineRetail.csv': InvalidOperation('Anonymous credentials cannot be refreshed.')}; 186775)
Traceback (most recent call last):
  File "/home/sst7260/airflow_projects/project1/env/lib/python3.10/site-packages/airflow/task/task_runner/standard_task_runner.py", line 117, in _start_by_fork
    ret = args.func(args, dag=self.dag)
  File "/home/sst7260/airflow_projects/project1/env/lib/python3.10/site-packages/airflow/cli/cli_config.py", line 49, in command
    return func(*args, **kwargs)
  File "/home/sst7260/airflow_projects/project1/env/lib/python3.10/site-packages/airflow/utils/cli.py", line 115, in wrapper
    return f(*args, **kwargs)
  File "/home/sst7260/airflow_projects/project1/env/lib/python3.10/site-packages/airflow/cli/commands/task_command.py", line 483, in task_run
    task_return_code = _run_task_by_selected_method(args, _dag, ti)
  File "/home/sst7260/airflow_projects/project1/env/lib/python3.10/site-packages/airflow/cli/commands/task_command.py", line 256, in _run_task_by_selected_method
    return _run_raw_task(args, ti)
  File "/home/sst7260/airflow_projects/project1/env/lib/python3.10/site-packages/airflow/cli/commands/task_command.py", line 341, in _run_raw_task
    return ti._run_raw_task(
  File "/home/sst7260/airflow_projects/project1/env/lib/python3.10/site-packages/airflow/utils/session.py", line 97, in wrapper
    return func(*args, session=session, **kwargs)
  File "/home/sst7260/airflow_projects/project1/env/lib/python3.10/site-packages/airflow/models/taskinstance.py", line 3004, in _run_raw_task
    return _run_raw_task(
  File "/home/sst7260/airflow_projects/project1/env/lib/python3.10/site-packages/airflow/models/taskinstance.py", line 273, in _run_raw_task
    TaskInstance._execute_task_with_callbacks(
  File "/home/sst7260/airflow_projects/project1/env/lib/python3.10/site-packages/airflow/models/taskinstance.py", line 3158, in _execute_task_with_callbacks
    result = self._execute_task(context, task_orig)
  File "/home/sst7260/airflow_projects/project1/env/lib/python3.10/site-packages/airflow/models/taskinstance.py", line 3182, in _execute_task
    return _execute_task(self, context, task_orig)
  File "/home/sst7260/airflow_projects/project1/env/lib/python3.10/site-packages/airflow/models/taskinstance.py", line 767, in _execute_task
    result = _execute_callable(context=context, **execute_callable_kwargs)
  File "/home/sst7260/airflow_projects/project1/env/lib/python3.10/site-packages/airflow/models/taskinstance.py", line 733, in _execute_callable
    return ExecutionCallableRunner(
  File "/home/sst7260/airflow_projects/project1/env/lib/python3.10/site-packages/airflow/utils/operator_helpers.py", line 252, in run
    return self.func(*args, **kwargs)
  File "/home/sst7260/airflow_projects/project1/env/lib/python3.10/site-packages/airflow/models/baseoperator.py", line 406, in wrapper
    return func(self, *args, **kwargs)
  File "/home/sst7260/airflow_projects/project1/env/lib/python3.10/site-packages/airflow/operators/python.py", line 238, in execute
    return_value = self.execute_callable()
  File "/home/sst7260/airflow_projects/project1/env/lib/python3.10/site-packages/airflow/operators/python.py", line 256, in execute_callable
    return runner.run(*self.op_args, **self.op_kwargs)
  File "/home/sst7260/airflow_projects/project1/env/lib/python3.10/site-packages/airflow/utils/operator_helpers.py", line 252, in run
    return self.func(*args, **kwargs)
  File "/home/sst7260/airflow_projects/project1/dags/beam_etl_dag.py", line 60, in run_beam_pipeline
    | 'ReadFromText' >> ReadFromText(raw_data_bucket,
  File "/home/sst7260/airflow_projects/project1/env/lib/python3.10/site-packages/apache_beam/io/textio.py", line 781, in __init__
    self._source = self._source_class(
  File "/home/sst7260/airflow_projects/project1/env/lib/python3.10/site-packages/apache_beam/io/textio.py", line 140, in __init__
    super().__init__(
  File "/home/sst7260/airflow_projects/project1/env/lib/python3.10/site-packages/apache_beam/io/filebasedsource.py", line 127, in __init__
    self._validate()
  File "/home/sst7260/airflow_projects/project1/env/lib/python3.10/site-packages/apache_beam/options/value_provider.py", line 193, in _f
    return fnc(self, *args, **kwargs)
  File "/home/sst7260/airflow_projects/project1/env/lib/python3.10/site-packages/apache_beam/io/filebasedsource.py", line 188, in _validate
    match_result = FileSystems.match([pattern], limits=[1])[0]
  File "/home/sst7260/airflow_projects/project1/env/lib/python3.10/site-packages/apache_beam/io/filesystems.py", line 239, in match
    return filesystem.match(patterns, limits)
  File "/home/sst7260/airflow_projects/project1/env/lib/python3.10/site-packages/apache_beam/io/filesystem.py", line 804, in match
    raise BeamIOError("Match operation failed", exceptions)
apache_beam.io.filesystem.BeamIOError: Match operation failed with exceptions {'gs://sn_insights_test/input/OnlineRetail.csv': InvalidOperation('Anonymous credentials cannot be refreshed.')}
[2024-09-10T15:23:00.774+0530] {local_task_job_runner.py:266} INFO - Task exited with return code 1
[2024-09-10T15:23:00.842+0530] {taskinstance.py:3900} INFO - 0 downstream tasks scheduled from follow-on schedule check
[2024-09-10T15:23:00.843+0530] {local_task_job_runner.py:245} INFO - ::endgroup::
