[2024-09-10T17:03:11.927+0530] {local_task_job_runner.py:123} INFO - ::group::Pre task execution logs
[2024-09-10T17:03:11.934+0530] {local_task_job_runner.py:123} INFO - ::group::Pre task execution logs
[2024-09-10T17:03:11.949+0530] {taskinstance.py:2612} INFO - Dependencies all met for dep_context=non-requeueable deps ti=<TaskInstance: apache_beam_etl_pipeline.run_beam_pipeline2 manual__2024-09-10T11:33:06.687202+00:00 [queued]>
[2024-09-10T17:03:11.949+0530] {taskinstance.py:2612} INFO - Dependencies all met for dep_context=non-requeueable deps ti=<TaskInstance: apache_beam_etl_pipeline.run_beam_pipeline2 manual__2024-09-10T11:33:06.687202+00:00 [queued]>
[2024-09-10T17:03:11.956+0530] {taskinstance.py:2612} INFO - Dependencies all met for dep_context=requeueable deps ti=<TaskInstance: apache_beam_etl_pipeline.run_beam_pipeline2 manual__2024-09-10T11:33:06.687202+00:00 [queued]>
[2024-09-10T17:03:11.956+0530] {taskinstance.py:2865} INFO - Starting attempt 2 of 2
[2024-09-10T17:03:11.956+0530] {taskinstance.py:2612} INFO - Dependencies all met for dep_context=requeueable deps ti=<TaskInstance: apache_beam_etl_pipeline.run_beam_pipeline2 manual__2024-09-10T11:33:06.687202+00:00 [queued]>
[2024-09-10T17:03:11.957+0530] {taskinstance.py:2865} INFO - Starting attempt 2 of 2
[2024-09-10T17:03:11.992+0530] {taskinstance.py:2888} INFO - Executing <Task(BashOperator): run_beam_pipeline2> on 2024-09-10 11:33:06.687202+00:00
[2024-09-10T17:03:11.998+0530] {standard_task_runner.py:72} INFO - Started process 209050 to run task
[2024-09-10T17:03:12.003+0530] {standard_task_runner.py:104} INFO - Running: ['airflow', 'tasks', 'run', 'apache_beam_etl_pipeline', 'run_beam_pipeline2', 'manual__2024-09-10T11:33:06.687202+00:00', '--job-id', '98', '--raw', '--subdir', 'DAGS_FOLDER/aaz.py', '--cfg-path', '/tmp/tmp7tdz7rrg']
[2024-09-10T17:03:12.004+0530] {standard_task_runner.py:105} INFO - Job 98: Subtask run_beam_pipeline2
[2024-09-10T17:03:12.022+0530] {taskinstance.py:2888} INFO - Executing <Task(BashOperator): run_beam_pipeline2> on 2024-09-10 11:33:06.687202+00:00
[2024-09-10T17:03:12.025+0530] {standard_task_runner.py:72} INFO - Started process 209052 to run task
[2024-09-10T17:03:12.034+0530] {standard_task_runner.py:104} INFO - Running: ['airflow', 'tasks', 'run', 'apache_beam_etl_pipeline', 'run_beam_pipeline2', 'manual__2024-09-10T11:33:06.687202+00:00', '--job-id', '99', '--raw', '--subdir', 'DAGS_FOLDER/aaz.py', '--cfg-path', '/tmp/tmpwwsjuzd6']
[2024-09-10T17:03:12.034+0530] {standard_task_runner.py:105} INFO - Job 99: Subtask run_beam_pipeline2
[2024-09-10T17:03:12.133+0530] {task_command.py:467} INFO - Running <TaskInstance: apache_beam_etl_pipeline.run_beam_pipeline2 manual__2024-09-10T11:33:06.687202+00:00 [running]> on host PG0392KD.springernature.com
[2024-09-10T17:03:12.194+0530] {task_command.py:467} INFO - Running <TaskInstance: apache_beam_etl_pipeline.run_beam_pipeline2 manual__2024-09-10T11:33:06.687202+00:00 [running]> on host PG0392KD.springernature.com
[2024-09-10T17:03:13.143+0530] {taskinstance.py:3131} INFO - Exporting env vars: AIRFLOW_CTX_DAG_OWNER='airflow_SS' AIRFLOW_CTX_DAG_ID='apache_beam_etl_pipeline' AIRFLOW_CTX_TASK_ID='run_beam_pipeline2' AIRFLOW_CTX_EXECUTION_DATE='2024-09-10T11:33:06.687202+00:00' AIRFLOW_CTX_TRY_NUMBER='2' AIRFLOW_CTX_DAG_RUN_ID='manual__2024-09-10T11:33:06.687202+00:00'
[2024-09-10T17:03:13.144+0530] {logging_mixin.py:190} INFO - Task instance is in running state
[2024-09-10T17:03:13.145+0530] {logging_mixin.py:190} INFO -  Previous state of the Task instance: queued
[2024-09-10T17:03:13.145+0530] {logging_mixin.py:190} INFO - Current task name:run_beam_pipeline2 state:running start_date:2024-09-10 11:33:11.949651+00:00
[2024-09-10T17:03:13.145+0530] {logging_mixin.py:190} INFO - Dag name:apache_beam_etl_pipeline and current dag run status:running
[2024-09-10T17:03:13.145+0530] {taskinstance.py:731} INFO - ::endgroup::
[2024-09-10T17:03:13.147+0530] {subprocess.py:63} INFO - Tmp dir root location: /tmp
[2024-09-10T17:03:13.426+0530] {subprocess.py:75} INFO - Running command: ['/usr/bin/bash', '-c', 'python3 ~/airflow_projects/project1/beam_scripts/etl_pipe_1.py']
[2024-09-10T17:03:13.439+0530] {subprocess.py:86} INFO - Output:
[2024-09-10T17:03:13.155+0530] {taskinstance.py:3310} ERROR - Task failed with exception
Traceback (most recent call last):
  File "/home/sst7260/airflow_projects/project1/env/lib/python3.10/site-packages/sqlalchemy/engine/base.py", line 1910, in _execute_context
    self.dialect.do_execute(
  File "/home/sst7260/airflow_projects/project1/env/lib/python3.10/site-packages/sqlalchemy/engine/default.py", line 736, in do_execute
    cursor.execute(statement, parameters)
sqlite3.IntegrityError: UNIQUE constraint failed: rendered_task_instance_fields.dag_id, rendered_task_instance_fields.task_id, rendered_task_instance_fields.run_id, rendered_task_instance_fields.map_index

The above exception was the direct cause of the following exception:

Traceback (most recent call last):
  File "/home/sst7260/airflow_projects/project1/env/lib/python3.10/site-packages/airflow/models/taskinstance.py", line 273, in _run_raw_task
    TaskInstance._execute_task_with_callbacks(
  File "/home/sst7260/airflow_projects/project1/env/lib/python3.10/site-packages/airflow/models/taskinstance.py", line 3122, in _execute_task_with_callbacks
    _update_rtif(ti=self, rendered_fields=rendered_fields)
  File "/home/sst7260/airflow_projects/project1/env/lib/python3.10/site-packages/airflow/api_internal/internal_api_call.py", line 139, in wrapper
    return func(*args, **kwargs)
  File "/home/sst7260/airflow_projects/project1/env/lib/python3.10/site-packages/airflow/utils/session.py", line 97, in wrapper
    return func(*args, session=session, **kwargs)
  File "/home/sst7260/airflow_projects/project1/env/lib/python3.10/site-packages/airflow/models/taskinstance.py", line 1642, in _update_rtif
    RenderedTaskInstanceFields.delete_old_records(ti.task_id, ti.dag_id, session=session)
  File "/home/sst7260/airflow_projects/project1/env/lib/python3.10/site-packages/airflow/utils/session.py", line 94, in wrapper
    return func(*args, **kwargs)
  File "/home/sst7260/airflow_projects/project1/env/lib/python3.10/site-packages/airflow/models/renderedtifields.py", line 271, in delete_old_records
    session.flush()
  File "/home/sst7260/airflow_projects/project1/env/lib/python3.10/site-packages/sqlalchemy/orm/session.py", line 3449, in flush
    self._flush(objects)
  File "/home/sst7260/airflow_projects/project1/env/lib/python3.10/site-packages/sqlalchemy/orm/session.py", line 3588, in _flush
    with util.safe_reraise():
  File "/home/sst7260/airflow_projects/project1/env/lib/python3.10/site-packages/sqlalchemy/util/langhelpers.py", line 70, in __exit__
    compat.raise_(
  File "/home/sst7260/airflow_projects/project1/env/lib/python3.10/site-packages/sqlalchemy/util/compat.py", line 211, in raise_
    raise exception
  File "/home/sst7260/airflow_projects/project1/env/lib/python3.10/site-packages/sqlalchemy/orm/session.py", line 3549, in _flush
    flush_context.execute()
  File "/home/sst7260/airflow_projects/project1/env/lib/python3.10/site-packages/sqlalchemy/orm/unitofwork.py", line 456, in execute
    rec.execute(self)
  File "/home/sst7260/airflow_projects/project1/env/lib/python3.10/site-packages/sqlalchemy/orm/unitofwork.py", line 630, in execute
    util.preloaded.orm_persistence.save_obj(
  File "/home/sst7260/airflow_projects/project1/env/lib/python3.10/site-packages/sqlalchemy/orm/persistence.py", line 245, in save_obj
    _emit_insert_statements(
  File "/home/sst7260/airflow_projects/project1/env/lib/python3.10/site-packages/sqlalchemy/orm/persistence.py", line 1097, in _emit_insert_statements
    c = connection._execute_20(
  File "/home/sst7260/airflow_projects/project1/env/lib/python3.10/site-packages/sqlalchemy/engine/base.py", line 1710, in _execute_20
    return meth(self, args_10style, kwargs_10style, execution_options)
  File "/home/sst7260/airflow_projects/project1/env/lib/python3.10/site-packages/sqlalchemy/sql/elements.py", line 334, in _execute_on_connection
    return connection._execute_clauseelement(
  File "/home/sst7260/airflow_projects/project1/env/lib/python3.10/site-packages/sqlalchemy/engine/base.py", line 1577, in _execute_clauseelement
    ret = self._execute_context(
  File "/home/sst7260/airflow_projects/project1/env/lib/python3.10/site-packages/sqlalchemy/engine/base.py", line 1953, in _execute_context
    self._handle_dbapi_exception(
  File "/home/sst7260/airflow_projects/project1/env/lib/python3.10/site-packages/sqlalchemy/engine/base.py", line 2134, in _handle_dbapi_exception
    util.raise_(
  File "/home/sst7260/airflow_projects/project1/env/lib/python3.10/site-packages/sqlalchemy/util/compat.py", line 211, in raise_
    raise exception
  File "/home/sst7260/airflow_projects/project1/env/lib/python3.10/site-packages/sqlalchemy/engine/base.py", line 1910, in _execute_context
    self.dialect.do_execute(
  File "/home/sst7260/airflow_projects/project1/env/lib/python3.10/site-packages/sqlalchemy/engine/default.py", line 736, in do_execute
    cursor.execute(statement, parameters)
sqlalchemy.exc.IntegrityError: (sqlite3.IntegrityError) UNIQUE constraint failed: rendered_task_instance_fields.dag_id, rendered_task_instance_fields.task_id, rendered_task_instance_fields.run_id, rendered_task_instance_fields.map_index
[SQL: INSERT INTO rendered_task_instance_fields (dag_id, task_id, run_id, map_index, rendered_fields, k8s_pod_yaml) VALUES (?, ?, ?, ?, ?, ?)]
[parameters: ('apache_beam_etl_pipeline', 'run_beam_pipeline2', 'manual__2024-09-10T11:33:06.687202+00:00', -1, '{"bash_command": "python3 ~/airflow_projects/project1/beam_scripts/etl_pipe_1.py", "env": null, "cwd": null}', 'null')]
(Background on this error at: https://sqlalche.me/e/14/gkpj)
[2024-09-10T17:03:15.340+0530] {logging_mixin.py:190} INFO - Task instance in failure state
[2024-09-10T17:03:15.341+0530] {logging_mixin.py:190} INFO - Task start:2024-09-10 11:33:11.949651+00:00 end:2024-09-10 11:33:15.340010+00:00 duration:3.390359
[2024-09-10T17:03:15.341+0530] {logging_mixin.py:190} INFO - Task:<Task(BashOperator): run_beam_pipeline2> dag:<DAG: apache_beam_etl_pipeline> dagrun:<DagRun apache_beam_etl_pipeline @ 2024-09-10 11:33:06.687202+00:00: manual__2024-09-10T11:33:06.687202+00:00, state:running, queued_at: 2024-09-10 11:33:06.806075+00:00. externally triggered: True>
[2024-09-10T17:03:15.348+0530] {logging_mixin.py:190} INFO - Failure caused by (sqlite3.IntegrityError) UNIQUE constraint failed: rendered_task_instance_fields.dag_id, rendered_task_instance_fields.task_id, rendered_task_instance_fields.run_id, rendered_task_instance_fields.map_index
[SQL: INSERT INTO rendered_task_instance_fields (dag_id, task_id, run_id, map_index, rendered_fields, k8s_pod_yaml) VALUES (?, ?, ?, ?, ?, ?)]
[parameters: ('apache_beam_etl_pipeline', 'run_beam_pipeline2', 'manual__2024-09-10T11:33:06.687202+00:00', -1, '{"bash_command": "python3 ~/airflow_projects/project1/beam_scripts/etl_pipe_1.py", "env": null, "cwd": null}', 'null')]
(Background on this error at: https://sqlalche.me/e/14/gkpj)
[2024-09-10T17:03:15.348+0530] {taskinstance.py:1225} INFO - Marking task as FAILED. dag_id=apache_beam_etl_pipeline, task_id=run_beam_pipeline2, run_id=manual__2024-09-10T11:33:06.687202+00:00, execution_date=20240910T113306, start_date=20240910T113311, end_date=20240910T113315
[2024-09-10T17:03:15.586+0530] {taskinstance.py:340} INFO - ::group::Post task execution logs
[2024-09-10T17:03:15.587+0530] {standard_task_runner.py:124} ERROR - Failed to execute job 99 for task run_beam_pipeline2 ((sqlite3.IntegrityError) UNIQUE constraint failed: rendered_task_instance_fields.dag_id, rendered_task_instance_fields.task_id, rendered_task_instance_fields.run_id, rendered_task_instance_fields.map_index
[SQL: INSERT INTO rendered_task_instance_fields (dag_id, task_id, run_id, map_index, rendered_fields, k8s_pod_yaml) VALUES (?, ?, ?, ?, ?, ?)]
[parameters: ('apache_beam_etl_pipeline', 'run_beam_pipeline2', 'manual__2024-09-10T11:33:06.687202+00:00', -1, '{"bash_command": "python3 ~/airflow_projects/project1/beam_scripts/etl_pipe_1.py", "env": null, "cwd": null}', 'null')]
(Background on this error at: https://sqlalche.me/e/14/gkpj); 209052)
Traceback (most recent call last):
  File "/home/sst7260/airflow_projects/project1/env/lib/python3.10/site-packages/sqlalchemy/engine/base.py", line 1910, in _execute_context
    self.dialect.do_execute(
  File "/home/sst7260/airflow_projects/project1/env/lib/python3.10/site-packages/sqlalchemy/engine/default.py", line 736, in do_execute
    cursor.execute(statement, parameters)
sqlite3.IntegrityError: UNIQUE constraint failed: rendered_task_instance_fields.dag_id, rendered_task_instance_fields.task_id, rendered_task_instance_fields.run_id, rendered_task_instance_fields.map_index

The above exception was the direct cause of the following exception:

Traceback (most recent call last):
  File "/home/sst7260/airflow_projects/project1/env/lib/python3.10/site-packages/airflow/task/task_runner/standard_task_runner.py", line 117, in _start_by_fork
    ret = args.func(args, dag=self.dag)
  File "/home/sst7260/airflow_projects/project1/env/lib/python3.10/site-packages/airflow/cli/cli_config.py", line 49, in command
    return func(*args, **kwargs)
  File "/home/sst7260/airflow_projects/project1/env/lib/python3.10/site-packages/airflow/utils/cli.py", line 115, in wrapper
    return f(*args, **kwargs)
  File "/home/sst7260/airflow_projects/project1/env/lib/python3.10/site-packages/airflow/cli/commands/task_command.py", line 483, in task_run
    task_return_code = _run_task_by_selected_method(args, _dag, ti)
  File "/home/sst7260/airflow_projects/project1/env/lib/python3.10/site-packages/airflow/cli/commands/task_command.py", line 256, in _run_task_by_selected_method
    return _run_raw_task(args, ti)
  File "/home/sst7260/airflow_projects/project1/env/lib/python3.10/site-packages/airflow/cli/commands/task_command.py", line 341, in _run_raw_task
    return ti._run_raw_task(
  File "/home/sst7260/airflow_projects/project1/env/lib/python3.10/site-packages/airflow/utils/session.py", line 97, in wrapper
    return func(*args, session=session, **kwargs)
  File "/home/sst7260/airflow_projects/project1/env/lib/python3.10/site-packages/airflow/models/taskinstance.py", line 3004, in _run_raw_task
    return _run_raw_task(
  File "/home/sst7260/airflow_projects/project1/env/lib/python3.10/site-packages/airflow/models/taskinstance.py", line 273, in _run_raw_task
    TaskInstance._execute_task_with_callbacks(
  File "/home/sst7260/airflow_projects/project1/env/lib/python3.10/site-packages/airflow/models/taskinstance.py", line 3122, in _execute_task_with_callbacks
    _update_rtif(ti=self, rendered_fields=rendered_fields)
  File "/home/sst7260/airflow_projects/project1/env/lib/python3.10/site-packages/airflow/api_internal/internal_api_call.py", line 139, in wrapper
    return func(*args, **kwargs)
  File "/home/sst7260/airflow_projects/project1/env/lib/python3.10/site-packages/airflow/utils/session.py", line 97, in wrapper
    return func(*args, session=session, **kwargs)
  File "/home/sst7260/airflow_projects/project1/env/lib/python3.10/site-packages/airflow/models/taskinstance.py", line 1642, in _update_rtif
    RenderedTaskInstanceFields.delete_old_records(ti.task_id, ti.dag_id, session=session)
  File "/home/sst7260/airflow_projects/project1/env/lib/python3.10/site-packages/airflow/utils/session.py", line 94, in wrapper
    return func(*args, **kwargs)
  File "/home/sst7260/airflow_projects/project1/env/lib/python3.10/site-packages/airflow/models/renderedtifields.py", line 271, in delete_old_records
    session.flush()
  File "/home/sst7260/airflow_projects/project1/env/lib/python3.10/site-packages/sqlalchemy/orm/session.py", line 3449, in flush
    self._flush(objects)
  File "/home/sst7260/airflow_projects/project1/env/lib/python3.10/site-packages/sqlalchemy/orm/session.py", line 3588, in _flush
    with util.safe_reraise():
  File "/home/sst7260/airflow_projects/project1/env/lib/python3.10/site-packages/sqlalchemy/util/langhelpers.py", line 70, in __exit__
    compat.raise_(
  File "/home/sst7260/airflow_projects/project1/env/lib/python3.10/site-packages/sqlalchemy/util/compat.py", line 211, in raise_
    raise exception
  File "/home/sst7260/airflow_projects/project1/env/lib/python3.10/site-packages/sqlalchemy/orm/session.py", line 3549, in _flush
    flush_context.execute()
  File "/home/sst7260/airflow_projects/project1/env/lib/python3.10/site-packages/sqlalchemy/orm/unitofwork.py", line 456, in execute
    rec.execute(self)
  File "/home/sst7260/airflow_projects/project1/env/lib/python3.10/site-packages/sqlalchemy/orm/unitofwork.py", line 630, in execute
    util.preloaded.orm_persistence.save_obj(
  File "/home/sst7260/airflow_projects/project1/env/lib/python3.10/site-packages/sqlalchemy/orm/persistence.py", line 245, in save_obj
    _emit_insert_statements(
  File "/home/sst7260/airflow_projects/project1/env/lib/python3.10/site-packages/sqlalchemy/orm/persistence.py", line 1097, in _emit_insert_statements
    c = connection._execute_20(
  File "/home/sst7260/airflow_projects/project1/env/lib/python3.10/site-packages/sqlalchemy/engine/base.py", line 1710, in _execute_20
    return meth(self, args_10style, kwargs_10style, execution_options)
  File "/home/sst7260/airflow_projects/project1/env/lib/python3.10/site-packages/sqlalchemy/sql/elements.py", line 334, in _execute_on_connection
    return connection._execute_clauseelement(
  File "/home/sst7260/airflow_projects/project1/env/lib/python3.10/site-packages/sqlalchemy/engine/base.py", line 1577, in _execute_clauseelement
    ret = self._execute_context(
  File "/home/sst7260/airflow_projects/project1/env/lib/python3.10/site-packages/sqlalchemy/engine/base.py", line 1953, in _execute_context
    self._handle_dbapi_exception(
  File "/home/sst7260/airflow_projects/project1/env/lib/python3.10/site-packages/sqlalchemy/engine/base.py", line 2134, in _handle_dbapi_exception
    util.raise_(
  File "/home/sst7260/airflow_projects/project1/env/lib/python3.10/site-packages/sqlalchemy/util/compat.py", line 211, in raise_
    raise exception
  File "/home/sst7260/airflow_projects/project1/env/lib/python3.10/site-packages/sqlalchemy/engine/base.py", line 1910, in _execute_context
    self.dialect.do_execute(
  File "/home/sst7260/airflow_projects/project1/env/lib/python3.10/site-packages/sqlalchemy/engine/default.py", line 736, in do_execute
    cursor.execute(statement, parameters)
sqlalchemy.exc.IntegrityError: (sqlite3.IntegrityError) UNIQUE constraint failed: rendered_task_instance_fields.dag_id, rendered_task_instance_fields.task_id, rendered_task_instance_fields.run_id, rendered_task_instance_fields.map_index
[SQL: INSERT INTO rendered_task_instance_fields (dag_id, task_id, run_id, map_index, rendered_fields, k8s_pod_yaml) VALUES (?, ?, ?, ?, ?, ?)]
[parameters: ('apache_beam_etl_pipeline', 'run_beam_pipeline2', 'manual__2024-09-10T11:33:06.687202+00:00', -1, '{"bash_command": "python3 ~/airflow_projects/project1/beam_scripts/etl_pipe_1.py", "env": null, "cwd": null}', 'null')]
(Background on this error at: https://sqlalche.me/e/14/gkpj)
[2024-09-10T17:03:15.621+0530] {local_task_job_runner.py:266} INFO - Task exited with return code 1
[2024-09-10T17:03:15.668+0530] {taskinstance.py:3900} INFO - 0 downstream tasks scheduled from follow-on schedule check
[2024-09-10T17:03:15.669+0530] {local_task_job_runner.py:245} INFO - ::endgroup::
[2024-09-10T17:03:19.524+0530] {subprocess.py:93} INFO - [2024-09-10T17:03:19.512+0530] {native_type_compatibility.py:340} INFO - Using Any for unsupported type: typing.Sequence[~T]
[2024-09-10T17:03:20.482+0530] {subprocess.py:93} INFO - Traceback (most recent call last):
[2024-09-10T17:03:20.483+0530] {subprocess.py:93} INFO -   File "/home/sst7260/airflow_projects/project1/beam_scripts/etl_pipe_1.py", line 56, in <module>
[2024-09-10T17:03:20.483+0530] {subprocess.py:93} INFO -     transform_load()
[2024-09-10T17:03:20.499+0530] {subprocess.py:93} INFO - NameError: name 'transform_load' is not defined
[2024-09-10T17:03:21.616+0530] {subprocess.py:97} INFO - Command exited with return code 1
[2024-09-10T17:03:21.668+0530] {taskinstance.py:340} INFO - ::group::Post task execution logs
[2024-09-10T17:03:21.690+0530] {local_task_job_runner.py:266} INFO - Task exited with return code 0
[2024-09-10T17:03:21.716+0530] {taskinstance.py:3900} INFO - 0 downstream tasks scheduled from follow-on schedule check
[2024-09-10T17:03:21.718+0530] {local_task_job_runner.py:245} INFO - ::endgroup::
